Workbook

Sheet NAC
B1: Índices | Y1: Tasas de inflación mensual | AV1: Tasas de inflación interanual
R2: =+SUM(C3:N3) -> 1 | S2: =+SUM($C$3:$E$3,$G$3,$K$3,$M$3:$N$3) -> 0.66456407 | T2: =+SUM($E$3,$G$3,$K$3,$M$3:$N$3) -> 0.35975272 | U2: =+SUM($E$3,$G$3,$K$3,$N$3) -> 0.27075759 | W2: =+SUM(E3,G3:L3,N3) -> 0.51189203 | AT2: =+SUM(AB3,AD3:AI3,AK3) -> 0.51189203 | BL2: =+SUM(AW3:BH3) -> 1 | BQ2: =+SUM(AY3,BA3:BF3,BH3) -> 0.51189203
C3: 0.26984735 | D3: 0.034964 | E3: 0.09889825 | F3: 0.09430149 | G3: 0.0640437 | H3: 0.0797777 | I3: 0.11018341 | J3: 0.02820723 | K3: 0.07259865 | L3: 0.0229661 | M3: 0.08899513 | N3: 0.03521699 | R3: headline | V3: no food & energy | W3: no food & energy & shelter | Z3: 0.26984735 | AA3: 0.034964 | AB3: 0.09889825 | AC3: 0.09430149 | AD3: 0.0640437 | AE3: 0.0797777 | AF3: 0.11018341 | AG3: 0.02820723 | AH3: 0.07259865 | AI3: 0.0229661 | AJ3: 0.08899513 | AK3: 0.03521699 | AO3: headline | AS3: no food & energy | AT3: no food & energy & shelter | AW3: 0.26984735 | AX3: 0.034964 | AY3: 0.09889825 | AZ3: 0.09430149 | BA3: 0.0640437 | BB3: 0.0797777 | BC3: 0.11018341 | BD3: 0.02820723 | BE3: 0.07259865 | BF3: 0.0229661 | BG3: 0.08899513 | BH3: 0.03521699 | BL3: headline | BP3: no food & energy | BQ3: no food & energy & shelter
A4: Fecha | B4: Nivel general | C4: Alimentos y bebidas no alcohólicas | D4: Bebidas alcohólicas y tabaco | E4: Prendas de vestir y calzado | F4: Vivienda, agua, electricidad, gas y otros combustibles | G4: Equipamiento y mantenimiento del hogar | H4: Salud | I4: Transporte | J4: Comunicación | K4: Recreación y cultura | L4: Educación | M4: Restaurantes y hoteles | N4: Bienes y servicios varios | O4: Estacional | P4: Núcleo | Q4: Regulados | R4: Nivel General | S4: Subyacente | T4: Subyacente-AyB | U4: Subyacente-Food | V4: Core | W4: Supercore | Y4: Nivel general | Z4: Alimentos y bebidas no alcohólicas | AA4: Bebidas alcohólicas y tabaco | AB4: Prendas de vestir y calzado | AC4: Vivienda, agua, electricidad, gas y otros combustibles | AD4: Equipamiento y mantenimiento del hogar | AE4: Salud | AF4: Transporte | AG4: Comunicación | AH4: Recreación y cultura | AI4: Educación | AJ4: Restaurantes y hoteles | AK4: Bienes y servicios varios | AL4: Estacional | AM4: Núcleo | AN4: Regulados | AO4: =+R4 -> Nivel General | AP4: =+S4 -> Subyacente | AQ4: =+T4 -> Subyacente-AyB | AR4: =+U4 -> Subyacente-Food | AS4: Core | AT4: Supercore | AV4: Nivel general | AW4: Alimentos y bebidas no alcohólicas | AX4: Bebidas alcohólicas y tabaco | AY4: Prendas de vestir y calzado | AZ4: Vivienda, agua, electricidad, gas y otros combustibles | BA4: Equipamiento y mantenimiento del hogar | BB4: Salud | BC4: Transporte | BD4: Comunicación | BE4: Recreación y cultura | BF4: Educación | BG4: Restaurantes y hoteles | BH4: Bienes y servicios varios | BI4: Estacional | BJ4: Núcleo | BK4: Regulados | BL4: =+AO4 -> Nivel General | BM4: =+AP4 -> Subyacente | BN4: =+AQ4 -> Subyacente-AyB | BO4: =+AR4 -> Subyacente-Food | BP4: Core | BQ4: Supercore
A5: =+[1]NAC!A6 -> 42705 | B5: =+[1]NAC!B6 -> 100 | C5: =+[1]NAC!C6 -> 100 | D5: =+[1]NAC!D6 -> 100 | E5: =+[1]NAC!E6 -> 100 | F5: =+[1]NAC!F6 -> 100 | G5: =+[1]NAC!G6 -> 100 | H5: =+[1]NAC!H6 -> 100 | ... N5: =+[1]NAC!N6 -> 100 | O5: =+[1]NAC!P6 -> 100 | P5: =+[1]NAC!Q6 -> 100 | Q5: =+[1]NAC!R6 -> 100 | R5: =+SUMPRODUCT($C$3:$N$3,C5:N5) -> 100 | S5: =+($C$3*$C5+$D$3*$D5+$E$3*$E5+$G$3*$G5+$K$3*$K5+$M$3*$M5+$N$3*$N5)/SUM($C$3:$E$3,$G$3,$K$3,$M$3:$N$3) -> 100 | T5: =+($E$3*$E5+$G$3*$G5+$K$3*$K5+$M$3*$M5+$N$3*$N5)/SUM($E$3,$G$3,$K$3,$M$3:$N$3) -> 100 | U5: =+($E$3*$E5+$G$3*$G5+$K$3*$K5+$N$3*$N5)/SUM($E$3,$G$3,$K$3,$N$3) -> 100 | W5: =($E$3*$E5+SUMPRODUCT($G$3:$L$3,$G5:$L5)+$N$3*$N5)/SUM($E$3,$G$3:$L$3,$N$3) -> 100
A6: =+[1]NAC!A7 -> 42736 | B6: =+[1]NAC!B7 -> 101.6 | C6: =+[1]NAC!C7 -> 101.3 | D6: =+[1]NAC!D7 -> 100.9 | E6: =+[1]NAC!E7 -> 99 | F6: =+[1]NAC!F7 -> 101.5 | G6: =+[1]NAC!G7 -> 100.9 | H6: =+[1]NAC!H7 -> 102.4 | ... N6: =+[1]NAC!N7 -> 101.9 | O6: =+[1]NAC!P7 -> 101.7 | P6: =+[1]NAC!Q7 -> 101.5 | Q6: =+[1]NAC!R7 -> 101.8 | R6: =+SUMPRODUCT($C$3:$N$3,C6:N6) -> 101.58624 | S6: =+($C$3*$C6+$D$3*$D6+$E$3*$E6+$G$3*$G6+$K$3*$K6+$M$3*$M6+$N$3*$N6)/SUM($C$3:$E$3,$G$3,$K$3,$M$3:$N$3) -> 101.37853 | T6: =+($E$3*$E6+$G$3*$G6+$K$3*$K6+$M$3*$M6+$N$3*$N6)/SUM($E$3,$G$3,$K$3,$M$3:$N$3) -> 101.48395 | U6: =+($E$3*$E6+$G$3*$G6+$K$3*$K6+$N$3*$N6)/SUM($E$3,$G$3,$K$3,$N$3) -> 100.95277 | W6: =($E$3*$E6+SUMPRODUCT($G$3:$L$3,$G6:$L6)+$N$3*$N6)/SUM($E$3,$G$3:$L$3,$N$3) -> 101.53672 | Y6: =+B6/B5-1 -> 0.016 | Z6: =+C6/C5-1 -> 0.013 | AA6: =+D6/D5-1 -> 0.009 | AB6: =+E6/E5-1 -> -0.01 | AC6: =+F6/F5-1 -> 0.015 | AD6: =+G6/G5-1 -> 0.009 | AE6: =+H6/H5-1 -> 0.024 | AF6: =+I6/I5-1 -> 0.021 | ... AT6: =+W6/W5-1 -> 0.015367225
A7: =+[1]NAC!A8 -> 42767 | B7: =+[1]NAC!B8 -> 103.7 | C7: =+[1]NAC!C8 -> 103.2 | D7: =+[1]NAC!D8 -> 105.2 | E7: =+[1]NAC!E8 -> 98.9 | F7: =+[1]NAC!F8 -> 107 | G7: =+[1]NAC!G8 -> 101.3 | H7: =+[1]NAC!H8 -> 105.1 | ... N7: =+[1]NAC!N8 -> 103.8 | O7: =+[1]NAC!P8 -> 102.3 | P7: =+[1]NAC!Q8 -> 103.2 | Q7: =+[1]NAC!R8 -> 105.9 | R7: =+SUMPRODUCT($C$3:$N$3,C7:N7) -> 103.67106 | S7: =+($C$3*$C7+$D$3*$D7+$E$3*$E7+$G$3*$G7+$K$3*$K7+$M$3*$M7+$N$3*$N7)/SUM($C$3:$E$3,$G$3,$K$3,$M$3:$N$3) -> 102.80721 | T7: =+($E$3*$E7+$G$3*$G7+$K$3*$K7+$M$3*$M7+$N$3*$N7)/SUM($E$3,$G$3,$K$3,$M$3:$N$3) -> 102.28002 | U7: =+($E$3*$E7+$G$3*$G7+$K$3*$K7+$N$3*$N7)/SUM($E$3,$G$3,$K$3,$N$3) -> 101.41886 | W7: =($E$3*$E7+SUMPRODUCT($G$3:$L$3,$G7:$L7)+$N$3*$N7)/SUM($E$3,$G$3:$L$3,$N$3) -> 102.98802 | Y7: =+B7/B6-1 -> 0.020669291 | Z7: =+C7/C6-1 -> 0.01875617 | AA7: =+D7/D6-1 -> 0.042616452 | AB7: =+E7/E6-1 -> -0.001010101 | AC7: =+F7/F6-1 -> 0.054187192 | AD7: =+G7/G6-1 -> 0.0039643211 | AE7: =+H7/H6-1 -> 0.026367187 | AF7: =+I7/I6-1 -> 0.018609207 | ... AT7: =+W7/W6-1 -> 0.014293358
A8: =+[1]NAC!A9 -> 42795 | B8: =+[1]NAC!B9 -> 106.1 | C8: =+[1]NAC!C9 -> 106 | D8: =+[1]NAC!D9 -> 107.3 | E8: =+[1]NAC!E9 -> 102.3 | F8: =+[1]NAC!F9 -> 110.8 | G8: =+[1]NAC!G9 -> 102.2 | H8: =+[1]NAC!H9 -> 107.1 | ... N8: =+[1]NAC!N9 -> 105.7 | O8: =+[1]NAC!P9 -> 104.8 | P8: =+[1]NAC!Q9 -> 105.2 | Q8: =+[1]NAC!R9 -> 110 | R8: =+SUMPRODUCT($C$3:$N$3,C8:N8) -> 106.18771 | S8: =+($C$3*$C8+$D$3*$D8+$E$3*$E8+$G$3*$G8+$K$3*$K8+$M$3*$M8+$N$3*$N8)/SUM($C$3:$E$3,$G$3,$K$3,$M$3:$N$3) -> 105.08105 | T8: =+($E$3*$E8+$G$3*$G8+$K$3*$K8+$M$3*$M8+$N$3*$N8)/SUM($E$3,$G$3,$K$3,$M$3:$N$3) -> 104.1761 | U8: =+($E$3*$E8+$G$3*$G8+$K$3*$K8+$N$3*$N8)/SUM($E$3,$G$3,$K$3,$N$3) -> 103.5766 | W8: =($E$3*$E8+SUMPRODUCT($G$3:$L$3,$G8:$L8)+$N$3*$N8)/SUM($E$3,$G$3:$L$3,$N$3) -> 105.39365 | Y8: =+B8/B7-1 -> 0.023143684 | Z8: =+C8/C7-1 -> 0.027131783 | AA8: =+D8/D7-1 -> 0.019961977 | AB8: =+E8/E7-1 -> 0.03437816 | AC8: =+F8/F7-1 -> 0.035514019 | AD8: =+G8/G7-1 -> 0.0088845015 | AE8: =+H8/H7-1 -> 0.019029496 | AF8: =+I8/I7-1 -> 0.011538462 | ... AT8: =+W8/W7-1 -> 0.023358301
A9: =+[1]NAC!A10 -> 42826 | B9: =+[1]NAC!B10 -> 109 | C9: =+[1]NAC!C10 -> 108.4 | D9: =+[1]NAC!D10 -> 109.8 | E9: =+[1]NAC!E10 -> 106.9 | F9: =+[1]NAC!F10 -> 117.4 | G9: =+[1]NAC!G10 -> 103.3 | H9: =+[1]NAC!H10 -> 109.1 | ... N9: =+[1]NAC!N10 -> 107.5 | O9: =+[1]NAC!P10 -> 108.2 | P9: =+[1]NAC!Q10 -> 107.4 | Q9: =+[1]NAC!R10 -> 114.5 | R9: =+SUMPRODUCT($C$3:$N$3,C9:N9) -> 109.04433 | S9: =+($C$3*$C9+$D$3*$D9+$E$3*$E9+$G$3*$G9+$K$3*$K9+$M$3*$M9+$N$3*$N9)/SUM($C$3:$E$3,$G$3,$K$3,$M$3:$N$3) -> 107.64676 | T9: =+($E$3*$E9+$G$3*$G9+$K$3*$K9+$M$3*$M9+$N$3*$N9)/SUM($E$3,$G$3,$K$3,$M$3:$N$3) -> 106.8725 | U9: =+($E$3*$E9+$G$3*$G9+$K$3*$K9+$N$3*$N9)/SUM($E$3,$G$3,$K$3,$N$3) -> 106.5019 | W9: =($E$3*$E9+SUMPRODUCT($G$3:$L$3,$G9:$L9)+$N$3*$N9)/SUM($E$3,$G$3:$L$3,$N$3) -> 107.97464 | Y9: =+B9/B8-1 -> 0.027332705 | Z9: =+C9/C8-1 -> 0.022641509 | AA9: =+D9/D8-1 -> 0.023299161 | AB9: =+E9/E8-1 -> 0.044965787 | AC9: =+F9/F8-1 -> 0.059566787 | AD9: =+G9/G8-1 -> 0.010763209 | AE9: =+H9/H8-1 -> 0.018674136 | AF9: =+I9/I8-1 -> 0.0066539924 | ... AT9: =+W9/W8-1 -> 0.024489086
A10: =+[1]NAC!A11 -> 42856 | B10: =+[1]NAC!B11 -> 110.5 | C10: =+[1]NAC!C11 -> 109.8 | D10: =+[1]NAC!D11 -> 111.7 | E10: =+[1]NAC!E11 -> 108.7 | F10: =+[1]NAC!F11 -> 119.5 | G10: =+[1]NAC!G11 -> 106.2 | H10: =+[1]NAC!H11 -> 110.7 | ... N10: =+[1]NAC!N11 -> 108.9 | O10: =+[1]NAC!P11 -> 109.1 | P10: =+[1]NAC!Q11 -> 109.2 | Q10: =+[1]NAC!R11 -> 115.7 | R10: =+SUMPRODUCT($C$3:$N$3,C10:N10) -> 110.59514 | S10: =+($C$3*$C10+$D$3*$D10+$E$3*$E10+$G$3*$G10+$K$3*$K10+$M$3*$M10+$N$3*$N10)/SUM($C$3:$E$3,$G$3,$K$3,$M$3:$N$3) -> 109.23839 | T10: =+($E$3*$E10+$G$3*$G10+$K$3*$K10+$M$3*$M10+$N$3*$N10)/SUM($E$3,$G$3,$K$3,$M$3:$N$3) -> 108.57789 | U10: =+($E$3*$E10+$G$3*$G10+$K$3*$K10+$N$3*$N10)/SUM($E$3,$G$3,$K$3,$N$3) -> 108.24193 | W10: =($E$3*$E10+SUMPRODUCT($G$3:$L$3,$G10:$L10)+$N$3*$N10)/SUM($E$3,$G$3:$L$3,$N$3) -> 109.47138 | Y10: =+B10/B9-1 -> 0.013761468 | Z10: =+C10/C9-1 -> 0.012915129 | AA10: =+D10/D9-1 -> 0.017304189 | AB10: =+E10/E9-1 -> 0.016838167 | AC10: =+F10/F9-1 -> 0.017887564 | AD10: =+G10/G9-1 -> 0.028073572 | AE10: =+H10/H9-1 -> 0.014665445 | AF10: =+I10/I9-1 -> 0.0094428706 | ... AT10: =+W10/W9-1 -> 0.013861955
A11: =+[1]NAC!A12 -> 42887 | B11: =+[1]NAC!B12 -> 111.8 | C11: =+[1]NAC!C12 -> 110.7 | D11: =+[1]NAC!D12 -> 112.5 | E11: =+[1]NAC!E12 -> 109.7 | F11: =+[1]NAC!F12 -> 121.6 | G11: =+[1]NAC!G12 -> 107.5 | H11: =+[1]NAC!H12 -> 112.4 | ... N11: =+[1]NAC!N12 -> 110.4 | O11: =+[1]NAC!P12 -> 110.1 | P11: =+[1]NAC!Q12 -> 110.7 | Q11: =+[1]NAC!R12 -> 116.7 | R11: =+SUMPRODUCT($C$3:$N$3,C11:N11) -> 111.87598 | S11: =+($C$3*$C11+$D$3*$D11+$E$3*$E11+$G$3*$G11+$K$3*$K11+$M$3*$M11+$N$3*$N11)/SUM($C$3:$E$3,$G$3,$K$3,$M$3:$N$3) -> 110.44671 | T11: =+($E$3*$E11+$G$3*$G11+$K$3*$K11+$M$3*$M11+$N$3*$N11)/SUM($E$3,$G$3,$K$3,$M$3:$N$3) -> 110.05715 | U11: =+($E$3*$E11+$G$3*$G11+$K$3*$K11+$N$3*$N11)/SUM($E$3,$G$3,$K$3,$N$3) -> 109.78012 | W11: =($E$3*$E11+SUMPRODUCT($G$3:$L$3,$G11:$L11)+$N$3*$N11)/SUM($E$3,$G$3:$L$3,$N$3) -> 110.83159 | Y11: =+B11/B10-1 -> 0.011764706 | Z11: =+C11/C10-1 -> 0.0081967213 | AA11: =+D11/D10-1 -> 0.0071620412 | AB11: =+E11/E10-1 -> 0.009199632 | AC11: =+F11/F10-1 -> 0.017573222 | AD11: =+G11/G10-1 -> 0.012241055 | AE11: =+H11/H10-1 -> 0.01535682 | AF11: =+I11/I10-1 -> 0.0065481759 | ... AT11: =+W11/W10-1 -> 0.012425193
A12: =+[1]NAC!A13 -> 42917 | B12: =+[1]NAC!B13 -> 113.8 | C12: =+[1]NAC!C13 -> 112 | D12: =+[1]NAC!D13 -> 115.8 | E12: =+[1]NAC!E13 -> 108.4 | F12: =+[1]NAC!F13 -> 124.1 | G12: =+[1]NAC!G13 -> 110.1 | H12: =+[1]NAC!H13 -> 116.1 | ... N12: =+[1]NAC!N13 -> 111.8 | O12: =+[1]NAC!P13 -> 110.6 | P12: =+[1]NAC!Q13 -> 112.6 | Q12: =+[1]NAC!R13 -> 119.4 | R12: =+SUMPRODUCT($C$3:$N$3,C12:N12) -> 113.81624 | S12: =+($C$3*$C12+$D$3*$D12+$E$3*$E12+$G$3*$G12+$K$3*$K12+$M$3*$M12+$N$3*$N12)/SUM($C$3:$E$3,$G$3,$K$3,$M$3:$N$3) -> 112.1048 | T12: =+($E$3*$E12+$G$3*$G12+$K$3*$K12+$M$3*$M12+$N$3*$N12)/SUM($E$3,$G$3,$K$3,$M$3:$N$3) -> 111.82429 | U12: =+($E$3*$E12+$G$3*$G12+$K$3*$K12+$N$3*$N12)/SUM($E$3,$G$3,$K$3,$N$3) -> 111.17489 | W12: =($E$3*$E12+SUMPRODUCT($G$3:$L$3,$G12:$L12)+$N$3*$N12)/SUM($E$3,$G$3:$L$3,$N$3) -> 112.74652 | Y12: =+B12/B11-1 -> 0.017889088 | Z12: =+C12/C11-1 -> 0.011743451 | AA12: =+D12/D11-1 -> 0.029333333 | AB12: =+E12/E11-1 -> -0.011850501 | AC12: =+F12/F11-1 -> 0.020559211 | AD12: =+G12/G11-1 -> 0.024186047 | AE12: =+H12/H11-1 -> 0.032918149 | AF12: =+I12/I11-1 -> 0.021375465 | ... AT12: =+W12/W11-1 -> 0.017277841
A13: =+[1]NAC!A14 -> 42948 | B13: =+[1]NAC!B14 -> 115.4 | C13: =+[1]NAC!C14 -> 114.3 | D13: =+[1]NAC!D14 -> 117.3 | E13: =+[1]NAC!E14 -> 107.7 | F13: =+[1]NAC!F14 -> 126.8 | G13: =+[1]NAC!G14 -> 111.2 | H13: =+[1]NAC!H14 -> 119 | ... N13: =+[1]NAC!N14 -> 113.6 | O13: =+[1]NAC!P14 -> 111.8 | P13: =+[1]NAC!Q14 -> 114.2 | Q13: =+[1]NAC!R14 -> 121.1 | R13: =+SUMPRODUCT($C$3:$N$3,C13:N13) -> 115.41012 | S13: =+($C$3*$C13+$D$3*$D13+$E$3*$E13+$G$3*$G13+$K$3*$K13+$M$3*$M13+$N$3*$N13)/SUM($C$3:$E$3,$G$3,$K$3,$M$3:$N$3) -> 113.40939 | T13: =+($E$3*$E13+$G$3*$G13+$K$3*$K13+$M$3*$M13+$N$3*$N13)/SUM($E$3,$G$3,$K$3,$M$3:$N$3) -> 112.36322 | U13: =+($E$3*$E13+$G$3*$G13+$K$3*$K13+$N$3*$N13)/SUM($E$3,$G$3,$K$3,$N$3) -> 111.62802 | W13: =($E$3*$E13+SUMPRODUCT($G$3:$L$3,$G13:$L13)+$N$3*$N13)/SUM($E$3,$G$3:$L$3,$N$3) -> 113.90882 | Y13: =+B13/B12-1 -> 0.014059754 | Z13: =+C13/C12-1 -> 0.020535714 | AA13: =+D13/D12-1 -> 0.012953368 | AB13: =+E13/E12-1 -> -0.0064575646 | AC13: =+F13/F12-1 -> 0.021756648 | AD13: =+G13/G12-1 -> 0.0099909173 | AE13: =+H13/H12-1 -> 0.024978467 | AF13: =+I13/I12-1 -> 0.010919017 | ... AT13: =+W13/W12-1 -> 0.010309044
A14: =+[1]NAC!A15 -> 42979 | B14: =+[1]NAC!B15 -> 117.6 | C14: =+[1]NAC!C15 -> 116.4 | D14: =+[1]NAC!D15 -> 118.1 | E14: =+[1]NAC!E15 -> 111.8 | F14: =+[1]NAC!F15 -> 129.3 | G14: =+[1]NAC!G15 -> 112.3 | H14: =+[1]NAC!H15 -> 121.9 | ... N14: =+[1]NAC!N15 -> 115.5 | O14: =+[1]NAC!P15 -> 116.2 | P14: =+[1]NAC!Q15 -> 116.1 | Q14: =+[1]NAC!R15 -> 123.2 | R14: =+SUMPRODUCT($C$3:$N$3,C14:N14) -> 117.62312 | S14: =+($C$3*$C14+$D$3*$D14+$E$3*$E14+$G$3*$G14+$K$3*$K14+$M$3*$M14+$N$3*$N14)/SUM($C$3:$E$3,$G$3,$K$3,$M$3:$N$3) -> 115.67394 | T14: =+($E$3*$E14+$G$3*$G14+$K$3*$K14+$M$3*$M14+$N$3*$N14)/SUM($E$3,$G$3,$K$3,$M$3:$N$3) -> 114.89355 | U14: =+($E$3*$E14+$G$3*$G14+$K$3*$K14+$N$3*$N14)/SUM($E$3,$G$3,$K$3,$N$3) -> 114.46413 | W14: =($E$3*$E14+SUMPRODUCT($G$3:$L$3,$G14:$L14)+$N$3*$N14)/SUM($E$3,$G$3:$L$3,$N$3) -> 116.33162 | Y14: =+B14/B13-1 -> 0.019064125 | Z14: =+C14/C13-1 -> 0.018372703 | AA14: =+D14/D13-1 -> 0.0068201194 | AB14: =+E14/E13-1 -> 0.038068709 | AC14: =+F14/F13-1 -> 0.019716088 | AD14: =+G14/G13-1 -> 0.0098920863 | AE14: =+H14/H13-1 -> 0.024369748 | AF14: =+I14/I13-1 -> 0.0081008101 | ... AT14: =+W14/W13-1 -> 0.021269587
A15: =+[1]NAC!A16 -> 43009 | B15: =+[1]NAC!B16 -> 119.4 | C15: =+[1]NAC!C16 -> 118.2 | D15: =+[1]NAC!D16 -> 121.7 | E15: =+[1]NAC!E16 -> 114.1 | F15: =+[1]NAC!F16 -> 130.4 | G15: =+[1]NAC!G16 -> 113.1 | H15: =+[1]NAC!H16 -> 123.2 | ... N15: =+[1]NAC!N16 -> 117.1 | O15: =+[1]NAC!P16 -> 119 | P15: =+[1]NAC!Q16 -> 117.6 | Q15: =+[1]NAC!R16 -> 125.3 | R15: =+SUMPRODUCT($C$3:$N$3,C15:N15) -> 119.39189 | S15: =+($C$3*$C15+$D$3*$D15+$E$3*$E15+$G$3*$G15+$K$3*$K15+$M$3*$M15+$N$3*$N15)/SUM($C$3:$E$3,$G$3,$K$3,$M$3:$N$3) -> 117.47653 | T15: =+($E$3*$E15+$G$3*$G15+$K$3*$K15+$M$3*$M15+$N$3*$N15)/SUM($E$3,$G$3,$K$3,$M$3:$N$3) -> 116.52339 | U15: =+($E$3*$E15+$G$3*$G15+$K$3*$K15+$N$3*$N15)/SUM($E$3,$G$3,$K$3,$N$3) -> 116.10378 | W15: =($E$3*$E15+SUMPRODUCT($G$3:$L$3,$G15:$L15)+$N$3*$N15)/SUM($E$3,$G$3:$L$3,$N$3) -> 118.11138 | Y15: =+B15/B14-1 -> 0.015306122 | Z15: =+C15/C14-1 -> 0.015463918 | AA15: =+D15/D14-1 -> 0.030482642 | AB15: =+E15/E14-1 -> 0.020572451 | AC15: =+F15/F14-1 -> 0.0085073473 | AD15: =+G15/G14-1 -> 0.0071237756 | AE15: =+H15/H14-1 -> 0.010664479 | AF15: =+I15/I14-1 -> 0.0125 | ... AT15: =+W15/W14-1 -> 0.015299068
A16: =+[1]NAC!A17 -> 43040 | B16: =+[1]NAC!B17 -> 121 | C16: =+[1]NAC!C17 -> 119.6 | D16: =+[1]NAC!D17 -> 123 | E16: =+[1]NAC!E17 -> 115.7 | F16: =+[1]NAC!F17 -> 132 | G16: =+[1]NAC!G17 -> 114.1 | H16: =+[1]NAC!H17 -> 124.8 | ... N16: =+[1]NAC!N17 -> 118.5 | O16: =+[1]NAC!P17 -> 121.1 | P16: =+[1]NAC!Q17 -> 119.1 | Q16: =+[1]NAC!R17 -> 127.1 | R16: =+SUMPRODUCT($C$3:$N$3,C16:N16) -> 121.04068 | S16: =+($C$3*$C16+$D$3*$D16+$E$3*$E16+$G$3*$G16+$K$3*$K16+$M$3*$M16+$N$3*$N16)/SUM($C$3:$E$3,$G$3,$K$3,$M$3:$N$3) -> 118.915 | T16: =+($E$3*$E16+$G$3*$G16+$K$3*$K16+$M$3*$M16+$N$3*$N16)/SUM($E$3,$G$3,$K$3,$M$3:$N$3) -> 118.00416 | U16: =+($E$3*$E16+$G$3*$G16+$K$3*$K16+$N$3*$N16)/SUM($E$3,$G$3,$K$3,$N$3) -> 117.34815 | W16: =($E$3*$E16+SUMPRODUCT($G$3:$L$3,$G16:$L16)+$N$3*$N16)/SUM($E$3,$G$3:$L$3,$N$3) -> 119.82831 | Y16: =+B16/B15-1 -> 0.013400335 | Z16: =+C16/C15-1 -> 0.011844332 | AA16: =+D16/D15-1 -> 0.010682005 | AB16: =+E16/E15-1 -> 0.014022787 | AC16: =+F16/F15-1 -> 0.012269939 | AD16: =+G16/G15-1 -> 0.008841733 | AE16: =+H16/H15-1 -> 0.012987013 | AF16: =+I16/I15-1 -> 0.029982363 | ... AT16: =+W16/W15-1 -> 0.014536514
A17: =+[1]NAC!A18 -> 43070 | B17: =+[1]NAC!B18 -> 124.8 | C17: =+[1]NAC!C18 -> 120.4 | D17: =+[1]NAC!D18 -> 123.7 | E17: =+[1]NAC!E18 -> 116.6 | F17: =+[1]NAC!F18 -> 155.6 | G17: =+[1]NAC!G18 -> 117.4 | H17: =+[1]NAC!H18 -> 127.8 | ... N17: =+[1]NAC!N18 -> 119.8 | O17: =+[1]NAC!P18 -> 121.5 | P17: =+[1]NAC!Q18 -> 121.1 | Q17: =+[1]NAC!R18 -> 138.7 | R17: =+SUMPRODUCT($C$3:$N$3,C17:N17) -> 124.825 | S17: =+($C$3*$C17+$D$3*$D17+$E$3*$E17+$G$3*$G17+$K$3*$K17+$M$3*$M17+$N$3*$N17)/SUM($C$3:$E$3,$G$3,$K$3,$M$3:$N$3) -> 120.17705 | T17: =+($E$3*$E17+$G$3*$G17+$K$3*$K17+$M$3*$M17+$N$3*$N17)/SUM($E$3,$G$3,$K$3,$M$3:$N$3) -> 119.66742 | U17: =+($E$3*$E17+$G$3*$G17+$K$3*$K17+$N$3*$N17)/SUM($E$3,$G$3,$K$3,$N$3) -> 118.86786 | W17: =($E$3*$E17+SUMPRODUCT($G$3:$L$3,$G17:$L17)+$N$3*$N17)/SUM($E$3,$G$3:$L$3,$N$3) -> 122.03885 | Y17: =+B17/B16-1 -> 0.031404959 | Z17: =+C17/C16-1 -> 0.0066889632 | AA17: =+D17/D16-1 -> 0.0056910569 | AB17: =+E17/E16-1 -> 0.0077787381 | AC17: =+F17/F16-1 -> 0.17878788 | AD17: =+G17/G16-1 -> 0.028921998 | AE17: =+H17/H16-1 -> 0.024038462 | AF17: =+I17/I16-1 -> 0.032534247 | ... AT17: =+W17/W16-1 -> 0.018447587 | AV17: =+B17/B5-1 -> 0.248 | AW17: =+C17/C5-1 -> 0.204 | AX17: =+D17/D5-1 -> 0.237 | AY17: =+E17/E5-1 -> 0.166 | AZ17: =+F17/F5-1 -> 0.556 | BA17: =+G17/G5-1 -> 0.174 | BB17: =+H17/H5-1 -> 0.278 | BC17: =+I17/I5-1 -> 0.206 | ... BQ17: =+W17/W5-1 -> 0.22038854
A18: =+[1]NAC!A19 -> 43101 | B18: =+[1]NAC!B19 -> 127 | C18: =+[1]NAC!C19 -> 122.9 | D18: =+[1]NAC!D19 -> 126.6 | E18: =+[1]NAC!E19 -> 115.7 | F18: =+[1]NAC!F19 -> 157.2 | G18: =+[1]NAC!G19 -> 118.7 | H18: =+[1]NAC!H19 -> 130 | ... N18: =+[1]NAC!N19 -> 122.7 | O18: =+[1]NAC!P19 -> 124.7 | P18: =+[1]NAC!Q19 -> 122.9 | Q18: =+[1]NAC!R19 -> 141.7 | R18: =+SUMPRODUCT($C$3:$N$3,C18:N18) -> 127.02727 | S18: =+($C$3*$C18+$D$3*$D18+$E$3*$E18+$G$3*$G18+$K$3*$K18+$M$3*$M18+$N$3*$N18)/SUM($C$3:$E$3,$G$3,$K$3,$M$3:$N$3) -> 122.43069 | T18: =+($E$3*$E18+$G$3*$G18+$K$3*$K18+$M$3*$M18+$N$3*$N18)/SUM($E$3,$G$3,$K$3,$M$3:$N$3) -> 121.67345 | U18: =+($E$3*$E18+$G$3*$G18+$K$3*$K18+$N$3*$N18)/SUM($E$3,$G$3,$K$3,$N$3) -> 120.34997 | W18: =($E$3*$E18+SUMPRODUCT($G$3:$L$3,$G18:$L18)+$N$3*$N18)/SUM($E$3,$G$3:$L$3,$N$3) -> 123.90447 | Y18: =+B18/B17-1 -> 0.017628205 | Z18: =+C18/C17-1 -> 0.02076412 | AA18: =+D18/D17-1 -> 0.023443816 | AB18: =+E18/E17-1 -> -0.0077186964 | AC18: =+F18/F17-1 -> 0.010282776 | AD18: =+G18/G17-1 -> 0.011073254 | AE18: =+H18/H17-1 -> 0.017214397 | AF18: =+I18/I17-1 -> 0.021558872 | ... AT18: =+W18/W17-1 -> 0.015287026 | AV18: =+B18/B6-1 -> 0.25 | AW18: =+C18/C6-1 -> 0.21322804 | AX18: =+D18/D6-1 -> 0.25470763 | AY18: =+E18/E6-1 -> 0.16868687 | AZ18: =+F18/F6-1 -> 0.54876847 | BA18: =+G18/G6-1 -> 0.17641229 | BB18: =+H18/H6-1 -> 0.26953125 | BC18: =+I18/I6-1 -> 0.20666014 | ... BQ18: =+W18/W6-1 -> 0.22029215
A19: =+[1]NAC!A20 -> 43132 | B19: =+[1]NAC!B20 -> 130.1 | C19: =+[1]NAC!C20 -> 125.6 | D19: =+[1]NAC!D20 -> 128.7 | E19: =+[1]NAC!E20 -> 115 | F19: =+[1]NAC!F20 -> 163.2 | G19: =+[1]NAC!G20 -> 120.7 | H19: =+[1]NAC!H20 -> 133.1 | ... N19: =+[1]NAC!N20 -> 124.9 | O19: =+[1]NAC!P20 -> 123.9 | P19: =+[1]NAC!Q20 -> 125.5 | Q19: =+[1]NAC!R20 -> 148.5 | R19: =+SUMPRODUCT($C$3:$N$3,C19:N19) -> 130.12872 | S19: =+($C$3*$C19+$D$3*$D19+$E$3*$E19+$G$3*$G19+$K$3*$K19+$M$3*$M19+$N$3*$N19)/SUM($C$3:$E$3,$G$3,$K$3,$M$3:$N$3) -> 124.33286 | T19: =+($E$3*$E19+$G$3*$G19+$K$3*$K19+$M$3*$M19+$N$3*$N19)/SUM($E$3,$G$3,$K$3,$M$3:$N$3) -> 122.95795 | U19: =+($E$3*$E19+$G$3*$G19+$K$3*$K19+$N$3*$N19)/SUM($E$3,$G$3,$K$3,$N$3) -> 121.20208 | W19: =($E$3*$E19+SUMPRODUCT($G$3:$L$3,$G19:$L19)+$N$3*$N19)/SUM($E$3,$G$3:$L$3,$N$3) -> 126.83914 | Y19: =+B19/B18-1 -> 0.024409449 | Z19: =+C19/C18-1 -> 0.021969081 | AA19: =+D19/D18-1 -> 0.016587678 | AB19: =+E19/E18-1 -> -0.0060501296 | AC19: =+F19/F18-1 -> 0.038167939 | AD19: =+G19/G18-1 -> 0.0168492 | AE19: =+H19/H18-1 -> 0.023846154 | AF19: =+I19/I18-1 -> 0.045454545 | ... AT19: =+W19/W18-1 -> 0.023684988 | AV19: =+B19/B7-1 -> 0.25458052 | AW19: =+C19/C7-1 -> 0.21705426 | AX19: =+D19/D7-1 -> 0.22338403 | AY19: =+E19/E7-1 -> 0.1627907 | AZ19: =+F19/F7-1 -> 0.52523364 | BA19: =+G19/G7-1 -> 0.19151037 | BB19: =+H19/H7-1 -> 0.26641294 | BC19: =+I19/I7-1 -> 0.23846154 | ... BQ19: =+W19/W7-1 -> 0.23159118
A20: =+[1]NAC!A21 -> 43160 | B20: =+[1]NAC!B21 -> 133.1 | C20: =+[1]NAC!C21 -> 128.5 | D20: =+[1]NAC!D21 -> 129.6 | E20: =+[1]NAC!E21 -> 120.1 | F20: =+[1]NAC!F21 -> 164.1 | G20: =+[1]NAC!G21 -> 126.2 | H20: =+[1]NAC!H21 -> 134.8 | ... N20: =+[1]NAC!N21 -> 127.2 | O20: =+[1]NAC!P21 -> 125.9 | P20: =+[1]NAC!Q21 -> 128.7 | Q20: =+[1]NAC!R21 -> 151.5 | R20: =+SUMPRODUCT($C$3:$N$3,C20:N20) -> 133.21068 | S20: =+($C$3*$C20+$D$3*$D20+$E$3*$E20+$G$3*$G20+$K$3*$K20+$M$3*$M20+$N$3*$N20)/SUM($C$3:$E$3,$G$3,$K$3,$M$3:$N$3) -> 127.44051 | T20: =+($E$3*$E20+$G$3*$G20+$K$3*$K20+$M$3*$M20+$N$3*$N20)/SUM($E$3,$G$3,$K$3,$M$3:$N$3) -> 126.43592 | U20: =+($E$3*$E20+$G$3*$G20+$K$3*$K20+$N$3*$N20)/SUM($E$3,$G$3,$K$3,$N$3) -> 125.06723 | W20: =($E$3*$E20+SUMPRODUCT($G$3:$L$3,$G20:$L20)+$N$3*$N20)/SUM($E$3,$G$3:$L$3,$N$3) -> 130.70398 | Y20: =+B20/B19-1 -> 0.023059185 | Z20: =+C20/C19-1 -> 0.023089172 | AA20: =+D20/D19-1 -> 0.006993007 | AB20: =+E20/E19-1 -> 0.044347826 | AC20: =+F20/F19-1 -> 0.0055147059 | AD20: =+G20/G19-1 -> 0.045567523 | AE20: =+H20/H19-1 -> 0.012772352 | AF20: =+I20/I19-1 -> 0.017857143 | ... AT20: =+W20/W19-1 -> 0.030470416 | AV20: =+B20/B8-1 -> 0.25447691 | AW20: =+C20/C8-1 -> 0.21226415 | AX20: =+D20/D8-1 -> 0.20782852 | AY20: =+E20/E8-1 -> 0.17399804 | AZ20: =+F20/F8-1 -> 0.48104693 | BA20: =+G20/G8-1 -> 0.23483366 | BB20: =+H20/H8-1 -> 0.25863679 | BC20: =+I20/I8-1 -> 0.24619772 | ... BQ20: =+W20/W8-1 -> 0.24015047
A21: =+[1]NAC!A22 -> 43191 | B21: =+[1]NAC!B22 -> 136.8 | C21: =+[1]NAC!C22 -> 130 | D21: =+[1]NAC!D22 -> 131.3 | E21: =+[1]NAC!E22 -> 124.9 | F21: =+[1]NAC!F22 -> 177.2 | G21: =+[1]NAC!G22 -> 127.8 | H21: =+[1]NAC!H22 -> 137.2 | ... N21: =+[1]NAC!N22 -> 129.3 | O21: =+[1]NAC!P22 -> 127 | P21: =+[1]NAC!Q22 -> 131.5 | Q21: =+[1]NAC!R22 -> 159.5 | R21: =+SUMPRODUCT($C$3:$N$3,C21:N21) -> 136.84927 | S21: =+($C$3*$C21+$D$3*$D21+$E$3*$E21+$G$3*$G21+$K$3*$K21+$M$3*$M21+$N$3*$N21)/SUM($C$3:$E$3,$G$3,$K$3,$M$3:$N$3) -> 129.79367 | T21: =+($E$3*$E21+$G$3*$G21+$K$3*$K21+$M$3*$M21+$N$3*$N21)/SUM($E$3,$G$3,$K$3,$M$3:$N$3) -> 129.49251 | U21: =+($E$3*$E21+$G$3*$G21+$K$3*$K21+$N$3*$N21)/SUM($E$3,$G$3,$K$3,$N$3) -> 128.14243 | W21: =($E$3*$E21+SUMPRODUCT($G$3:$L$3,$G21:$L21)+$N$3*$N21)/SUM($E$3,$G$3:$L$3,$N$3) -> 133.97038 | Y21: =+B21/B20-1 -> 0.027798648 | Z21: =+C21/C20-1 -> 0.011673152 | AA21: =+D21/D20-1 -> 0.013117284 | AB21: =+E21/E20-1 -> 0.039966694 | AC21: =+F21/F20-1 -> 0.079829372 | AD21: =+G21/G20-1 -> 0.012678288 | AE21: =+H21/H20-1 -> 0.017804154 | AF21: =+I21/I20-1 -> 0.039664378 | ... AT21: =+W21/W20-1 -> 0.024990783 | AV21: =+B21/B9-1 -> 0.25504587 | AW21: =+C21/C9-1 -> 0.19926199 | AX21: =+D21/D9-1 -> 0.19581056 | AY21: =+E21/E9-1 -> 0.16838167 | AZ21: =+F21/F9-1 -> 0.50936968 | BA21: =+G21/G9-1 -> 0.23717328 | BB21: =+H21/H9-1 -> 0.25756187 | BC21: =+I21/I9-1 -> 0.28706327 | ... BQ21: =+W21/W9-1 -> 0.24075778
A22: =+[1]NAC!A23 -> 43221 | B22: =+[1]NAC!B23 -> 139.6 | C22: =+[1]NAC!C23 -> 134.2 | D22: =+[1]NAC!D23 -> 133.4 | E22: =+[1]NAC!E23 -> 127.4 | F22: =+[1]NAC!F23 -> 175.9 | G22: =+[1]NAC!G23 -> 130.6 | H22: =+[1]NAC!H23 -> 140.3 | ... N22: =+[1]NAC!N23 -> 131.9 | O22: =+[1]NAC!P23 -> 130.2 | P22: =+[1]NAC!Q23 -> 135 | Q22: =+[1]NAC!R23 -> 160 | R22: =+SUMPRODUCT($C$3:$N$3,C22:N22) -> 139.71396 | S22: =+($C$3*$C22+$D$3*$D22+$E$3*$E22+$G$3*$G22+$K$3*$K22+$M$3*$M22+$N$3*$N22)/SUM($C$3:$E$3,$G$3,$K$3,$M$3:$N$3) -> 133.17826 | T22: =+($E$3*$E22+$G$3*$G22+$K$3*$K22+$M$3*$M22+$N$3*$N22)/SUM($E$3,$G$3,$K$3,$M$3:$N$3) -> 132.39032 | U22: =+($E$3*$E22+$G$3*$G22+$K$3*$K22+$N$3*$N22)/SUM($E$3,$G$3,$K$3,$N$3) -> 130.9409 | W22: =($E$3*$E22+SUMPRODUCT($G$3:$L$3,$G22:$L22)+$N$3*$N22)/SUM($E$3,$G$3:$L$3,$N$3) -> 136.89231 | Y22: =+B22/B21-1 -> 0.020467836 | Z22: =+C22/C21-1 -> 0.032307692 | AA22: =+D22/D21-1 -> 0.015993907 | AB22: =+E22/E21-1 -> 0.020016013 | AC22: =+F22/F21-1 -> -0.0073363431 | AD22: =+G22/G21-1 -> 0.021909233 | AE22: =+H22/H21-1 -> 0.022594752 | AF22: =+I22/I21-1 -> 0.019075569 | ... AT22: =+W22/W21-1 -> 0.02181026 | AV22: =+B22/B10-1 -> 0.26334842 | AW22: =+C22/C10-1 -> 0.22222222 | AX22: =+D22/D10-1 -> 0.19427037 | AY22: =+E22/E10-1 -> 0.17203312 | AZ22: =+F22/F10-1 -> 0.47196653 | BA22: =+G22/G10-1 -> 0.22975518 | BB22: =+H22/H10-1 -> 0.26738934 | BC22: =+I22/I10-1 -> 0.29934518 | ... BQ22: =+W22/W10-1 -> 0.25048486
A23: =+[1]NAC!A24 -> 43252 | B23: =+[1]NAC!B24 -> 144.8 | C23: =+[1]NAC!C24 -> 141.2 | D23: =+[1]NAC!D24 -> 134.6 | E23: =+[1]NAC!E24 -> 129.8 | F23: =+[1]NAC!F24 -> 180.6 | G23: =+[1]NAC!G24 -> 135.8 | H23: =+[1]NAC!H24 -> 146.3 | ... N23: =+[1]NAC!N24 -> 136.1 | O23: =+[1]NAC!P24 -> 134.5 | P23: =+[1]NAC!Q24 -> 140.5 | Q23: =+[1]NAC!R24 -> 164.7 | R23: =+SUMPRODUCT($C$3:$N$3,C23:N23) -> 144.91444 | S23: =+($C$3*$C23+$D$3*$D23+$E$3*$E23+$G$3*$G23+$K$3*$K23+$M$3*$M23+$N$3*$N23)/SUM($C$3:$E$3,$G$3,$K$3,$M$3:$N$3) -> 138.14922 | T23: =+($E$3*$E23+$G$3*$G23+$K$3*$K23+$M$3*$M23+$N$3*$N23)/SUM($E$3,$G$3,$K$3,$M$3:$N$3) -> 136.2058 | U23: =+($E$3*$E23+$G$3*$G23+$K$3*$K23+$N$3*$N23)/SUM($E$3,$G$3,$K$3,$N$3) -> 134.82721 | W23: =($E$3*$E23+SUMPRODUCT($G$3:$L$3,$G23:$L23)+$N$3*$N23)/SUM($E$3,$G$3:$L$3,$N$3) -> 141.78786 | Y23: =+B23/B22-1 -> 0.037249284 | Z23: =+C23/C22-1 -> 0.052160954 | AA23: =+D23/D22-1 -> 0.0089955022 | AB23: =+E23/E22-1 -> 0.018838305 | AC23: =+F23/F22-1 -> 0.026719727 | AD23: =+G23/G22-1 -> 0.039816233 | AE23: =+H23/H22-1 -> 0.042765502 | AF23: =+I23/I22-1 -> 0.05975522 | ... AT23: =+W23/W22-1 -> 0.035762105 | AV23: =+B23/B11-1 -> 0.29516995 | AW23: =+C23/C11-1 -> 0.27551942 | AX23: =+D23/D11-1 -> 0.19644444 | AY23: =+E23/E11-1 -> 0.18322698 | AZ23: =+F23/F11-1 -> 0.48519737 | BA23: =+G23/G11-1 -> 0.26325581 | BB23: =+H23/H11-1 -> 0.30160142 | BC23: =+I23/I11-1 -> 0.36802974 | ... BQ23: =+W23/W11-1 -> 0.27930917
A24: =+[1]NAC!A25 -> 43282 | B24: =+[1]NAC!B25 -> 149.3 | C24: =+[1]NAC!C25 -> 146.8 | D24: =+[1]NAC!D25 -> 138.1 | E24: =+[1]NAC!E25 -> 129.6 | F24: =+[1]NAC!F25 -> 182.4 | G24: =+[1]NAC!G25 -> 141.5 | H24: =+[1]NAC!H25 -> 150.4 | ... N24: =+[1]NAC!N25 -> 141.4 | O24: =+[1]NAC!P25 -> 139.6 | P24: =+[1]NAC!Q25 -> 145 | Q24: =+[1]NAC!R25 -> 169 | R24: =+SUMPRODUCT($C$3:$N$3,C24:N24) -> 149.37523 | S24: =+($C$3*$C24+$D$3*$D24+$E$3*$E24+$G$3*$G24+$K$3*$K24+$M$3*$M24+$N$3*$N24)/SUM($C$3:$E$3,$G$3,$K$3,$M$3:$N$3) -> 142.71894 | T24: =+($E$3*$E24+$G$3*$G24+$K$3*$K24+$M$3*$M24+$N$3*$N24)/SUM($E$3,$G$3,$K$3,$M$3:$N$3) -> 140.10667 | U24: =+($E$3*$E24+$G$3*$G24+$K$3*$K24+$N$3*$N24)/SUM($E$3,$G$3,$K$3,$N$3) -> 138.6955 | W24: =($E$3*$E24+SUMPRODUCT($G$3:$L$3,$G24:$L24)+$N$3*$N24)/SUM($E$3,$G$3:$L$3,$N$3) -> 146.28401 | Y24: =+B24/B23-1 -> 0.031077348 | Z24: =+C24/C23-1 -> 0.039660057 | AA24: =+D24/D23-1 -> 0.026002972 | AB24: =+E24/E23-1 -> -0.001540832 | AC24: =+F24/F23-1 -> 0.0099667774 | AD24: =+G24/G23-1 -> 0.04197349 | AE24: =+H24/H23-1 -> 0.028024607 | AF24: =+I24/I23-1 -> 0.051630435 | ... AT24: =+W24/W23-1 -> 0.03171041 | AV24: =+B24/B12-1 -> 0.31195079 | AW24: =+C24/C12-1 -> 0.31071429 | AX24: =+D24/D12-1 -> 0.1925734 | AY24: =+E24/E12-1 -> 0.19557196 | AZ24: =+F24/F12-1 -> 0.46978243 | BA24: =+G24/G12-1 -> 0.28519528 | BB24: =+H24/H12-1 -> 0.29543497 | BC24: =+I24/I12-1 -> 0.40855323 | ... BQ24: =+W24/W12-1 -> 0.29745929
A25: =+[1]NAC!A26 -> 43313 | B25: =+[1]NAC!B26 -> 155.1 | C25: =+[1]NAC!C26 -> 152.7 | D25: =+[1]NAC!D26 -> 140 | E25: =+[1]NAC!E26 -> 130.1 | F25: =+[1]NAC!F26 -> 193.7 | G25: =+[1]NAC!G26 -> 146 | H25: =+[1]NAC!H26 -> 156.5 | ... N25: =+[1]NAC!N26 -> 148.3 | O25: =+[1]NAC!P26 -> 142.3 | P25: =+[1]NAC!Q26 -> 149.8 | Q25: =+[1]NAC!R26 -> 179.5 | R25: =+SUMPRODUCT($C$3:$N$3,C25:N25) -> 155.16175 | S25: =+($C$3*$C25+$D$3*$D25+$E$3*$E25+$G$3*$G25+$K$3*$K25+$M$3*$M25+$N$3*$N25)/SUM($C$3:$E$3,$G$3,$K$3,$M$3:$N$3) -> 147.08139 | T25: =+($E$3*$E25+$G$3*$G25+$K$3*$K25+$M$3*$M25+$N$3*$N25)/SUM($E$3,$G$3,$K$3,$M$3:$N$3) -> 143.55515 | U25: =+($E$3*$E25+$G$3*$G25+$K$3*$K25+$N$3*$N25)/SUM($E$3,$G$3,$K$3,$N$3) -> 142.12705 | W25: =($E$3*$E25+SUMPRODUCT($G$3:$L$3,$G25:$L25)+$N$3*$N25)/SUM($E$3,$G$3:$L$3,$N$3) -> 151.65799 | Y25: =+B25/B24-1 -> 0.038847957 | Z25: =+C25/C24-1 -> 0.040190736 | AA25: =+D25/D24-1 -> 0.013758146 | AB25: =+E25/E24-1 -> 0.0038580247 | AC25: =+F25/F24-1 -> 0.061951754 | AD25: =+G25/G24-1 -> 0.03180212 | AE25: =+H25/H24-1 -> 0.040558511 | AF25: =+I25/I24-1 -> 0.040697674 | ... AT25: =+W25/W24-1 -> 0.03673661 | AV25: =+B25/B13-1 -> 0.3440208 | AW25: =+C25/C13-1 -> 0.33595801 | AX25: =+D25/D13-1 -> 0.19352089 | AY25: =+E25/E13-1 -> 0.20798514 | AZ25: =+F25/F13-1 -> 0.52760252 | BA25: =+G25/G13-1 -> 0.31294964 | BB25: =+H25/H13-1 -> 0.31512605 | BC25: =+I25/I13-1 -> 0.450045 | ... BQ25: =+W25/W13-1 -> 0.33139811
A26: =+[1]NAC!A27 -> 43344 | B26: =+[1]NAC!B27 -> 165.2 | C26: =+[1]NAC!C27 -> 163.4 | D26: =+[1]NAC!D27 -> 146.2 | E26: =+[1]NAC!E27 -> 142.8 | F26: =+[1]NAC!F27 -> 198.1 | G26: =+[1]NAC!G27 -> 160.2 | H26: =+[1]NAC!H27 -> 163.6 | ... N26: =+[1]NAC!N27 -> 160.1 | O26: =+[1]NAC!P27 -> 148 | P26: =+[1]NAC!Q27 -> 161.3 | Q26: =+[1]NAC!R27 -> 187.9 | R26: =+SUMPRODUCT($C$3:$N$3,C26:N26) -> 165.34949 | S26: =+($C$3*$C26+$D$3*$D26+$E$3*$E26+$G$3*$G26+$K$3*$K26+$M$3*$M26+$N$3*$N26)/SUM($C$3:$E$3,$G$3,$K$3,$M$3:$N$3) -> 157.91047 | T26: =+($E$3*$E26+$G$3*$G26+$K$3*$K26+$M$3*$M26+$N$3*$N26)/SUM($E$3,$G$3,$K$3,$M$3:$N$3) -> 154.93095 | U26: =+($E$3*$E26+$G$3*$G26+$K$3*$K26+$N$3*$N26)/SUM($E$3,$G$3,$K$3,$N$3) -> 154.44809 | W26: =($E$3*$E26+SUMPRODUCT($G$3:$L$3,$G26:$L26)+$N$3*$N26)/SUM($E$3,$G$3:$L$3,$N$3) -> 163.20773 | Y26: =+B26/B25-1 -> 0.065119278 | Z26: =+C26/C25-1 -> 0.070072037 | AA26: =+D26/D25-1 -> 0.044285714 | AB26: =+E26/E25-1 -> 0.097617218 | AC26: =+F26/F25-1 -> 0.022715539 | AD26: =+G26/G25-1 -> 0.097260274 | AE26: =+H26/H25-1 -> 0.045367412 | AF26: =+I26/I25-1 -> 0.10366232 | ... AT26: =+W26/W25-1 -> 0.076156481 | AV26: =+B26/B14-1 -> 0.4047619 | AW26: =+C26/C14-1 -> 0.40378007 | AX26: =+D26/D14-1 -> 0.23793395 | AY26: =+E26/E14-1 -> 0.27728086 | AZ26: =+F26/F14-1 -> 0.5320959 | BA26: =+G26/G14-1 -> 0.42653606 | BB26: =+H26/H14-1 -> 0.34208368 | BC26: =+I26/I14-1 -> 0.5875 | ... BQ26: =+W26/W14-1 -> 0.40295249
A27: =+[1]NAC!A28 -> 43374 | B27: =+[1]NAC!B28 -> 174.1 | C27: =+[1]NAC!C28 -> 173 | D27: =+[1]NAC!D28 -> 149.6 | E27: =+[1]NAC!E28 -> 150 | F27: =+[1]NAC!F28 -> 215.5 | G27: =+[1]NAC!G28 -> 167 | H27: =+[1]NAC!H28 -> 172.6 | ... N27: =+[1]NAC!N28 -> 170 | O27: =+[1]NAC!P28 -> 157.2 | P27: =+[1]NAC!Q28 -> 168.6 | Q27: =+[1]NAC!R28 -> 201.9 | R27: =+SUMPRODUCT($C$3:$N$3,C27:N27) -> 174.28502 | S27: =+($C$3*$C27+$D$3*$D27+$E$3*$E27+$G$3*$G27+$K$3*$K27+$M$3*$M27+$N$3*$N27)/SUM($C$3:$E$3,$G$3,$K$3,$M$3:$N$3) -> 165.37572 | T27: =+($E$3*$E27+$G$3*$G27+$K$3*$K27+$M$3*$M27+$N$3*$N27)/SUM($E$3,$G$3,$K$3,$M$3:$N$3) -> 161.19003 | U27: =+($E$3*$E27+$G$3*$G27+$K$3*$K27+$N$3*$N27)/SUM($E$3,$G$3,$K$3,$N$3) -> 161.15389 | W27: =($E$3*$E27+SUMPRODUCT($G$3:$L$3,$G27:$L27)+$N$3*$N27)/SUM($E$3,$G$3:$L$3,$N$3) -> 171.31333 | Y27: =+B27/B26-1 -> 0.053874092 | Z27: =+C27/C26-1 -> 0.05875153 | AA27: =+D27/D26-1 -> 0.023255814 | AB27: =+E27/E26-1 -> 0.050420168 | AC27: =+F27/F26-1 -> 0.087834427 | AD27: =+G27/G26-1 -> 0.042446941 | AE27: =+H27/H26-1 -> 0.055012225 | AF27: =+I27/I26-1 -> 0.076490439 | ... AT27: =+W27/W26-1 -> 0.049664304 | AV27: =+B27/B15-1 -> 0.45812395 | AW27: =+C27/C15-1 -> 0.46362098 | AX27: =+D27/D15-1 -> 0.22925226 | AY27: =+E27/E15-1 -> 0.31463628 | AZ27: =+F27/F15-1 -> 0.65260736 | BA27: =+G27/G15-1 -> 0.47656941 | BB27: =+H27/H15-1 -> 0.40097403 | BC27: =+I27/I15-1 -> 0.68783069 | ... BQ27: =+W27/W15-1 -> 0.45043878
A28: =+[1]NAC!A29 -> 43405 | B28: =+[1]NAC!B29 -> 179.6 | C28: =+[1]NAC!C29 -> 178.9 | D28: =+[1]NAC!D29 -> 156.5 | E28: =+[1]NAC!E29 -> 153.4 | F28: =+[1]NAC!F29 -> 220.1 | G28: =+[1]NAC!G29 -> 173 | H28: =+[1]NAC!H29 -> 182.3 | ... N28: =+[1]NAC!N29 -> 177.5 | O28: =+[1]NAC!P29 -> 161.9 | P28: =+[1]NAC!Q29 -> 174.2 | Q28: =+[1]NAC!R29 -> 207.5 | R28: =+SUMPRODUCT($C$3:$N$3,C28:N28) -> 179.78539 | S28: =+($C$3*$C28+$D$3*$D28+$E$3*$E28+$G$3*$G28+$K$3*$K28+$M$3*$M28+$N$3*$N28)/SUM($C$3:$E$3,$G$3,$K$3,$M$3:$N$3) -> 170.67857 | T28: =+($E$3*$E28+$G$3*$G28+$K$3*$K28+$M$3*$M28+$N$3*$N28)/SUM($E$3,$G$3,$K$3,$M$3:$N$3) -> 165.88975 | U28: =+($E$3*$E28+$G$3*$G28+$K$3*$K28+$N$3*$N28)/SUM($E$3,$G$3,$K$3,$N$3) -> 166.05073 | W28: =($E$3*$E28+SUMPRODUCT($G$3:$L$3,$G28:$L28)+$N$3*$N28)/SUM($E$3,$G$3:$L$3,$N$3) -> 176.91676 | Y28: =+B28/B27-1 -> 0.03159104 | Z28: =+C28/C27-1 -> 0.034104046 | AA28: =+D28/D27-1 -> 0.046122995 | AB28: =+E28/E27-1 -> 0.022666667 | AC28: =+F28/F27-1 -> 0.021345708 | AD28: =+G28/G27-1 -> 0.035928144 | AE28: =+H28/H27-1 -> 0.056199305 | AF28: =+I28/I27-1 -> 0.026645768 | ... AT28: =+W28/W27-1 -> 0.032708648 | AV28: =+B28/B16-1 -> 0.48429752 | AW28: =+C28/C16-1 -> 0.4958194 | AX28: =+D28/D16-1 -> 0.27235772 | AY28: =+E28/E16-1 -> 0.3258427 | AZ28: =+F28/F16-1 -> 0.66742424 | BA28: =+G28/G16-1 -> 0.51621385 | BB28: =+H28/H16-1 -> 0.46073718 | BC28: =+I28/I16-1 -> 0.68236301 | ... BQ28: =+W28/W16-1 -> 0.47641869
... A118: =+[1]NAC!A119 -> 46143 | B118: =+[1]NAC!B119 -> 11607.4 | C118: =+[1]NAC!C119 -> 12495 | D118: =+[1]NAC!D119 -> 8033.3 | E118: =+[1]NAC!E119 -> 8350.2 | F118: =+[1]NAC!F119 -> 12790.1 | G118: =+[1]NAC!G119 -> 9312.2 | H118: =+[1]NAC!H119 -> 12832 | ... N118: =+[1]NAC!N119 -> 11171.6 | O118: =+[1]NAC!P119 -> 9420.5 | P118: =+[1]NAC!Q119 -> 11824.7 | Q118: =+[1]NAC!R119 -> 12111.5 | R118: =+SUMPRODUCT($C$3:$N$3,C118:N118) -> 11618.873 | S118: =+($C$3*$C118+$D$3*$D118+$E$3*$E118+$G$3*$G118+$K$3*$K118+$M$3*$M118+$N$3*$N118)/SUM($C$3:$E$3,$G$3,$K$3,$M$3:$N$3) -> 11249.073 | T118: =+($E$3*$E118+$G$3*$G118+$K$3*$K118+$M$3*$M118+$N$3*$N118)/SUM($E$3,$G$3,$K$3,$M$3:$N$3) -> 10627.051 | U118: =+($E$3*$E118+$G$3*$G118+$K$3*$K118+$N$3*$N118)/SUM($E$3,$G$3,$K$3,$N$3) -> 9422.5857 | W118: =($E$3*$E118+SUMPRODUCT($G$3:$L$3,$G118:$L118)+$N$3*$N118)/SUM($E$3,$G$3:$L$3,$N$3) -> 10721.509 | Y118: =+B118/B117-1 -> 0.021499415 | Z118: =+C118/C117-1 -> 0.024608648 | AA118: =+D118/D117-1 -> 0.0079422836 | AB118: =+E118/E117-1 -> 0.0028222465 | AC118: =+F118/F117-1 -> 0.025612035 | AD118: =+G118/G117-1 -> 0.014091562 | AE118: =+H118/H117-1 -> 0.025870615 | AF118: =+I118/I117-1 -> 0.019757518 | ... AT118: =+W118/W117-1 -> 0.020226474 | AV118: =+B118/B106-1 -> 0.33196397 | AW118: =+C118/C106-1 -> 0.33418043 | AX118: =+D118/D106-1 -> 0.24012782 | AY118: =+E118/E106-1 -> 0.12026081 | AZ118: =+F118/F106-1 -> 0.48006156 | BA118: =+G118/G106-1 -> 0.23495789 | BB118: =+H118/H106-1 -> 0.29540269 | BC118: =+I118/I106-1 -> 0.42121946 | ... BQ118: =+W118/W106-1 -> 0.29758896

Sheet GBA
B1: Índices | Y1: Tasas de inflación mensual | AV1: Tasas de inflación interanual | BS1: Incidencia mensual | CH1: Incidencia Feb 21 - Jun 24
R2: =+SUM(C3:N3) -> 1 | S2: =+SUM($C$3:$E$3,$G$3,$K$3,$M$3:$N$3) -> 0.6332 | T2: =+SUM($E$3,$G$3,$K$3,$M$3:$N$3) -> 0.3661 | U2: =+SUM($E$3,$G$3,$K$3,$N$3) -> 0.2577 | W2: =+SUM(E3,G3:L3,N3) -> 0.5199 | AT2: =+SUM(AB3,AD3:AI3,AK3) -> 0.5199 | BL2: =+SUM(AW3:BH3) -> 1 | BQ2: =+SUM(AY3,BA3:BF3,BH3) -> 0.5199
C3: =+[1]GBA!C$3 -> 0.2344 | D3: =+[1]GBA!D$3 -> 0.0327 | E3: =+[1]GBA!E$3 -> 0.0849 | F3: =+[1]GBA!F$3 -> 0.1046 | G3: =+[1]GBA!G$3 -> 0.0627 | H3: =+[1]GBA!H$3 -> 0.088 | I3: =+[1]GBA!I$3 -> 0.1159 | J3: =+[1]GBA!J$3 -> 0.0281 | ... N3: =+[1]GBA!N$3 -> 0.0355 | R3: headline | V3: no food & energy | W3: no food & energy & shelter | Z3: =+C3 -> 0.2344 | AA3: =+D3 -> 0.0327 | AB3: =+E3 -> 0.0849 | AC3: =+F3 -> 0.1046 | AD3: =+G3 -> 0.0627 | AE3: =+H3 -> 0.088 | AF3: =+I3 -> 0.1159 | AG3: =+J3 -> 0.0281 | ... AK3: =+N3 -> 0.0355 | AL3: 0.108 | AM3: 0.699 | AN3: 0.194 | AO3: headline | AS3: no food & energy | AT3: no food & energy & shelter | AW3: =+Z3 -> 0.2344 | AX3: =+AA3 -> 0.0327 | AY3: =+AB3 -> 0.0849 | AZ3: =+AC3 -> 0.1046 | BA3: =+AD3 -> 0.0627 | BB3: =+AE3 -> 0.088 | BC3: =+AF3 -> 0.1159 | BD3: =+AG3 -> 0.0281 | ... BH3: =+AK3 -> 0.0355 | BL3: headline | BP3: no food & energy | BQ3: no food & energy & shelter | BT3: =+AW3 -> 0.2344 | BU3: =+AX3 -> 0.0327 | BV3: =+AY3 -> 0.0849 | BW3: =+AZ3 -> 0.1046 | BX3: =+BA3 -> 0.0627 | BY3: =+BB3 -> 0.088 | BZ3: =+BC3 -> 0.1159 | CA3: =+BD3 -> 0.0281 | ... CE3: =+BH3 -> 0.0355 | CH3: 1 | CI3: =+BT3 -> 0.2344 | CJ3: =+BU3 -> 0.0327 | CK3: =+BV3 -> 0.0849 | CL3: =+BW3 -> 0.1046 | CM3: =+BX3 -> 0.0627 | CN3: =+BY3 -> 0.088 | CO3: =+BZ3 -> 0.1159 | CP3: =+CA3 -> 0.0281 | ... CT3: =+CE3 -> 0.0355
A4: Fecha | B4: Nivel general | C4: Alimentos y bebidas no alcohólicas | D4: Bebidas alcohólicas y tabaco | E4: Prendas de vestir y calzado | F4: Vivienda, agua, electricidad, gas y otros combustibles | G4: Equipamiento y mantenimiento del hogar | H4: Salud | I4: Transporte | J4: Comunicación | K4: Recreación y cultura | L4: Educación | M4: Restaurantes y hoteles | N4: Bienes y servicios varios | O4: Estacional | P4: Núcleo | Q4: Regulados | R4: Nivel General | S4: Subyacente | T4: Subyacente-AyB | U4: Subyacente-Food | V4: Core | W4: Supercore | Y4: Nivel general | Z4: Alimentos y bebidas no alcohólicas | AA4: Bebidas alcohólicas y tabaco | AB4: Prendas de vestir y calzado | AC4: Vivienda, agua, electricidad, gas y otros combustibles | AD4: Equipamiento y mantenimiento del hogar | AE4: Salud | AF4: Transporte | AG4: Comunicación | AH4: Recreación y cultura | AI4: Educación | AJ4: Restaurantes y hoteles | AK4: Bienes y servicios varios | AL4: Estacional | AM4: Núcleo | AN4: Regulados | AO4: =+R4 -> Nivel General | AP4: =+S4 -> Subyacente | AQ4: =+T4 -> Subyacente-AyB | AR4: =+U4 -> Subyacente-Food | AS4: Core | AT4: Supercore | AV4: Nivel general | AW4: Alimentos y bebidas no alcohólicas | AX4: Bebidas alcohólicas y tabaco | AY4: Prendas de vestir y calzado | AZ4: Vivienda, agua, electricidad, gas y otros combustibles | BA4: Equipamiento y mantenimiento del hogar | BB4: Salud | BC4: Transporte | BD4: Comunicación | BE4: Recreación y cultura | BF4: Educación | BG4: Restaurantes y hoteles | BH4: Bienes y servicios varios | BI4: Estacional | BJ4: Núcleo | BK4: Regulados | BL4: =+AO4 -> Nivel General | BM4: =+AP4 -> Subyacente | BN4: =+AQ4 -> Subyacente-AyB | BO4: =+AR4 -> Subyacente-Food | BP4: Core | BQ4: Supercore | BS4: Fecha | BT4: Alimentos y bebidas no alcohólicas | BU4: Bebidas alcohólicas y tabaco | BV4: Prendas de vestir y calzado | BW4: Vivienda, agua, electricidad, gas y otros combustibles | BX4: Equipamiento y mantenimiento del hogar | BY4: Salud | BZ4: Transporte | CA4: Comunicación | CB4: Recreación y cultura | CC4: Educación | CD4: Restaurantes y hoteles | CE4: Bienes y servicios varios | CF4: Nivel general | CH4: Fecha | CI4: Alimentos y bebidas no alcohólicas | CJ4: Bebidas alcohólicas y tabaco | CK4: Prendas de vestir y calzado | CL4: Vivienda, agua, electricidad, gas y otros combustibles | CM4: Equipamiento y mantenimiento del hogar | CN4: Salud | CO4: Transporte | CP4: Comunicación | CQ4: Recreación y cultura | CR4: Educación | CS4: Restaurantes y hoteles | CT4: Bienes y servicios varios | CU4: Nivel general
A5: =+[1]NAC!A6 -> 42705 | B5: =+[1]GBA!B6 -> 100 | C5: =+[1]GBA!C6 -> 100 | D5: =+[1]GBA!D6 -> 100 | E5: =+[1]GBA!E6 -> 100 | F5: =+[1]GBA!F6 -> 100 | G5: =+[1]GBA!G6 -> 100 | H5: =+[1]GBA!H6 -> 100 | I5: =+[1]GBA!I6 -> 100 | ... N5: =+[1]GBA!N6 -> 100 | O5: =+[1]GBA!R6 -> 100 | P5: =+[1]GBA!S6 -> 100 | Q5: =+[1]GBA!T6 -> 100 | R5: =+SUMPRODUCT($C$3:$N$3,C5:N5) -> 100 | S5: =+($C$3*$C5+$D$3*$D5+$E$3*$E5+$G$3*$G5+$K$3*$K5+$M$3*$M5+$N$3*$N5)/SUM($C$3:$E$3,$G$3,$K$3,$M$3:$N$3) -> 100 | T5: =+($E$3*$E5+$G$3*$G5+$K$3*$K5+$M$3*$M5+$N$3*$N5)/SUM($E$3,$G$3,$K$3,$M$3:$N$3) -> 100 | U5: =+($E$3*$E5+$G$3*$G5+$K$3*$K5+$N$3*$N5)/SUM($E$3,$G$3,$K$3,$N$3) -> 100 | W5: =($E$3*$E5+SUMPRODUCT($G$3:$L$3,$G5:$L5)+$N$3*$N5)/SUM($E$3,$G$3:$L$3,$N$3) -> 100 | BS5: =+A5 -> 42705
A6: =+[1]NAC!A7 -> 42736 | B6: =+[1]GBA!B7 -> 101.3 | C6: =+[1]GBA!C7 -> 101.3 | D6: =+[1]GBA!D7 -> 100.5 | E6: =+[1]GBA!E7 -> 97.9 | F6: =+[1]GBA!F7 -> 100 | G6: =+[1]GBA!G7 -> 100.9 | H6: =+[1]GBA!H7 -> 101.4 | I6: =+[1]GBA!I7 -> 101.8 | ... N6: =+[1]GBA!N7 -> 102.1 | O6: =+[1]GBA!R7 -> 101.6 | P6: =+[1]GBA!S7 -> 101.3 | Q6: =+[1]GBA!T7 -> 101.1 | R6: =+SUMPRODUCT($C$3:$N$3,C6:N6) -> 101.3239 | S6: =+($C$3*$C6+$D$3*$D6+$E$3*$E6+$G$3*$G6+$K$3*$K6+$M$3*$M6+$N$3*$N6)/SUM($C$3:$E$3,$G$3,$K$3,$M$3:$N$3) -> 101.37429 | T6: =+($E$3*$E6+$G$3*$G6+$K$3*$K6+$M$3*$M6+$N$3*$N6)/SUM($E$3,$G$3,$K$3,$M$3:$N$3) -> 101.49995 | U6: =+($E$3*$E6+$G$3*$G6+$K$3*$K6+$N$3*$N6)/SUM($E$3,$G$3,$K$3,$N$3) -> 100.74276 | W6: =($E$3*$E6+SUMPRODUCT($G$3:$L$3,$G6:$L6)+$N$3*$N6)/SUM($E$3,$G$3:$L$3,$N$3) -> 101.24083 | Y6: =+B6/B5-1 -> 0.013 | Z6: =+C6/C5-1 -> 0.013 | AA6: =+D6/D5-1 -> 0.005 | AB6: =+E6/E5-1 -> -0.021 | AC6: =+F6/F5-1 -> 0 | AD6: =+G6/G5-1 -> 0.009 | AE6: =+H6/H5-1 -> 0.014 | AF6: =+I6/I5-1 -> 0.018 | ... AT6: =+W6/W5-1 -> 0.012408348 | BS6: =+A6 -> 42736 | BT6: =(C6-C5)/$B5*C$3 -> 0.0030472 | BU6: =(D6-D5)/$B5*D$3 -> 0.0001635 | BV6: =(E6-E5)/$B5*E$3 -> -0.0017829 | BW6: =(F6-F5)/$B5*F$3 -> 0 | BX6: =(G6-G5)/$B5*G$3 -> 0.0005643 | BY6: =(H6-H5)/$B5*H$3 -> 0.001232 | BZ6: =(I6-I5)/$B5*I$3 -> 0.0020862 | CA6: =(J6-J5)/$B5*J$3 -> 0.0010678 | ... CE6: =(N6-N5)/$B5*N$3 -> 0.0007455 | CF6: =+SUM(BT6:CE6) -> 0.013239 | CH6: =+CH$3*(B$95-B$55)/$B$55 -> 14.606196 | CI6: =+CI$3*(C$95-C$55)/$B$55 -> 3.9148576 | CJ6: =+CJ$3*(D$95-D$55)/$B$55 -> 0.36350082 | CK6: =+CK$3*(E$95-E$55)/$B$55 -> 1.1726089 | CL6: =+CL$3*(F$95-F$55)/$B$55 -> 1.2681357 | CM6: =+CM$3*(G$95-G$55)/$B$55 -> 0.87024803 | CN6: =+CN$3*(H$95-H$55)/$B$55 -> 1.3690706 | CO6: =+CO$3*(I$95-I$55)/$B$55 -> 1.6954719 | ... CT6: =+CT$3*(N$95-N$55)/$B$55 -> 0.50825266
A7: =+[1]NAC!A8 -> 42767 | B7: =+[1]GBA!B8 -> 103.8 | C7: =+[1]GBA!C8 -> 103.2 | D7: =+[1]GBA!D8 -> 105.5 | E7: =+[1]GBA!E8 -> 97.4 | F7: =+[1]GBA!F8 -> 108.4 | G7: =+[1]GBA!G8 -> 101.2 | H7: =+[1]GBA!H8 -> 104.7 | I7: =+[1]GBA!I8 -> 103.5 | ... N7: =+[1]GBA!N8 -> 104.1 | O7: =+[1]GBA!R8 -> 102.1 | P7: =+[1]GBA!S8 -> 103.2 | Q7: =+[1]GBA!T8 -> 106.3 | R7: =+SUMPRODUCT($C$3:$N$3,C7:N7) -> 103.79967 | S7: =+($C$3*$C7+$D$3*$D7+$E$3*$E7+$G$3*$G7+$K$3*$K7+$M$3*$M7+$N$3*$N7)/SUM($C$3:$E$3,$G$3,$K$3,$M$3:$N$3) -> 102.73057 | T7: =+($E$3*$E7+$G$3*$G7+$K$3*$K7+$M$3*$M7+$N$3*$N7)/SUM($E$3,$G$3,$K$3,$M$3:$N$3) -> 102.18266 | U7: =+($E$3*$E7+$G$3*$G7+$K$3*$K7+$N$3*$N7)/SUM($E$3,$G$3,$K$3,$N$3) -> 100.95549 | W7: =($E$3*$E7+SUMPRODUCT($G$3:$L$3,$G7:$L7)+$N$3*$N7)/SUM($E$3,$G$3:$L$3,$N$3) -> 102.76642 | Y7: =+B7/B6-1 -> 0.024679171 | Z7: =+C7/C6-1 -> 0.01875617 | AA7: =+D7/D6-1 -> 0.049751244 | AB7: =+E7/E6-1 -> -0.0051072523 | AC7: =+F7/F6-1 -> 0.084 | AD7: =+G7/G6-1 -> 0.0029732408 | AE7: =+H7/H6-1 -> 0.032544379 | AF7: =+I7/I6-1 -> 0.016699411 | ... AT7: =+W7/W6-1 -> 0.015068839 | BS7: =+A7 -> 42767 | BT7: =(C7-C6)/$B6*C$3 -> 0.0043964462 | BU7: =(D7-D6)/$B6*D$3 -> 0.0016140178 | BV7: =(E7-E6)/$B6*E$3 -> -0.00041905232 | BW7: =(F7-F6)/$B6*F$3 -> 0.0086736426 | BX7: =(G7-G6)/$B6*G$3 -> 0.00018568608 | BY7: =(H7-H6)/$B6*H$3 -> 0.0028667325 | BZ7: =(I7-I6)/$B6*I$3 -> 0.0019450148 | CA7: =(J7-J6)/$B6*J$3 -> 0.0011650543 | ... CE7: =(N7-N6)/$B6*N$3 -> 0.00070088845 | CF7: =+SUM(BT7:CE7) -> 0.02443998
A8: =+[1]NAC!A9 -> 42795 | B8: =+[1]GBA!B9 -> 106.3 | C8: =+[1]GBA!C9 -> 106.8 | D8: =+[1]GBA!D9 -> 107.1 | E8: =+[1]GBA!E9 -> 102.1 | F8: =+[1]GBA!F9 -> 110.8 | G8: =+[1]GBA!G9 -> 102.1 | H8: =+[1]GBA!H9 -> 106.7 | I8: =+[1]GBA!I9 -> 104.6 | ... N8: =+[1]GBA!N9 -> 105.6 | O8: =+[1]GBA!R9 -> 105.9 | P8: =+[1]GBA!S9 -> 105.1 | Q8: =+[1]GBA!T9 -> 109.9 | R8: =+SUMPRODUCT($C$3:$N$3,C8:N8) -> 106.27748 | S8: =+($C$3*$C8+$D$3*$D8+$E$3*$E8+$G$3*$G8+$K$3*$K8+$M$3*$M8+$N$3*$N8)/SUM($C$3:$E$3,$G$3,$K$3,$M$3:$N$3) -> 105.31429 | T8: =+($E$3*$E8+$G$3*$G8+$K$3*$K8+$M$3*$M8+$N$3*$N8)/SUM($E$3,$G$3,$K$3,$M$3:$N$3) -> 104.20355 | U8: =+($E$3*$E8+$G$3*$G8+$K$3*$K8+$N$3*$N8)/SUM($E$3,$G$3,$K$3,$N$3) -> 103.36376 | W8: =($E$3*$E8+SUMPRODUCT($G$3:$L$3,$G8:$L8)+$N$3*$N8)/SUM($E$3,$G$3:$L$3,$N$3) -> 105.09642 | Y8: =+B8/B7-1 -> 0.024084778 | Z8: =+C8/C7-1 -> 0.034883721 | AA8: =+D8/D7-1 -> 0.015165877 | AB8: =+E8/E7-1 -> 0.04825462 | AC8: =+F8/F7-1 -> 0.022140221 | AD8: =+G8/G7-1 -> 0.0088932806 | AE8: =+H8/H7-1 -> 0.019102197 | AF8: =+I8/I7-1 -> 0.010628019 | ... AT8: =+W8/W7-1 -> 0.022672833 | BS8: =+A8 -> 42795 | BT8: =(C8-C7)/$B7*C$3 -> 0.0081294798 | BU8: =(D8-D7)/$B7*D$3 -> 0.00050404624 | BV8: =(E8-E7)/$B7*E$3 -> 0.0038442197 | BW8: =(F8-F7)/$B7*F$3 -> 0.0024184971 | BX8: =(G8-G7)/$B7*G$3 -> 0.00054364162 | BY8: =(H8-H7)/$B7*H$3 -> 0.0016955684 | BZ8: =(I8-I7)/$B7*I$3 -> 0.0012282274 | CA8: =(J8-J7)/$B7*J$3 -> 0.00073092486 | ... CE8: =(N8-N7)/$B7*N$3 -> 0.00051300578 | CF8: =+SUM(BT8:CE8) -> 0.023871002
A9: =+[1]NAC!A10 -> 42826 | B9: =+[1]GBA!B10 -> 109.1 | C9: =+[1]GBA!C10 -> 109.2 | D9: =+[1]GBA!D10 -> 109.6 | E9: =+[1]GBA!E10 -> 107.2 | F9: =+[1]GBA!F10 -> 115.9 | G9: =+[1]GBA!G10 -> 103.2 | H9: =+[1]GBA!H10 -> 108.2 | I9: =+[1]GBA!I10 -> 105.1 | ... N9: =+[1]GBA!N10 -> 107.6 | O9: =+[1]GBA!R10 -> 108.5 | P9: =+[1]GBA!S10 -> 107.5 | Q9: =+[1]GBA!T10 -> 113.9 | R9: =+SUMPRODUCT($C$3:$N$3,C9:N9) -> 109.05799 | S9: =+($C$3*$C9+$D$3*$D9+$E$3*$E9+$G$3*$G9+$K$3*$K9+$M$3*$M9+$N$3*$N9)/SUM($C$3:$E$3,$G$3,$K$3,$M$3:$N$3) -> 108.02034 | T9: =+($E$3*$E9+$G$3*$G9+$K$3*$K9+$M$3*$M9+$N$3*$N9)/SUM($E$3,$G$3,$K$3,$M$3:$N$3) -> 107.12396 | U9: =+($E$3*$E9+$G$3*$G9+$K$3*$K9+$N$3*$N9)/SUM($E$3,$G$3,$K$3,$N$3) -> 106.62926 | W9: =($E$3*$E9+SUMPRODUCT($G$3:$L$3,$G9:$L9)+$N$3*$N9)/SUM($E$3,$G$3:$L$3,$N$3) -> 107.74135 | Y9: =+B9/B8-1 -> 0.026340546 | Z9: =+C9/C8-1 -> 0.02247191 | AA9: =+D9/D8-1 -> 0.02334267 | AB9: =+E9/E8-1 -> 0.049951028 | AC9: =+F9/F8-1 -> 0.046028881 | AD9: =+G9/G8-1 -> 0.010773751 | AE9: =+H9/H8-1 -> 0.014058107 | AF9: =+I9/I8-1 -> 0.0047801147 | ... AT9: =+W9/W8-1 -> 0.025166715 | BS9: =+A9 -> 42826 | BT9: =(C9-C8)/$B8*C$3 -> 0.0052921919 | BU9: =(D9-D8)/$B8*D$3 -> 0.00076904986 | BV9: =(E9-E8)/$B8*E$3 -> 0.0040732832 | BW9: =(F9-F8)/$B8*F$3 -> 0.0050184384 | BX9: =(G9-G8)/$B8*G$3 -> 0.00064882408 | BY9: =(H9-H8)/$B8*H$3 -> 0.0012417686 | BZ9: =(I9-I8)/$B8*I$3 -> 0.00054515522 | CA9: =(J9-J8)/$B8*J$3 -> 0.0019825964 | ... CE9: =(N9-N8)/$B8*N$3 -> 0.00066792098 | CF9: =+SUM(BT9:CE9) -> 0.026157197
A10: =+[1]NAC!A11 -> 42856 | B10: =+[1]GBA!B11 -> 110.5 | C10: =+[1]GBA!C11 -> 110.4 | D10: =+[1]GBA!D11 -> 111.6 | E10: =+[1]GBA!E11 -> 107.9 | F10: =+[1]GBA!F11 -> 118 | G10: =+[1]GBA!G11 -> 106.3 | H10: =+[1]GBA!H11 -> 109.8 | I10: =+[1]GBA!I11 -> 106.2 | ... N10: =+[1]GBA!N11 -> 109.1 | O10: =+[1]GBA!R11 -> 108 | P10: =+[1]GBA!S11 -> 109.2 | Q10: =+[1]GBA!T11 -> 115.2 | R10: =+SUMPRODUCT($C$3:$N$3,C10:N10) -> 110.46333 | S10: =+($C$3*$C10+$D$3*$D10+$E$3*$E10+$G$3*$G10+$K$3*$K10+$M$3*$M10+$N$3*$N10)/SUM($C$3:$E$3,$G$3,$K$3,$M$3:$N$3) -> 109.36423 | T10: =+($E$3*$E10+$G$3*$G10+$K$3*$K10+$M$3*$M10+$N$3*$N10)/SUM($E$3,$G$3,$K$3,$M$3:$N$3) -> 108.50137 | U10: =+($E$3*$E10+$G$3*$G10+$K$3*$K10+$N$3*$N10)/SUM($E$3,$G$3,$K$3,$N$3) -> 108.0813 | W10: =($E$3*$E10+SUMPRODUCT($G$3:$L$3,$G10:$L10)+$N$3*$N10)/SUM($E$3,$G$3:$L$3,$N$3) -> 109.10492 | Y10: =+B10/B9-1 -> 0.012832264 | Z10: =+C10/C9-1 -> 0.010989011 | AA10: =+D10/D9-1 -> 0.018248175 | AB10: =+E10/E9-1 -> 0.0065298507 | AC10: =+F10/F9-1 -> 0.018119068 | AD10: =+G10/G9-1 -> 0.03003876 | AE10: =+H10/H9-1 -> 0.014787431 | AF10: =+I10/I9-1 -> 0.010466223 | ... AT10: =+W10/W9-1 -> 0.012655957 | BS10: =+A10 -> 42856 | BT10: =(C10-C9)/$B9*C$3 -> 0.0025781852 | BU10: =(D10-D9)/$B9*D$3 -> 0.00059945005 | BV10: =(E10-E9)/$B9*E$3 -> 0.00054472961 | BW10: =(F10-F9)/$B9*F$3 -> 0.0020133822 | BX10: =(G10-G9)/$B9*G$3 -> 0.0017815765 | BY10: =(H10-H9)/$B9*H$3 -> 0.0012905591 | BZ10: =(I10-I9)/$B9*I$3 -> 0.001168561 | CA10: =(J10-J9)/$B9*J$3 -> 0 | ... CE10: =(N10-N9)/$B9*N$3 -> 0.00048808433 | CF10: =+SUM(BT10:CE10) -> 0.01288121
A11: =+[1]NAC!A12 -> 42887 | B11: =+[1]GBA!B12 -> 112 | C11: =+[1]GBA!C12 -> 111.8 | D11: =+[1]GBA!D12 -> 112.2 | E11: =+[1]GBA!E12 -> 108.6 | F11: =+[1]GBA!F12 -> 120.9 | G11: =+[1]GBA!G12 -> 107.7 | H11: =+[1]GBA!H12 -> 111.2 | I11: =+[1]GBA!I12 -> 106.5 | ... N11: =+[1]GBA!N12 -> 110.2 | O11: =+[1]GBA!R12 -> 109.6 | P11: =+[1]GBA!S12 -> 110.9 | Q11: =+[1]GBA!T12 -> 116.4 | R11: =+SUMPRODUCT($C$3:$N$3,C11:N11) -> 111.98898 | S11: =+($C$3*$C11+$D$3*$D11+$E$3*$E11+$G$3*$G11+$K$3*$K11+$M$3*$M11+$N$3*$N11)/SUM($C$3:$E$3,$G$3,$K$3,$M$3:$N$3) -> 110.90456 | T11: =+($E$3*$E11+$G$3*$G11+$K$3*$K11+$M$3*$M11+$N$3*$N11)/SUM($E$3,$G$3,$K$3,$M$3:$N$3) -> 110.21554 | U11: =+($E$3*$E11+$G$3*$G11+$K$3*$K11+$N$3*$N11)/SUM($E$3,$G$3,$K$3,$N$3) -> 109.75937 | W11: =($E$3*$E11+SUMPRODUCT($G$3:$L$3,$G11:$L11)+$N$3*$N11)/SUM($E$3,$G$3:$L$3,$N$3) -> 110.41173 | Y11: =+B11/B10-1 -> 0.013574661 | Z11: =+C11/C10-1 -> 0.012681159 | AA11: =+D11/D10-1 -> 0.0053763441 | AB11: =+E11/E10-1 -> 0.0064874884 | AC11: =+F11/F10-1 -> 0.024576271 | AD11: =+G11/G10-1 -> 0.013170273 | AE11: =+H11/H10-1 -> 0.012750455 | AF11: =+I11/I10-1 -> 0.0028248588 | ... AT11: =+W11/W10-1 -> 0.011977544 | BS11: =+A11 -> 42887 | BT11: =(C11-C10)/$B10*C$3 -> 0.0029697738 | BU11: =(D11-D10)/$B10*D$3 -> 0.00017755656 | BV11: =(E11-E10)/$B10*E$3 -> 0.00053782805 | BW11: =(F11-F10)/$B10*F$3 -> 0.0027451584 | BX11: =(G11-G10)/$B10*G$3 -> 0.00079438914 | BY11: =(H11-H10)/$B10*H$3 -> 0.0011149321 | BZ11: =(I11-I10)/$B10*I$3 -> 0.00031466063 | CA11: =(J11-J10)/$B10*J$3 -> 0.00055945701 | ... CE11: =(N11-N10)/$B10*N$3 -> 0.00035339367 | CF11: =+SUM(BT11:CE11) -> 0.013806787
A12: =+[1]NAC!A13 -> 42917 | B12: =+[1]GBA!B13 -> 113.9 | C12: =+[1]GBA!C13 -> 113.2 | D12: =+[1]GBA!D13 -> 115.9 | E12: =+[1]GBA!E13 -> 106.6 | F12: =+[1]GBA!F13 -> 123.9 | G12: =+[1]GBA!G13 -> 110.4 | H12: =+[1]GBA!H13 -> 115 | I12: =+[1]GBA!I13 -> 108.1 | ... N12: =+[1]GBA!N13 -> 111.8 | O12: =+[1]GBA!R13 -> 110.1 | P12: =+[1]GBA!S13 -> 112.8 | Q12: =+[1]GBA!T13 -> 118.8 | R12: =+SUMPRODUCT($C$3:$N$3,C12:N12) -> 113.93651 | S12: =+($C$3*$C12+$D$3*$D12+$E$3*$E12+$G$3*$G12+$K$3*$K12+$M$3*$M12+$N$3*$N12)/SUM($C$3:$E$3,$G$3,$K$3,$M$3:$N$3) -> 112.59449 | T12: =+($E$3*$E12+$G$3*$G12+$K$3*$K12+$M$3*$M12+$N$3*$N12)/SUM($E$3,$G$3,$K$3,$M$3:$N$3) -> 111.91155 | U12: =+($E$3*$E12+$G$3*$G12+$K$3*$K12+$N$3*$N12)/SUM($E$3,$G$3,$K$3,$N$3) -> 110.991 | W12: =($E$3*$E12+SUMPRODUCT($G$3:$L$3,$G12:$L12)+$N$3*$N12)/SUM($E$3,$G$3:$L$3,$N$3) -> 112.10641 | Y12: =+B12/B11-1 -> 0.016964286 | Z12: =+C12/C11-1 -> 0.012522361 | AA12: =+D12/D11-1 -> 0.032976827 | AB12: =+E12/E11-1 -> -0.018416206 | AC12: =+F12/F11-1 -> 0.024813896 | AD12: =+G12/G11-1 -> 0.025069638 | AE12: =+H12/H11-1 -> 0.034172662 | AF12: =+I12/I11-1 -> 0.015023474 | ... AT12: =+W12/W11-1 -> 0.015348659 | BS12: =+A12 -> 42917 | BT12: =(C12-C11)/$B11*C$3 -> 0.00293 | BU12: =(D12-D11)/$B11*D$3 -> 0.0010802679 | BV12: =(E12-E11)/$B11*E$3 -> -0.0015160714 | BW12: =(F12-F11)/$B11*F$3 -> 0.0028017857 | BX12: =(G12-G11)/$B11*G$3 -> 0.0015115179 | BY12: =(H12-H11)/$B11*H$3 -> 0.0029857143 | BZ12: =(I12-I11)/$B11*I$3 -> 0.0016557143 | CA12: =(J12-J11)/$B11*J$3 -> 0.000175625 | ... CE12: =(N12-N11)/$B11*N$3 -> 0.00050714286 | CF12: =+SUM(BT12:CE12) -> 0.017388661
A13: =+[1]NAC!A14 -> 42948 | B13: =+[1]GBA!B14 -> 115.6 | C13: =+[1]GBA!C14 -> 115.7 | D13: =+[1]GBA!D14 -> 117.4 | E13: =+[1]GBA!E14 -> 105.6 | F13: =+[1]GBA!F14 -> 127.2 | G13: =+[1]GBA!G14 -> 111.5 | H13: =+[1]GBA!H14 -> 118.3 | I13: =+[1]GBA!I14 -> 109.3 | ... N13: =+[1]GBA!N14 -> 113.5 | O13: =+[1]GBA!R14 -> 111.5 | P13: =+[1]GBA!S14 -> 114.5 | Q13: =+[1]GBA!T14 -> 120.6 | R13: =+SUMPRODUCT($C$3:$N$3,C13:N13) -> 115.61803 | S13: =+($C$3*$C13+$D$3*$D13+$E$3*$E13+$G$3*$G13+$K$3*$K13+$M$3*$M13+$N$3*$N13)/SUM($C$3:$E$3,$G$3,$K$3,$M$3:$N$3) -> 113.83876 | T13: =+($E$3*$E13+$G$3*$G13+$K$3*$K13+$M$3*$M13+$N$3*$N13)/SUM($E$3,$G$3,$K$3,$M$3:$N$3) -> 112.32898 | U13: =+($E$3*$E13+$G$3*$G13+$K$3*$K13+$N$3*$N13)/SUM($E$3,$G$3,$K$3,$N$3) -> 111.16337 | W13: =($E$3*$E13+SUMPRODUCT($G$3:$L$3,$G13:$L13)+$N$3*$N13)/SUM($E$3,$G$3:$L$3,$N$3) -> 113.2468 | Y13: =+B13/B12-1 -> 0.014925373 | Z13: =+C13/C12-1 -> 0.022084806 | AA13: =+D13/D12-1 -> 0.012942192 | AB13: =+E13/E12-1 -> -0.009380863 | AC13: =+F13/F12-1 -> 0.026634383 | AD13: =+G13/G12-1 -> 0.0099637681 | AE13: =+H13/H12-1 -> 0.028695652 | AF13: =+I13/I12-1 -> 0.011100833 | ... AT13: =+W13/W12-1 -> 0.010172411 | BS13: =+A13 -> 42948 | BT13: =(C13-C12)/$B12*C$3 -> 0.0051448639 | BU13: =(D13-D12)/$B12*D$3 -> 0.00043064091 | BV13: =(E13-E12)/$B12*E$3 -> -0.00074539069 | BW13: =(F13-F12)/$B12*F$3 -> 0.0030305531 | BX13: =(G13-G12)/$B12*G$3 -> 0.00060553117 | BY13: =(H13-H12)/$B12*H$3 -> 0.0025496049 | BZ13: =(I13-I12)/$B12*I$3 -> 0.0012210711 | CA13: =(J13-J12)/$B12*J$3 -> 0.00056742757 | ... CE13: =(N13-N12)/$B12*N$3 -> 0.00052985075 | CF13: =+SUM(BT13:CE13) -> 0.014763126
A14: =+[1]NAC!A15 -> 42979 | B14: =+[1]GBA!B15 -> 118 | C14: =+[1]GBA!C15 -> 117.9 | D14: =+[1]GBA!D15 -> 118.3 | E14: =+[1]GBA!E15 -> 111.8 | F14: =+[1]GBA!F15 -> 128.2 | G14: =+[1]GBA!G15 -> 112.6 | H14: =+[1]GBA!H15 -> 121.2 | I14: =+[1]GBA!I15 -> 110.3 | ... N14: =+[1]GBA!N15 -> 115.6 | O14: =+[1]GBA!R15 -> 117.2 | P14: =+[1]GBA!S15 -> 116.5 | Q14: =+[1]GBA!T15 -> 122.5 | R14: =+SUMPRODUCT($C$3:$N$3,C14:N14) -> 117.97261 | S14: =+($C$3*$C14+$D$3*$D14+$E$3*$E14+$G$3*$G14+$K$3*$K14+$M$3*$M14+$N$3*$N14)/SUM($C$3:$E$3,$G$3,$K$3,$M$3:$N$3) -> 116.45674 | T14: =+($E$3*$E14+$G$3*$G14+$K$3*$K14+$M$3*$M14+$N$3*$N14)/SUM($E$3,$G$3,$K$3,$M$3:$N$3) -> 115.36804 | U14: =+($E$3*$E14+$G$3*$G14+$K$3*$K14+$N$3*$N14)/SUM($E$3,$G$3,$K$3,$N$3) -> 114.89189 | W14: =($E$3*$E14+SUMPRODUCT($G$3:$L$3,$G14:$L14)+$N$3*$N14)/SUM($E$3,$G$3:$L$3,$N$3) -> 116.23412 | Y14: =+B14/B13-1 -> 0.020761246 | Z14: =+C14/C13-1 -> 0.019014693 | AA14: =+D14/D13-1 -> 0.0076660988 | AB14: =+E14/E13-1 -> 0.058712121 | AC14: =+F14/F13-1 -> 0.0078616352 | AD14: =+G14/G13-1 -> 0.0098654709 | AE14: =+H14/H13-1 -> 0.024513948 | AF14: =+I14/I13-1 -> 0.0091491308 | ... AT14: =+W14/W13-1 -> 0.026378887 | BS14: =+A14 -> 42979 | BT14: =(C14-C13)/$B13*C$3 -> 0.0044608997 | BU14: =(D14-D13)/$B13*D$3 -> 0.00025458478 | BV14: =(E14-E13)/$B13*E$3 -> 0.0045534602 | BW14: =(F14-F13)/$B13*F$3 -> 0.00090484429 | BX14: =(G14-G13)/$B13*G$3 -> 0.0005966263 | BY14: =(H14-H13)/$B13*H$3 -> 0.0022076125 | BZ14: =(I14-I13)/$B13*I$3 -> 0.0010025952 | CA14: =(J14-J13)/$B13*J$3 -> 0.00026738754 | ... CE14: =(N14-N13)/$B13*N$3 -> 0.00064489619 | CF14: =+SUM(BT14:CE14) -> 0.020368339
A15: =+[1]NAC!A16 -> 43009 | B15: =+[1]GBA!B16 -> 119.5 | C15: =+[1]GBA!C16 -> 119.7 | D15: =+[1]GBA!D16 -> 122.1 | E15: =+[1]GBA!E16 -> 113.6 | F15: =+[1]GBA!F16 -> 128.9 | G15: =+[1]GBA!G16 -> 113.4 | H15: =+[1]GBA!H16 -> 122.1 | I15: =+[1]GBA!I16 -> 111.2 | ... N15: =+[1]GBA!N16 -> 117.3 | O15: =+[1]GBA!R16 -> 119.8 | P15: =+[1]GBA!S16 -> 117.9 | Q15: =+[1]GBA!T16 -> 124.1 | R15: =+SUMPRODUCT($C$3:$N$3,C15:N15) -> 119.49921 | S15: =+($C$3*$C15+$D$3*$D15+$E$3*$E15+$G$3*$G15+$K$3*$K15+$M$3*$M15+$N$3*$N15)/SUM($C$3:$E$3,$G$3,$K$3,$M$3:$N$3) -> 118.14826 | T15: =+($E$3*$E15+$G$3*$G15+$K$3*$K15+$M$3*$M15+$N$3*$N15)/SUM($E$3,$G$3,$K$3,$M$3:$N$3) -> 116.80178 | U15: =+($E$3*$E15+$G$3*$G15+$K$3*$K15+$N$3*$N15)/SUM($E$3,$G$3,$K$3,$N$3) -> 116.08743 | W15: =($E$3*$E15+SUMPRODUCT($G$3:$L$3,$G15:$L15)+$N$3*$N15)/SUM($E$3,$G$3:$L$3,$N$3) -> 117.56207 | Y15: =+B15/B14-1 -> 0.012711864 | Z15: =+C15/C14-1 -> 0.015267176 | AA15: =+D15/D14-1 -> 0.032121724 | AB15: =+E15/E14-1 -> 0.016100179 | AC15: =+F15/F14-1 -> 0.0054602184 | AD15: =+G15/G14-1 -> 0.0071047957 | AE15: =+H15/H14-1 -> 0.0074257426 | AF15: =+I15/I14-1 -> 0.0081595648 | ... AT15: =+W15/W14-1 -> 0.011424766 | BS15: =+A15 -> 43009 | BT15: =(C15-C14)/$B14*C$3 -> 0.0035755932 | BU15: =(D15-D14)/$B14*D$3 -> 0.0010530508 | BV15: =(E15-E14)/$B14*E$3 -> 0.0012950847 | BW15: =(F15-F14)/$B14*F$3 -> 0.00062050847 | BX15: =(G15-G14)/$B14*G$3 -> 0.00042508475 | BY15: =(H15-H14)/$B14*H$3 -> 0.00067118644 | BZ15: =(I15-I14)/$B14*I$3 -> 0.00088398305 | CA15: =(J15-J14)/$B14*J$3 -> 0.0014288136 | ... CE15: =(N15-N14)/$B14*N$3 -> 0.00051144068 | CF15: =+SUM(BT15:CE15) -> 0.012937288
A16: =+[1]NAC!A17 -> 43040 | B16: =+[1]GBA!B17 -> 120.9 | C16: =+[1]GBA!C17 -> 120.9 | D16: =+[1]GBA!D17 -> 123.4 | E16: =+[1]GBA!E17 -> 114.9 | F16: =+[1]GBA!F17 -> 130.2 | G16: =+[1]GBA!G17 -> 114.2 | H16: =+[1]GBA!H17 -> 123.6 | I16: =+[1]GBA!I17 -> 114.1 | ... N16: =+[1]GBA!N17 -> 118.7 | O16: =+[1]GBA!R17 -> 121 | P16: =+[1]GBA!S17 -> 119.4 | Q16: =+[1]GBA!T17 -> 125.2 | R16: =+SUMPRODUCT($C$3:$N$3,C16:N16) -> 120.89635 | S16: =+($C$3*$C16+$D$3*$D16+$E$3*$E16+$G$3*$G16+$K$3*$K16+$M$3*$M16+$N$3*$N16)/SUM($C$3:$E$3,$G$3,$K$3,$M$3:$N$3) -> 119.3458 | T16: =+($E$3*$E16+$G$3*$G16+$K$3*$K16+$M$3*$M16+$N$3*$N16)/SUM($E$3,$G$3,$K$3,$M$3:$N$3) -> 117.98858 | U16: =+($E$3*$E16+$G$3*$G16+$K$3*$K16+$N$3*$N16)/SUM($E$3,$G$3,$K$3,$N$3) -> 116.93217 | W16: =($E$3*$E16+SUMPRODUCT($G$3:$L$3,$G16:$L16)+$N$3*$N16)/SUM($E$3,$G$3:$L$3,$N$3) -> 118.94805 | Y16: =+B16/B15-1 -> 0.011715481 | Z16: =+C16/C15-1 -> 0.010025063 | AA16: =+D16/D15-1 -> 0.010647011 | AB16: =+E16/E15-1 -> 0.011443662 | AC16: =+F16/F15-1 -> 0.010085337 | AD16: =+G16/G15-1 -> 0.0070546737 | AE16: =+H16/H15-1 -> 0.012285012 | AF16: =+I16/I15-1 -> 0.026079137 | ... AT16: =+W16/W15-1 -> 0.01178933 | BS16: =+A16 -> 43040 | BT16: =(C16-C15)/$B15*C$3 -> 0.0023538075 | BU16: =(D16-D15)/$B15*D$3 -> 0.00035573222 | BV16: =(E16-E15)/$B15*E$3 -> 0.00092359833 | BW16: =(F16-F15)/$B15*F$3 -> 0.0011379079 | BX16: =(G16-G15)/$B15*G$3 -> 0.00041974895 | BY16: =(H16-H15)/$B15*H$3 -> 0.0011046025 | BZ16: =(I16-I15)/$B15*I$3 -> 0.002812636 | CA16: =(J16-J15)/$B15*J$3 -> 0.00016460251 | ... CE16: =(N16-N15)/$B15*N$3 -> 0.00041589958 | CF16: =+SUM(BT16:CE16) -> 0.011691548
A17: =+[1]NAC!A18 -> 43070 | B17: =+[1]GBA!B18 -> 125 | C17: =+[1]GBA!C18 -> 121.6 | D17: =+[1]GBA!D18 -> 124.1 | E17: =+[1]GBA!E18 -> 115.7 | F17: =+[1]GBA!F18 -> 154.7 | G17: =+[1]GBA!G18 -> 117.7 | H17: =+[1]GBA!H18 -> 127.2 | I17: =+[1]GBA!I18 -> 117.5 | ... N17: =+[1]GBA!N18 -> 119.7 | O17: =+[1]GBA!R18 -> 121.2 | P17: =+[1]GBA!S18 -> 121.8 | Q17: =+[1]GBA!T18 -> 136.4 | R17: =+SUMPRODUCT($C$3:$N$3,C17:N17) -> 125.05919 | S17: =+($C$3*$C17+$D$3*$D17+$E$3*$E17+$G$3*$G17+$K$3*$K17+$M$3*$M17+$N$3*$N17)/SUM($C$3:$E$3,$G$3,$K$3,$M$3:$N$3) -> 120.62186 | T17: =+($E$3*$E17+$G$3*$G17+$K$3*$K17+$M$3*$M17+$N$3*$N17)/SUM($E$3,$G$3,$K$3,$M$3:$N$3) -> 119.68492 | U17: =+($E$3*$E17+$G$3*$G17+$K$3*$K17+$N$3*$N17)/SUM($E$3,$G$3,$K$3,$N$3) -> 118.41665 | W17: =($E$3*$E17+SUMPRODUCT($G$3:$L$3,$G17:$L17)+$N$3*$N17)/SUM($E$3,$G$3:$L$3,$N$3) -> 121.2075 | Y17: =+B17/B16-1 -> 0.033912324 | Z17: =+C17/C16-1 -> 0.005789909 | AA17: =+D17/D16-1 -> 0.0056726094 | AB17: =+E17/E16-1 -> 0.0069625762 | AC17: =+F17/F16-1 -> 0.18817204 | AD17: =+G17/G16-1 -> 0.030647986 | AE17: =+H17/H16-1 -> 0.029126214 | AF17: =+I17/I16-1 -> 0.029798422 | ... AT17: =+W17/W16-1 -> 0.018995299 | AV17: =+B17/B5-1 -> 0.25 | AW17: =+C17/C5-1 -> 0.216 | AX17: =+D17/D5-1 -> 0.241 | AY17: =+E17/E5-1 -> 0.157 | AZ17: =+F17/F5-1 -> 0.547 | BA17: =+G17/G5-1 -> 0.177 | BB17: =+H17/H5-1 -> 0.272 | BC17: =+I17/I5-1 -> 0.175 | ... BQ17: =+W17/W5-1 -> 0.21207501 | BS17: =+A17 -> 43070 | BT17: =(C17-C16)/$B16*C$3 -> 0.0013571547 | BU17: =(D17-D16)/$B16*D$3 -> 0.00018933002 | BV17: =(E17-E16)/$B16*E$3 -> 0.0005617866 | BW17: =(F17-F16)/$B16*F$3 -> 0.021196857 | BX17: =(G17-G16)/$B16*G$3 -> 0.0018151365 | BY17: =(H17-H16)/$B16*H$3 -> 0.0026203474 | BZ17: =(I17-I16)/$B16*I$3 -> 0.0032593879 | CA17: =(J17-J16)/$B16*J$3 -> 0.00069727047 | ... CE17: =(N17-N16)/$B16*N$3 -> 0.0002936311 | CF17: =+SUM(BT17:CE17) -> 0.034432093
