Workbook

Sheet Indice PondENGHO
A1: Period | B1: Mes | C1: Anio | D1: ipc_d1_i1 | E1: ipc_d1_i2 | F1: ipc_d1_i3 | G1: ipc_d1_i4 | H1: ipc_d1_i5 | I1: ipc_d1_i6 | J1: ipc_d1_i7 | K1: ipc_d1_i8 | L1: ipc_d1_i9 | M1: ipc_d1_i10 | N1: ipc_d1_i11 | O1: ipc_d1_i12 | P1: ipc_d2_i1 | Q1: ipc_d2_i2 | R1: ipc_d2_i3 | S1: ipc_d2_i4 | T1: ipc_d2_i5 | U1: ipc_d2_i6 | V1: ipc_d2_i7 | W1: ipc_d2_i8 | X1: ipc_d2_i9 | Y1: ipc_d2_i10 | Z1: ipc_d2_i11 | AA1: ipc_d2_i12 | AB1: ipc_d3_i1 | AC1: ipc_d3_i2 | AD1: ipc_d3_i3 | AE1: ipc_d3_i4 | AF1: ipc_d3_i5 | AG1: ipc_d3_i6 | AH1: ipc_d3_i7 | AI1: ipc_d3_i8 | AJ1: ipc_d3_i9 | AK1: ipc_d3_i10 | AL1: ipc_d3_i11 | AM1: ipc_d3_i12 | AN1: ipc_d4_i1 | AO1: ipc_d4_i2 | AP1: ipc_d4_i3 | AQ1: ipc_d4_i4 | AR1: ipc_d4_i5 | AS1: ipc_d4_i6 | AT1: ipc_d4_i7 | AU1: ipc_d4_i8 | AV1: ipc_d4_i9 | AW1: ipc_d4_i10 | AX1: ipc_d4_i11 | AY1: ipc_d4_i12 | AZ1: ipc_d5_i1 | BA1: ipc_d5_i2 | BB1: ipc_d5_i3 | BC1: ipc_d5_i4 | BD1: ipc_d5_i5 | BE1: ipc_d5_i6 | BF1: ipc_d5_i7 | BG1: ipc_d5_i8 | BH1: ipc_d5_i9 | BI1: ipc_d5_i10 | BJ1: ipc_d5_i11 | BK1: ipc_d5_i12 | BL1: ipc_quintil1 | BM1: ipc_quintil2 | BN1: ipc_quintil3 | BO1: ipc_quintil4 | BP1: ipc_quintil5 | BQ1: ipc_div1 | BR1: ipc_div2 | BS1: ipc_div3 | BT1: ipc_div4 | BU1: ipc_div5 | BV1: ipc_div6 | BW1: ipc_div7 | BX1: ipc_div8 | BY1: ipc_div9 | BZ1: ipc_div10 | CA1: ipc_div11 | CB1: ipc_div12 | CC1: ipc_sum_d | CD1: ipc_sum_i | CF1: IPCse Nacional
A2: =+[1]Sheet1!A2 -> 42705 | B2: =+[1]Sheet1!B2 -> 12 | C2: =+[1]Sheet1!C2 -> 2016 | D2: =+[1]Sheet1!D2 -> 100 | E2: =+[1]Sheet1!E2 -> 100 | F2: =+[1]Sheet1!F2 -> 100 | G2: =+[1]Sheet1!G2 -> 100 | H2: =+[1]Sheet1!H2 -> 100 | ... CD2: =+[1]Sheet1!CD2 -> 100 | CF2: =+[2]IPCse!DC6 -> 100.08115 | CG2: =+CF2/$CF$2*100 -> 100
A3: =+[1]Sheet1!A3 -> 42736 | B3: =+[1]Sheet1!B3 -> 1 | C3: =+[1]Sheet1!C3 -> 2017 | D3: =+[1]Sheet1!D3 -> 100.75443 | E3: =+[1]Sheet1!E3 -> 100.07867 | F3: =+[1]Sheet1!F3 -> 101.8736 | G3: =+[1]Sheet1!G3 -> 101.75706 | H3: =+[1]Sheet1!H3 -> 101.41307 | ... CD3: =+[1]Sheet1!CD3 -> 101.71334 | CF3: =+[2]IPCse!DC7 -> 101.83133 | CG3: =+CF3/$CF$2*100 -> 101.74877
A4: =+[1]Sheet1!A4 -> 42767 | B4: =+[1]Sheet1!B4 -> 2 | C4: =+[1]Sheet1!C4 -> 2017 | D4: =+[1]Sheet1!D4 -> 101.49557 | E4: =+[1]Sheet1!E4 -> 104.12119 | F4: =+[1]Sheet1!F4 -> 103.72802 | G4: =+[1]Sheet1!G4 -> 106.74596 | H4: =+[1]Sheet1!H4 -> 102.41474 | ... CD4: =+[1]Sheet1!CD4 -> 103.7085 | CF4: =+[2]IPCse!DC8 -> 104.1019 | CG4: =+CF4/$CF$2*100 -> 104.01749
A5: =+[1]Sheet1!A5 -> 42795 | B5: =+[1]Sheet1!B5 -> 3 | C5: =+[1]Sheet1!C5 -> 2017 | D5: =+[1]Sheet1!D5 -> 102.59162 | E5: =+[1]Sheet1!E5 -> 105.44258 | F5: =+[1]Sheet1!F5 -> 105.09715 | G5: =+[1]Sheet1!G5 -> 111.78063 | H5: =+[1]Sheet1!H5 -> 103.34509 | ... CD5: =+[1]Sheet1!CD5 -> 105.21078 | CF5: =+[2]IPCse!DC9 -> 105.87704 | CG5: =+CF5/$CF$2*100 -> 105.79119
A6: =+[1]Sheet1!A6 -> 42826 | B6: =+[1]Sheet1!B6 -> 4 | C6: =+[1]Sheet1!C6 -> 2017 | D6: =+[1]Sheet1!D6 -> 104.83715 | E6: =+[1]Sheet1!E6 -> 109.06272 | F6: =+[1]Sheet1!F6 -> 107.19997 | G6: =+[1]Sheet1!G6 -> 118.56262 | H6: =+[1]Sheet1!H6 -> 104.72852 | ... CD6: =+[1]Sheet1!CD6 -> 107.88415 | CF6: =+[2]IPCse!DC10 -> 108.69903 | CG6: =+CF6/$CF$2*100 -> 108.61089
A7: =+[1]Sheet1!A7 -> 42856 | B7: =+[1]Sheet1!B7 -> 5 | C7: =+[1]Sheet1!C7 -> 2017 | D7: =+[1]Sheet1!D7 -> 107.56224 | E7: =+[1]Sheet1!E7 -> 111.66264 | F7: =+[1]Sheet1!F7 -> 109.13326 | G7: =+[1]Sheet1!G7 -> 120.7638 | H7: =+[1]Sheet1!H7 -> 107.61269 | ... CD7: =+[1]Sheet1!CD7 -> 109.93848 | CF7: =+[2]IPCse!DC11 -> 110.58836 | CG7: =+CF7/$CF$2*100 -> 110.4987
A8: =+[1]Sheet1!A8 -> 42887 | B8: =+[1]Sheet1!B8 -> 6 | C8: =+[1]Sheet1!C8 -> 2017 | D8: =+[1]Sheet1!D8 -> 109.82121 | E8: =+[1]Sheet1!E8 -> 113.23004 | F8: =+[1]Sheet1!F8 -> 110.39194 | G8: =+[1]Sheet1!G8 -> 122.76114 | H8: =+[1]Sheet1!H8 -> 108.65285 | ... CD8: =+[1]Sheet1!CD8 -> 111.71211 | CF8: =+[2]IPCse!DC12 -> 112.02423 | CG8: =+CF8/$CF$2*100 -> 111.93339
A9: =+[1]Sheet1!A9 -> 42917 | B9: =+[1]Sheet1!B9 -> 7 | C9: =+[1]Sheet1!C9 -> 2017 | D9: =+[1]Sheet1!D9 -> 111.87272 | E9: =+[1]Sheet1!E9 -> 117.20149 | F9: =+[1]Sheet1!F9 -> 111.47215 | G9: =+[1]Sheet1!G9 -> 125.07801 | H9: =+[1]Sheet1!H9 -> 110.44017 | ... CD9: =+[1]Sheet1!CD9 -> 114.14445 | CF9: =+[2]IPCse!DC13 -> 114.31438 | CG9: =+CF9/$CF$2*100 -> 114.2217
A10: =+[1]Sheet1!A10 -> 42948 | B10: =+[1]Sheet1!B10 -> 8 | C10: =+[1]Sheet1!C10 -> 2017 | D10: =+[1]Sheet1!D10 -> 113.92788 | E10: =+[1]Sheet1!E10 -> 119.41688 | F10: =+[1]Sheet1!F10 -> 111.48376 | G10: =+[1]Sheet1!G10 -> 127.60696 | H10: =+[1]Sheet1!H10 -> 111.23627 | ... CD10: =+[1]Sheet1!CD10 -> 115.80611 | CF10: =+[2]IPCse!DC14 -> 115.95096 | CG10: =+CF10/$CF$2*100 -> 115.85695
A11: =+[1]Sheet1!A11 -> 42979 | B11: =+[1]Sheet1!B11 -> 9 | C11: =+[1]Sheet1!C11 -> 2017 | D11: =+[1]Sheet1!D11 -> 115.58742 | E11: =+[1]Sheet1!E11 -> 119.55397 | F11: =+[1]Sheet1!F11 -> 111.56204 | G11: =+[1]Sheet1!G11 -> 130.02391 | H11: =+[1]Sheet1!H11 -> 111.74674 | ... CD11: =+[1]Sheet1!CD11 -> 117.44674 | CF11: =+[2]IPCse!DC15 -> 117.3269 | CG11: =+CF11/$CF$2*100 -> 117.23176
A12: =+[1]Sheet1!A12 -> 43009 | B12: =+[1]Sheet1!B12 -> 10 | C12: =+[1]Sheet1!C12 -> 2017 | D12: =+[1]Sheet1!D12 -> 117.12006 | E12: =+[1]Sheet1!E12 -> 123.16584 | F12: =+[1]Sheet1!F12 -> 112.53708 | G12: =+[1]Sheet1!G12 -> 131.26573 | H12: =+[1]Sheet1!H12 -> 112.17809 | ... CD12: =+[1]Sheet1!CD12 -> 119.02953 | CF12: =+[2]IPCse!DC16 -> 118.77745 | CG12: =+CF12/$CF$2*100 -> 118.68115
A13: =+[1]Sheet1!A13 -> 43040 | B13: =+[1]Sheet1!B13 -> 11 | C13: =+[1]Sheet1!C13 -> 2017 | D13: =+[1]Sheet1!D13 -> 119.28683 | E13: =+[1]Sheet1!E13 -> 123.90735 | F13: =+[1]Sheet1!F13 -> 114.2287 | G13: =+[1]Sheet1!G13 -> 133.02287 | H13: =+[1]Sheet1!H13 -> 113.32578 | ... CD13: =+[1]Sheet1!CD13 -> 120.90509 | CF13: =+[2]IPCse!DC17 -> 120.73169 | CG13: =+CF13/$CF$2*100 -> 120.6338
... A102: =+[1]Sheet1!A102 -> 45748 | B102: =+[1]Sheet1!B102 -> 4 | C102: =+[1]Sheet1!C102 -> 2025 | D102: =+[1]Sheet1!D102 -> 8950.2314 | E102: =+[1]Sheet1!E102 -> 6382.5938 | F102: =+[1]Sheet1!F102 -> 7108.0645 | G102: =+[1]Sheet1!G102 -> 8837.0273 | H102: =+[1]Sheet1!H102 -> 7473.8218 | ... CD102: =+[1]Sheet1!CD102 -> 8485.3545 | CF102: =+[2]IPCse!DC106 -> 8482.8647 | CG102: =+CF102/$CF$2*100 -> 8475.9866
A103: =+[1]Sheet1!A103 -> 45778 | B103: =+[1]Sheet1!B103 -> 5 | C103: =+[1]Sheet1!C103 -> 2025 | D103: =+[1]Sheet1!D103 -> 9110.873 | E103: =+[1]Sheet1!E103 -> 6465.0679 | F103: =+[1]Sheet1!F103 -> 7233.2056 | G103: =+[1]Sheet1!G103 -> 9039.3633 | H103: =+[1]Sheet1!H103 -> 7594.3174 | ... CD103: =+[1]Sheet1!CD103 -> 8657.0293
A104: =+[1]Sheet1!A104 -> 45809 | B104: =+[1]Sheet1!B104 -> 6 | C104: =+[1]Sheet1!C104 -> 2025 | D104: =+[1]Sheet1!D104 -> 9262.332 | E104: =+[1]Sheet1!E104 -> 6681.9668 | F104: =+[1]Sheet1!F104 -> 7385.7178 | G104: =+[1]Sheet1!G104 -> 9322.1201 | H104: =+[1]Sheet1!H104 -> 7752.8857 | ... CD104: =+[1]Sheet1!CD104 -> 8848.1533
A105: =+[1]Sheet1!A105 -> 45839 | B105: =+[1]Sheet1!B105 -> 7 | C105: =+[1]Sheet1!C105 -> 2025 | D105: =+[1]Sheet1!D105 -> 9502.2041 | E105: =+[1]Sheet1!E105 -> 6768.7134 | F105: =+[1]Sheet1!F105 -> 7494.5532 | G105: =+[1]Sheet1!G105 -> 9488.043 | H105: =+[1]Sheet1!H105 -> 7857.6504 | ... CD105: =+[1]Sheet1!CD105 -> 9061.7129
A106: =+[1]Sheet1!A106 -> 45870 | B106: =+[1]Sheet1!B106 -> 8 | C106: =+[1]Sheet1!C106 -> 2025 | D106: =+[1]Sheet1!D106 -> 9619.2559 | E106: =+[1]Sheet1!E106 -> 7030.8726 | F106: =+[1]Sheet1!F106 -> 7547.9531 | G106: =+[1]Sheet1!G106 -> 9753.0479 | H106: =+[1]Sheet1!H106 -> 7914.2612 | ... CD106: =+[1]Sheet1!CD106 -> 9242.8193
A107: =+[1]Sheet1!A107 -> 45901 | B107: =+[1]Sheet1!B107 -> 9 | C107: =+[1]Sheet1!C107 -> 2025 | D107: =+[1]Sheet1!D107 -> 9755.3994 | E107: =+[1]Sheet1!E107 -> 7095.3384 | F107: =+[1]Sheet1!F107 -> 7498.5928 | G107: =+[1]Sheet1!G107 -> 10050.595 | H107: =+[1]Sheet1!H107 -> 8046.3662 | ... CD107: =+[1]Sheet1!CD107 -> 9404.5459
A108: =+[1]Sheet1!A108 -> 45931 | B108: =+[1]Sheet1!B108 -> 10 | C108: =+[1]Sheet1!C108 -> 2025 | D108: =+[1]Sheet1!D108 -> 9954.0771 | E108: =+[1]Sheet1!E108 -> 7272.54 | F108: =+[1]Sheet1!F108 -> 7589.1943 | G108: =+[1]Sheet1!G108 -> 10332.94 | H108: =+[1]Sheet1!H108 -> 8144.1665 | ... CD108: =+[1]Sheet1!CD108 -> 9611.4648
A109: =+[1]Sheet1!A109 -> 45962 | B109: =+[1]Sheet1!B109 -> 11 | C109: =+[1]Sheet1!C109 -> 2025 | D109: =+[1]Sheet1!D109 -> 10310.335 | E109: =+[1]Sheet1!E109 -> 7319.1528 | F109: =+[1]Sheet1!F109 -> 7648.3823 | G109: =+[1]Sheet1!G109 -> 10679.304 | H109: =+[1]Sheet1!H109 -> 8239.876 | ... CD109: =+[1]Sheet1!CD109 -> 9869.6943
A110: =+[1]Sheet1!A110 -> 45992 | B110: =+[1]Sheet1!B110 -> 12 | C110: =+[1]Sheet1!C110 -> 2025 | D110: =+[1]Sheet1!D110 -> 10671.262 | E110: =+[1]Sheet1!E110 -> 7470.8403 | F110: =+[1]Sheet1!F110 -> 7725.6196 | G110: =+[1]Sheet1!G110 -> 11031.151 | H110: =+[1]Sheet1!H110 -> 8390.0928 | ... CD110: =+[1]Sheet1!CD110 -> 10152.513
A111: =+[1]Sheet1!A111 -> 46023 | B111: =+[1]Sheet1!B111 -> 1 | C111: =+[1]Sheet1!C111 -> 2026 | D111: =+[1]Sheet1!D111 -> 11097.93 | E111: =+[1]Sheet1!E111 -> 7518.1904 | F111: =+[1]Sheet1!F111 -> 7853.9209 | G111: =+[1]Sheet1!G111 -> 11427.988 | H111: =+[1]Sheet1!H111 -> 8537.5908 | ... CD111: =+[1]Sheet1!CD111 -> 10440.051
A112: =+[1]Sheet1!A112 -> 46054 | B112: =+[1]Sheet1!B112 -> 2 | C112: =+[1]Sheet1!C112 -> 2026 | D112: =+[1]Sheet1!D112 -> 11359.511 | E112: =+[1]Sheet1!E112 -> 7570.7695 | F112: =+[1]Sheet1!F112 -> 7962.8838 | G112: =+[1]Sheet1!G112 -> 12210.819 | H112: =+[1]Sheet1!H112 -> 8763.833 | ... CD112: =+[1]Sheet1!CD112 -> 10714.419
A113: =+[1]Sheet1!A113 -> 46082 | B113: =+[1]Sheet1!B113 -> 3 | C113: =+[1]Sheet1!C113 -> 2026 | D113: =+[1]Sheet1!D113 -> 11606.613 | E113: =+[1]Sheet1!E113 -> 7675.4512 | F113: =+[1]Sheet1!F113 -> 7988.353 | G113: =+[1]Sheet1!G113 -> 12727.055 | H113: =+[1]Sheet1!H113 -> 8890.0332 | ... CD113: =+[1]Sheet1!CD113 -> 10969.06
A114: =+[1]Sheet1!A114 -> 46113 | B114: =+[1]Sheet1!B114 -> 4 | C114: =+[1]Sheet1!C114 -> 2026 | D114: =+[1]Sheet1!D114 -> 11778.271 | E114: =+[1]Sheet1!E114 -> 7896.3306 | F114: =+[1]Sheet1!F114 -> 8027.4614 | G114: =+[1]Sheet1!G114 -> 13155.908 | H114: =+[1]Sheet1!H114 -> 9140.6045 | ... CD114: =+[1]Sheet1!CD114 -> 11236.183
... A118: =+[1]Sheet1!A118 -> 46235 | B118: =+[1]Sheet1!B118 -> 8 | C118: =+[1]Sheet1!C118 -> 2026 | D118: =+[1]Sheet1!D118 -> 13064.222 | E118: =+[1]Sheet1!E118 -> 8617.0977 | F118: =+[1]Sheet1!F118 -> 8419.2559 | G118: =+[1]Sheet1!G118 -> 14799.204 | H118: =+[1]Sheet1!H118 -> 9780.8721 | ... CD118: =+[1]Sheet1!CD118 -> 12340.214

Sheet Infla Mensual PondENGHO
D1: QUINTIL 1 | P1: QUINTIL 2 | AB1: QUINTIL 3 | AN1: QUINTIL 4 | AZ1: QUINTIL 5 | BM1: QUINTIL 1 | BN1: QUINTIL 2 | BO1: QUINTIL 3 | BP1: QUINTIL 4 | BQ1: QUINTIL 5 | BR1: TODOS | BS1: TODOS | BT1: TODOS | BU1: TODOS | BV1: TODOS | BW1: TODOS | BX1: TODOS | BY1: TODOS | BZ1: TODOS | CA1: TODOS | CB1: TODOS | CC1: TODOS | CD1: TODOS | CE1: TODOS
D2: Alimentos y bebidas no alcohólicas | E2: Bebidas alcohólicas y tabaco | F2: Prendas de vestir y calzado | G2: Vivienda, agua, electricidad, gas y otros combustibles | H2: Equipamiento y mantenimiento del hogar | I2: Salud | J2: Transporte | K2: Comunicación | L2: Recreación y cultura | M2: Educación | N2: Restaurantes y hoteles | O2: Bienes y servicios varios | P2: Alimentos y bebidas no alcohólicas | Q2: Bebidas alcohólicas y tabaco | R2: Prendas de vestir y calzado | S2: Vivienda, agua, electricidad, gas y otros combustibles | T2: Equipamiento y mantenimiento del hogar | U2: Salud | V2: Transporte | W2: Comunicación | X2: Recreación y cultura | Y2: Educación | Z2: Restaurantes y hoteles | AA2: Bienes y servicios varios | AB2: Alimentos y bebidas no alcohólicas | AC2: Bebidas alcohólicas y tabaco | AD2: Prendas de vestir y calzado | AE2: Vivienda, agua, electricidad, gas y otros combustibles | AF2: Equipamiento y mantenimiento del hogar | AG2: Salud | AH2: Transporte | AI2: Comunicación | AJ2: Recreación y cultura | AK2: Educación | AL2: Restaurantes y hoteles | AM2: Bienes y servicios varios | AN2: Alimentos y bebidas no alcohólicas | AO2: Bebidas alcohólicas y tabaco | AP2: Prendas de vestir y calzado | AQ2: Vivienda, agua, electricidad, gas y otros combustibles | AR2: Equipamiento y mantenimiento del hogar | AS2: Salud | AT2: Transporte | AU2: Comunicación | AV2: Recreación y cultura | AW2: Educación | AX2: Restaurantes y hoteles | AY2: Bienes y servicios varios | AZ2: Alimentos y bebidas no alcohólicas | BA2: Bebidas alcohólicas y tabaco | BB2: Prendas de vestir y calzado | BC2: Vivienda, agua, electricidad, gas y otros combustibles | BD2: Equipamiento y mantenimiento del hogar | BE2: Salud | BF2: Transporte | BG2: Comunicación | BH2: Recreación y cultura | BI2: Educación | BJ2: Restaurantes y hoteles | BK2: Bienes y servicios varios | BM2: TOTAL | BN2: TOTAL | BO2: TOTAL | BP2: TOTAL | BQ2: TOTAL | BR2: Alimentos y bebidas no alcohólicas | BS2: Bebidas alcohólicas y tabaco | BT2: Prendas de vestir y calzado | BU2: Vivienda, agua, electricidad, gas y otros combustibles | BV2: Equipamiento y mantenimiento del hogar | BW2: Salud | BX2: Transporte | BY2: Comunicación | BZ2: Recreación y cultura | CA2: Educación | CB2: Restaurantes y hoteles | CC2: Bienes y servicios varios | CD2: TOTAL | CE2: TOTAL | CI2: Q1-Q5 IPCse | CJ2: Q1-Q5 INDEC | CS2: =+BR2 -> Alimentos y bebidas no alcohólicas | CT2: =+BS2 -> Bebidas alcohólicas y tabaco | CU2: =+BT2 -> Prendas de vestir y calzado | CV2: =+BU2 -> Vivienda, agua, electricidad, gas y otros combustibles | CW2: =+BV2 -> Equipamiento y mantenimiento del hogar | CX2: =+BW2 -> Salud | CY2: =+BX2 -> Transporte | CZ2: =+BY2 -> Comunicación | ... DD2: =+CC2 -> Bienes y servicios varios
A3: Period | B3: Mes | C3: Anio | D3: ipc_d1_i1 | E3: ipc_d1_i2 | F3: ipc_d1_i3 | G3: ipc_d1_i4 | H3: ipc_d1_i5 | I3: ipc_d1_i6 | J3: ipc_d1_i7 | K3: ipc_d1_i8 | L3: ipc_d1_i9 | M3: ipc_d1_i10 | N3: ipc_d1_i11 | O3: ipc_d1_i12 | P3: ipc_d2_i1 | Q3: ipc_d2_i2 | R3: ipc_d2_i3 | S3: ipc_d2_i4 | T3: ipc_d2_i5 | U3: ipc_d2_i6 | V3: ipc_d2_i7 | W3: ipc_d2_i8 | X3: ipc_d2_i9 | Y3: ipc_d2_i10 | Z3: ipc_d2_i11 | AA3: ipc_d2_i12 | AB3: ipc_d3_i1 | AC3: ipc_d3_i2 | AD3: ipc_d3_i3 | AE3: ipc_d3_i4 | AF3: ipc_d3_i5 | AG3: ipc_d3_i6 | AH3: ipc_d3_i7 | AI3: ipc_d3_i8 | AJ3: ipc_d3_i9 | AK3: ipc_d3_i10 | AL3: ipc_d3_i11 | AM3: ipc_d3_i12 | AN3: ipc_d4_i1 | AO3: ipc_d4_i2 | AP3: ipc_d4_i3 | AQ3: ipc_d4_i4 | AR3: ipc_d4_i5 | AS3: ipc_d4_i6 | AT3: ipc_d4_i7 | AU3: ipc_d4_i8 | AV3: ipc_d4_i9 | AW3: ipc_d4_i10 | AX3: ipc_d4_i11 | AY3: ipc_d4_i12 | AZ3: ipc_d5_i1 | BA3: ipc_d5_i2 | BB3: ipc_d5_i3 | BC3: ipc_d5_i4 | BD3: ipc_d5_i5 | BE3: ipc_d5_i6 | BF3: ipc_d5_i7 | BG3: ipc_d5_i8 | BH3: ipc_d5_i9 | BI3: ipc_d5_i10 | BJ3: ipc_d5_i11 | BK3: ipc_d5_i12 | BM3: ipc_quintil1 | BN3: ipc_quintil2 | BO3: ipc_quintil3 | BP3: ipc_quintil4 | BQ3: ipc_quintil5 | BR3: ipc_div1 | BS3: ipc_div2 | BT3: ipc_div3 | BU3: ipc_div4 | BV3: ipc_div5 | BW3: ipc_div6 | BX3: ipc_div7 | BY3: ipc_div8 | BZ3: ipc_div9 | CA3: ipc_div10 | CB3: ipc_div11 | CC3: ipc_div12 | CD3: ipc_sum_d | CE3: ipc_sum_i | CI3: mensual | CJ3: mensual
A4: =+DATE(C4,B4,1) -> 42705 | B4: 12 | C4: 2016
A5: =+DATE(C5,B5,1) -> 42736 | B5: =+IF(B4=12,1,B4+1) -> 1 | C5: 2017 | D5: =+'Indice PondENGHO'!D3/'Indice PondENGHO'!D2-1 -> 0.0075442505 | E5: =+'Indice PondENGHO'!E3/'Indice PondENGHO'!E2-1 -> 0.00078674316 | F5: =+'Indice PondENGHO'!F3/'Indice PondENGHO'!F2-1 -> 0.018735962 | G5: =+'Indice PondENGHO'!G3/'Indice PondENGHO'!G2-1 -> 0.017570572 | H5: =+'Indice PondENGHO'!H3/'Indice PondENGHO'!H2-1 -> 0.014130707 | I5: =+'Indice PondENGHO'!I3/'Indice PondENGHO'!I2-1 -> 0.025207367 | J5: =+'Indice PondENGHO'!J3/'Indice PondENGHO'!J2-1 -> 0.021638412 | K5: =+'Indice PondENGHO'!K3/'Indice PondENGHO'!K2-1 -> 0.018220444 | ... BK5: =+'Indice PondENGHO'!BK3/'Indice PondENGHO'!BK2-1 -> 0.017867737 | BL5: =+A5 -> 42736 | BM5: =+'Indice PondENGHO'!BL3/'Indice PondENGHO'!BL2-1 -> 0.015351639 | BN5: =+'Indice PondENGHO'!BM3/'Indice PondENGHO'!BM2-1 -> 0.016014862 | BO5: =+'Indice PondENGHO'!BN3/'Indice PondENGHO'!BN2-1 -> 0.016733551 | BP5: =+'Indice PondENGHO'!BO3/'Indice PondENGHO'!BO2-1 -> 0.017434006 | BQ5: =+'Indice PondENGHO'!BP3/'Indice PondENGHO'!BP2-1 -> 0.018357315 | BR5: =+'Indice PondENGHO'!BQ3/'Indice PondENGHO'!BQ2-1 -> 0.0066861725 | BS5: =+'Indice PondENGHO'!BR3/'Indice PondENGHO'!BR2-1 -> 0.0002457428 | BT5: =+'Indice PondENGHO'!BS3/'Indice PondENGHO'!BS2-1 -> 0.018330994 | ... CE5: =+'Indice PondENGHO'!CD3/'Indice PondENGHO'!CD2-1 -> 0.017133408 | CG5: =+'Indice PondENGHO'!CF3/'Indice PondENGHO'!CF2-1 -> 0.017487652 | CI5: =+BM5-BQ5 -> -0.0030056763 | CJ5: =+'[3]Infla Mensual PondENGHO'!CF5 -> -0.0017551422 | CK5: =+CI5-CJ5 -> -0.0012505341
A6: =+DATE(C6,B6,1) -> 42767 | B6: =+IF(B5=12,1,B5+1) -> 2 | C6: 2017 | D6: =+'Indice PondENGHO'!D4/'Indice PondENGHO'!D3-1 -> 0.0073560035 | E6: =+'Indice PondENGHO'!E4/'Indice PondENGHO'!E3-1 -> 0.040393407 | F6: =+'Indice PondENGHO'!F4/'Indice PondENGHO'!F3-1 -> 0.018203181 | G6: =+'Indice PondENGHO'!G4/'Indice PondENGHO'!G3-1 -> 0.049027625 | H6: =+'Indice PondENGHO'!H4/'Indice PondENGHO'!H3-1 -> 0.0098771374 | I6: =+'Indice PondENGHO'!I4/'Indice PondENGHO'!I3-1 -> 0.025133212 | J6: =+'Indice PondENGHO'!J4/'Indice PondENGHO'!J3-1 -> 0.019411658 | K6: =+'Indice PondENGHO'!K4/'Indice PondENGHO'!K3-1 -> 0.028371307 | ... BK6: =+'Indice PondENGHO'!BK4/'Indice PondENGHO'!BK3-1 -> 0.023270428 | BL6: =+A6 -> 42767 | BM6: =+'Indice PondENGHO'!BL4/'Indice PondENGHO'!BL3-1 -> 0.017521768 | BN6: =+'Indice PondENGHO'!BM4/'Indice PondENGHO'!BM3-1 -> 0.018878946 | BO6: =+'Indice PondENGHO'!BN4/'Indice PondENGHO'!BN3-1 -> 0.019006823 | BP6: =+'Indice PondENGHO'!BO4/'Indice PondENGHO'!BO3-1 -> 0.019595881 | BQ6: =+'Indice PondENGHO'!BP4/'Indice PondENGHO'!BP3-1 -> 0.021104506 | BR6: =+'Indice PondENGHO'!BQ4/'Indice PondENGHO'!BQ3-1 -> 0.0060322837 | BS6: =+'Indice PondENGHO'!BR4/'Indice PondENGHO'!BR3-1 -> 0.042024509 | BT6: =+'Indice PondENGHO'!BS4/'Indice PondENGHO'!BS3-1 -> 0.019383302 | ... CE6: =+'Indice PondENGHO'!CD4/'Indice PondENGHO'!CD3-1 -> 0.019615473 | CG6: =+'Indice PondENGHO'!CF4/'Indice PondENGHO'!CF3-1 -> 0.022297309 | CI6: =+BM6-BQ6 -> -0.0035827377 | CJ6: =+'[3]Infla Mensual PondENGHO'!CF6 -> -0.0011134335 | CK6: =+CI6-CJ6 -> -0.0024693042
A7: =+DATE(C7,B7,1) -> 42795 | B7: =+IF(B6=12,1,B6+1) -> 3 | C7: 2017 | D7: =+'Indice PondENGHO'!D5/'Indice PondENGHO'!D4-1 -> 0.010798958 | E7: =+'Indice PondENGHO'!E5/'Indice PondENGHO'!E4-1 -> 0.012690867 | F7: =+'Indice PondENGHO'!F5/'Indice PondENGHO'!F4-1 -> 0.013199259 | G7: =+'Indice PondENGHO'!G5/'Indice PondENGHO'!G4-1 -> 0.047164949 | H7: =+'Indice PondENGHO'!H5/'Indice PondENGHO'!H4-1 -> 0.0090840792 | I7: =+'Indice PondENGHO'!I5/'Indice PondENGHO'!I4-1 -> 0.020900845 | J7: =+'Indice PondENGHO'!J5/'Indice PondENGHO'!J4-1 -> 0.01144149 | K7: =+'Indice PondENGHO'!K5/'Indice PondENGHO'!K4-1 -> 0.029446479 | ... BK7: =+'Indice PondENGHO'!BK5/'Indice PondENGHO'!BK4-1 -> 0.021812932 | BL7: =+A7 -> 42795 | BM7: =+'Indice PondENGHO'!BL5/'Indice PondENGHO'!BL4-1 -> 0.015757365 | BN7: =+'Indice PondENGHO'!BM5/'Indice PondENGHO'!BM4-1 -> 0.015214699 | BO7: =+'Indice PondENGHO'!BN5/'Indice PondENGHO'!BN4-1 -> 0.014807407 | BP7: =+'Indice PondENGHO'!BO5/'Indice PondENGHO'!BO4-1 -> 0.014391298 | BQ7: =+'Indice PondENGHO'!BP5/'Indice PondENGHO'!BP4-1 -> 0.013548027 | BR7: =+'Indice PondENGHO'!BQ5/'Indice PondENGHO'!BQ4-1 -> 0.012459968 | BS7: =+'Indice PondENGHO'!BR5/'Indice PondENGHO'!BR4-1 -> 0.011634696 | BT7: =+'Indice PondENGHO'!BS5/'Indice PondENGHO'!BS4-1 -> 0.011380265 | ... CE7: =+'Indice PondENGHO'!CD5/'Indice PondENGHO'!CD4-1 -> 0.014485613 | CG7: =+'Indice PondENGHO'!CF5/'Indice PondENGHO'!CF4-1 -> 0.017051949 | CI7: =+BM7-BQ7 -> 0.002209338 | CJ7: =+'[3]Infla Mensual PondENGHO'!CF7 -> 0.0028364713 | CK7: =+CI7-CJ7 -> -0.00062713335
A8: =+DATE(C8,B8,1) -> 42826 | B8: =+IF(B7=12,1,B7+1) -> 4 | C8: 2017 | D8: =+'Indice PondENGHO'!D6/'Indice PondENGHO'!D5-1 -> 0.021888037 | E8: =+'Indice PondENGHO'!E6/'Indice PondENGHO'!E5-1 -> 0.03433281 | F8: =+'Indice PondENGHO'!F6/'Indice PondENGHO'!F5-1 -> 0.020008284 | G8: =+'Indice PondENGHO'!G6/'Indice PondENGHO'!G5-1 -> 0.060672318 | H8: =+'Indice PondENGHO'!H6/'Indice PondENGHO'!H5-1 -> 0.013386515 | I8: =+'Indice PondENGHO'!I6/'Indice PondENGHO'!I5-1 -> 0.019375686 | J8: =+'Indice PondENGHO'!J6/'Indice PondENGHO'!J5-1 -> 0.0072845964 | K8: =+'Indice PondENGHO'!K6/'Indice PondENGHO'!K5-1 -> 0.07388664 | ... BK8: =+'Indice PondENGHO'!BK6/'Indice PondENGHO'!BK5-1 -> 0.025473053 | BL8: =+A8 -> 42826 | BM8: =+'Indice PondENGHO'!BL6/'Indice PondENGHO'!BL5-1 -> 0.025906973 | BN8: =+'Indice PondENGHO'!BM6/'Indice PondENGHO'!BM5-1 -> 0.026092845 | BO8: =+'Indice PondENGHO'!BN6/'Indice PondENGHO'!BN5-1 -> 0.026030652 | BP8: =+'Indice PondENGHO'!BO6/'Indice PondENGHO'!BO5-1 -> 0.025123118 | BQ8: =+'Indice PondENGHO'!BP6/'Indice PondENGHO'!BP5-1 -> 0.024753143 | BR8: =+'Indice PondENGHO'!BQ6/'Indice PondENGHO'!BQ5-1 -> 0.021215817 | BS8: =+'Indice PondENGHO'!BR6/'Indice PondENGHO'!BR5-1 -> 0.034221407 | BT8: =+'Indice PondENGHO'!BS6/'Indice PondENGHO'!BS5-1 -> 0.022149726 | ... CE8: =+'Indice PondENGHO'!CD6/'Indice PondENGHO'!CD5-1 -> 0.025409663 | CG8: =+'Indice PondENGHO'!CF6/'Indice PondENGHO'!CF5-1 -> 0.026653445 | CI8: =+BM8-BQ8 -> 0.0011538302 | CJ8: =+'[3]Infla Mensual PondENGHO'!CF8 -> 0.0017536667 | CK8: =+CI8-CJ8 -> -0.00059983651
A9: =+DATE(C9,B9,1) -> 42856 | B9: =+IF(B8=12,1,B8+1) -> 5 | C9: 2017 | D9: =+'Indice PondENGHO'!D7/'Indice PondENGHO'!D6-1 -> 0.025993553 | E9: =+'Indice PondENGHO'!E7/'Indice PondENGHO'!E6-1 -> 0.02383871 | F9: =+'Indice PondENGHO'!F7/'Indice PondENGHO'!F6-1 -> 0.018034414 | G9: =+'Indice PondENGHO'!G7/'Indice PondENGHO'!G6-1 -> 0.018565543 | H9: =+'Indice PondENGHO'!H7/'Indice PondENGHO'!H6-1 -> 0.027539496 | I9: =+'Indice PondENGHO'!I7/'Indice PondENGHO'!I6-1 -> 0.01571528 | J9: =+'Indice PondENGHO'!J7/'Indice PondENGHO'!J6-1 -> 0.010541779 | K9: =+'Indice PondENGHO'!K7/'Indice PondENGHO'!K6-1 -> 0.010837333 | ... BK9: =+'Indice PondENGHO'!BK7/'Indice PondENGHO'!BK6-1 -> 0.021562207 | BL9: =+A9 -> 42856 | BM9: =+'Indice PondENGHO'!BL7/'Indice PondENGHO'!BL6-1 -> 0.020444488 | BN9: =+'Indice PondENGHO'!BM7/'Indice PondENGHO'!BM6-1 -> 0.019712981 | BO9: =+'Indice PondENGHO'!BN7/'Indice PondENGHO'!BN6-1 -> 0.019302128 | BP9: =+'Indice PondENGHO'!BO7/'Indice PondENGHO'!BO6-1 -> 0.01870519 | BQ9: =+'Indice PondENGHO'!BP7/'Indice PondENGHO'!BP6-1 -> 0.018280376 | BR9: =+'Indice PondENGHO'!BQ7/'Indice PondENGHO'!BQ6-1 -> 0.026290407 | BS9: =+'Indice PondENGHO'!BR7/'Indice PondENGHO'!BR6-1 -> 0.024210473 | BT9: =+'Indice PondENGHO'!BS7/'Indice PondENGHO'!BS6-1 -> 0.017431604 | ... CE9: =+'Indice PondENGHO'!CD7/'Indice PondENGHO'!CD6-1 -> 0.019041991 | CG9: =+'Indice PondENGHO'!CF7/'Indice PondENGHO'!CF6-1 -> 0.01738138 | CI9: =+BM9-BQ9 -> 0.0021641118 | CJ9: =+'[3]Infla Mensual PondENGHO'!CF9 -> 0.00040561072 | CK9: =+CI9-CJ9 -> 0.001758501
A10: =+DATE(C10,B10,1) -> 42887 | B10: =+IF(B9=12,1,B9+1) -> 6 | C10: 2017 | D10: =+'Indice PondENGHO'!D8/'Indice PondENGHO'!D7-1 -> 0.021001535 | E10: =+'Indice PondENGHO'!E8/'Indice PondENGHO'!E7-1 -> 0.014036976 | F10: =+'Indice PondENGHO'!F8/'Indice PondENGHO'!F7-1 -> 0.011533444 | G10: =+'Indice PondENGHO'!G8/'Indice PondENGHO'!G7-1 -> 0.016539206 | H10: =+'Indice PondENGHO'!H8/'Indice PondENGHO'!H7-1 -> 0.0096657854 | I10: =+'Indice PondENGHO'!I8/'Indice PondENGHO'!I7-1 -> 0.015332169 | J10: =+'Indice PondENGHO'!J8/'Indice PondENGHO'!J7-1 -> 0.01045778 | K10: =+'Indice PondENGHO'!K8/'Indice PondENGHO'!K7-1 -> 0.009911869 | ... BK10: =+'Indice PondENGHO'!BK8/'Indice PondENGHO'!BK7-1 -> 0.018566962 | BL10: =+A10 -> 42887 | BM10: =+'Indice PondENGHO'!BL8/'Indice PondENGHO'!BL7-1 -> 0.016783459 | BN10: =+'Indice PondENGHO'!BM8/'Indice PondENGHO'!BM7-1 -> 0.016316702 | BO10: =+'Indice PondENGHO'!BN8/'Indice PondENGHO'!BN7-1 -> 0.01626526 | BP10: =+'Indice PondENGHO'!BO8/'Indice PondENGHO'!BO7-1 -> 0.015934925 | BQ10: =+'Indice PondENGHO'!BP8/'Indice PondENGHO'!BP7-1 -> 0.015862697 | BR10: =+'Indice PondENGHO'!BQ8/'Indice PondENGHO'!BQ7-1 -> 0.021632916 | BS10: =+'Indice PondENGHO'!BR8/'Indice PondENGHO'!BR7-1 -> 0.012900801 | BT10: =+'Indice PondENGHO'!BS8/'Indice PondENGHO'!BS7-1 -> 0.010693157 | ... CE10: =+'Indice PondENGHO'!CD8/'Indice PondENGHO'!CD7-1 -> 0.016132986 | CG10: =+'Indice PondENGHO'!CF8/'Indice PondENGHO'!CF7-1 -> 0.012983834 | CI10: =+BM10-BQ10 -> 0.00092076157 | CJ10: =+'[3]Infla Mensual PondENGHO'!CF10 -> -0.0013441253 | CK10: =+CI10-CJ10 -> 0.0022648869
A11: =+DATE(C11,B11,1) -> 42917 | B11: =+IF(B10=12,1,B10+1) -> 7 | C11: 2017 | D11: =+'Indice PondENGHO'!D9/'Indice PondENGHO'!D8-1 -> 0.018680417 | E11: =+'Indice PondENGHO'!E9/'Indice PondENGHO'!E8-1 -> 0.03507418 | F11: =+'Indice PondENGHO'!F9/'Indice PondENGHO'!F8-1 -> 0.0097852058 | G11: =+'Indice PondENGHO'!G9/'Indice PondENGHO'!G8-1 -> 0.018873005 | H11: =+'Indice PondENGHO'!H9/'Indice PondENGHO'!H8-1 -> 0.01644985 | I11: =+'Indice PondENGHO'!I9/'Indice PondENGHO'!I8-1 -> 0.032012265 | J11: =+'Indice PondENGHO'!J9/'Indice PondENGHO'!J8-1 -> 0.022630492 | K11: =+'Indice PondENGHO'!K9/'Indice PondENGHO'!K8-1 -> 0.02321019 | ... BK11: =+'Indice PondENGHO'!BK9/'Indice PondENGHO'!BK8-1 -> 0.013328871 | BL11: =+A11 -> 42917 | BM11: =+'Indice PondENGHO'!BL9/'Indice PondENGHO'!BL8-1 -> 0.020383551 | BN11: =+'Indice PondENGHO'!BM9/'Indice PondENGHO'!BM8-1 -> 0.021108606 | BO11: =+'Indice PondENGHO'!BN9/'Indice PondENGHO'!BN8-1 -> 0.021689451 | BP11: =+'Indice PondENGHO'!BO9/'Indice PondENGHO'!BO8-1 -> 0.0218843 | BQ11: =+'Indice PondENGHO'!BP9/'Indice PondENGHO'!BP8-1 -> 0.022588107 | BR11: =+'Indice PondENGHO'!BQ9/'Indice PondENGHO'!BQ8-1 -> 0.019100005 | BS11: =+'Indice PondENGHO'!BR9/'Indice PondENGHO'!BR8-1 -> 0.035475419 | BT11: =+'Indice PondENGHO'!BS9/'Indice PondENGHO'!BS8-1 -> 0.010139414 | ... CE11: =+'Indice PondENGHO'!CD9/'Indice PondENGHO'!CD8-1 -> 0.021773242 | CG11: =+'Indice PondENGHO'!CF9/'Indice PondENGHO'!CF8-1 -> 0.020443428 | CI11: =+BM11-BQ11 -> -0.002204556 | CJ11: =+'[3]Infla Mensual PondENGHO'!CF11 -> -0.0041420631 | CK11: =+CI11-CJ11 -> 0.0019375071
A12: =+DATE(C12,B12,1) -> 42948 | B12: =+IF(B11=12,1,B11+1) -> 8 | C12: 2017 | D12: =+'Indice PondENGHO'!D10/'Indice PondENGHO'!D9-1 -> 0.018370525 | E12: =+'Indice PondENGHO'!E10/'Indice PondENGHO'!E9-1 -> 0.018902365 | F12: =+'Indice PondENGHO'!F10/'Indice PondENGHO'!F9-1 -> 0.00010423741 | G12: =+'Indice PondENGHO'!G10/'Indice PondENGHO'!G9-1 -> 0.020218949 | H12: =+'Indice PondENGHO'!H10/'Indice PondENGHO'!H9-1 -> 0.007208468 | I12: =+'Indice PondENGHO'!I10/'Indice PondENGHO'!I9-1 -> 0.024041935 | J12: =+'Indice PondENGHO'!J10/'Indice PondENGHO'!J9-1 -> 0.010212166 | K12: =+'Indice PondENGHO'!K10/'Indice PondENGHO'!K9-1 -> 0.023255416 | ... BK12: =+'Indice PondENGHO'!BK10/'Indice PondENGHO'!BK9-1 -> 0.0029795492 | BL12: =+A12 -> 42948 | BM12: =+'Indice PondENGHO'!BL10/'Indice PondENGHO'!BL9-1 -> 0.014516038 | BN12: =+'Indice PondENGHO'!BM10/'Indice PondENGHO'!BM9-1 -> 0.014656693 | BO12: =+'Indice PondENGHO'!BN10/'Indice PondENGHO'!BN9-1 -> 0.014821914 | BP12: =+'Indice PondENGHO'!BO10/'Indice PondENGHO'!BO9-1 -> 0.014598553 | BQ12: =+'Indice PondENGHO'!BP10/'Indice PondENGHO'!BP9-1 -> 0.014352775 | BR12: =+'Indice PondENGHO'!BQ10/'Indice PondENGHO'!BQ9-1 -> 0.019967367 | BS12: =+'Indice PondENGHO'!BR10/'Indice PondENGHO'!BR9-1 -> 0.018481044 | BT12: =+'Indice PondENGHO'!BS10/'Indice PondENGHO'!BS9-1 -> 0.00079975591 | ... CE12: =+'Indice PondENGHO'!CD10/'Indice PondENGHO'!CD9-1 -> 0.014557513 | CG12: =+'Indice PondENGHO'!CF10/'Indice PondENGHO'!CF9-1 -> 0.014316455 | CI12: =+BM12-BQ12 -> 0.00016326331 | CJ12: =+'[3]Infla Mensual PondENGHO'!CF12 -> 0.00028042872 | CK12: =+CI12-CJ12 -> -0.00011716542
A13: =+DATE(C13,B13,1) -> 42979 | B13: =+IF(B12=12,1,B12+1) -> 9 | C13: 2017 | D13: =+'Indice PondENGHO'!D11/'Indice PondENGHO'!D10-1 -> 0.014566569 | E13: =+'Indice PondENGHO'!E11/'Indice PondENGHO'!E10-1 -> 0.0011480169 | F13: =+'Indice PondENGHO'!F11/'Indice PondENGHO'!F10-1 -> 0.00070214339 | G13: =+'Indice PondENGHO'!G11/'Indice PondENGHO'!G10-1 -> 0.018940613 | H13: =+'Indice PondENGHO'!H11/'Indice PondENGHO'!H10-1 -> 0.0045890383 | I13: =+'Indice PondENGHO'!I11/'Indice PondENGHO'!I10-1 -> 0.023532853 | J13: =+'Indice PondENGHO'!J11/'Indice PondENGHO'!J10-1 -> 0.0068897453 | K13: =+'Indice PondENGHO'!K11/'Indice PondENGHO'!K10-1 -> 0.011162919 | ... BK13: =+'Indice PondENGHO'!BK11/'Indice PondENGHO'!BK10-1 -> 0.0096761026 | BL13: =+A13 -> 42979 | BM13: =+'Indice PondENGHO'!BL11/'Indice PondENGHO'!BL10-1 -> 0.013175251 | BN13: =+'Indice PondENGHO'!BM11/'Indice PondENGHO'!BM10-1 -> 0.013593273 | BO13: =+'Indice PondENGHO'!BN11/'Indice PondENGHO'!BN10-1 -> 0.014248866 | BP13: =+'Indice PondENGHO'!BO11/'Indice PondENGHO'!BO10-1 -> 0.014269333 | BQ13: =+'Indice PondENGHO'!BP11/'Indice PondENGHO'!BP10-1 -> 0.014701921 | BR13: =+'Indice PondENGHO'!BQ11/'Indice PondENGHO'!BQ10-1 -> 0.014152631 | BS13: =+'Indice PondENGHO'!BR11/'Indice PondENGHO'!BR10-1 -> 0.00073903402 | BT13: =+'Indice PondENGHO'!BS11/'Indice PondENGHO'!BS10-1 -> 0.0013111397 | ... CE13: =+'Indice PondENGHO'!CD11/'Indice PondENGHO'!CD10-1 -> 0.014167065 | CG13: =+'Indice PondENGHO'!CF11/'Indice PondENGHO'!CF10-1 -> 0.01186652 | CI13: =+BM13-BQ13 -> -0.0015266696 | CJ13: =+'[3]Infla Mensual PondENGHO'!CF13 -> -0.00046864004 | CK13: =+CI13-CJ13 -> -0.0010580295
A14: =+DATE(C14,B14,1) -> 43009 | B14: =+IF(B13=12,1,B13+1) -> 10 | C14: 2017 | D14: =+'Indice PondENGHO'!D12/'Indice PondENGHO'!D11-1 -> 0.013259562 | E14: =+'Indice PondENGHO'!E12/'Indice PondENGHO'!E11-1 -> 0.030211208 | F14: =+'Indice PondENGHO'!F12/'Indice PondENGHO'!F11-1 -> 0.0087398599 | G14: =+'Indice PondENGHO'!G12/'Indice PondENGHO'!G11-1 -> 0.0095507148 | H14: =+'Indice PondENGHO'!H12/'Indice PondENGHO'!H11-1 -> 0.0038600058 | I14: =+'Indice PondENGHO'!I12/'Indice PondENGHO'!I11-1 -> 0.011406851 | J14: =+'Indice PondENGHO'!J12/'Indice PondENGHO'!J11-1 -> 0.013872925 | K14: =+'Indice PondENGHO'!K12/'Indice PondENGHO'!K11-1 -> 0.060242422 | ... BK14: =+'Indice PondENGHO'!BK12/'Indice PondENGHO'!BK11-1 -> 0.010856543 | BL14: =+A14 -> 43009 | BM14: =+'Indice PondENGHO'!BL12/'Indice PondENGHO'!BL11-1 -> 0.014050382 | BN14: =+'Indice PondENGHO'!BM12/'Indice PondENGHO'!BM11-1 -> 0.01406007 | BO14: =+'Indice PondENGHO'!BN12/'Indice PondENGHO'!BN11-1 -> 0.013849764 | BP14: =+'Indice PondENGHO'!BO12/'Indice PondENGHO'!BO11-1 -> 0.013411135 | BQ14: =+'Indice PondENGHO'!BP12/'Indice PondENGHO'!BP11-1 -> 0.012821369 | BR14: =+'Indice PondENGHO'!BQ12/'Indice PondENGHO'!BQ11-1 -> 0.012393814 | BS14: =+'Indice PondENGHO'!BR12/'Indice PondENGHO'!BR11-1 -> 0.030352781 | BT14: =+'Indice PondENGHO'!BS12/'Indice PondENGHO'!BS11-1 -> 0.0085000476 | ... CE14: =+'Indice PondENGHO'!CD12/'Indice PondENGHO'!CD11-1 -> 0.013476633 | CG14: =+'Indice PondENGHO'!CF12/'Indice PondENGHO'!CF11-1 -> 0.012363395 | CI14: =+BM14-BQ14 -> 0.0012290132 | CJ14: =+'[3]Infla Mensual PondENGHO'!CF14 -> 0.0018482203 | CK14: =+CI14-CJ14 -> -0.00061920712
A15: =+DATE(C15,B15,1) -> 43040 | B15: =+IF(B14=12,1,B14+1) -> 11 | C15: 2017 | D15: =+'Indice PondENGHO'!D13/'Indice PondENGHO'!D12-1 -> 0.018500491 | E15: =+'Indice PondENGHO'!E13/'Indice PondENGHO'!E12-1 -> 0.006020407 | F15: =+'Indice PondENGHO'!F13/'Indice PondENGHO'!F12-1 -> 0.015031667 | G15: =+'Indice PondENGHO'!G13/'Indice PondENGHO'!G12-1 -> 0.013386137 | H15: =+'Indice PondENGHO'!H13/'Indice PondENGHO'!H12-1 -> 0.010230963 | I15: =+'Indice PondENGHO'!I13/'Indice PondENGHO'!I12-1 -> 0.012730552 | J15: =+'Indice PondENGHO'!J13/'Indice PondENGHO'!J12-1 -> 0.028882212 | K15: =+'Indice PondENGHO'!K13/'Indice PondENGHO'!K12-1 -> 0.0094774191 | ... BK15: =+'Indice PondENGHO'!BK13/'Indice PondENGHO'!BK12-1 -> 0.0064634738 | BL15: =+A15 -> 43040 | BM15: =+'Indice PondENGHO'!BL13/'Indice PondENGHO'!BL12-1 -> 0.015979991 | BN15: =+'Indice PondENGHO'!BM13/'Indice PondENGHO'!BM12-1 -> 0.015980937 | BO15: =+'Indice PondENGHO'!BN13/'Indice PondENGHO'!BN12-1 -> 0.01592988 | BP15: =+'Indice PondENGHO'!BO13/'Indice PondENGHO'!BO12-1 -> 0.015984154 | BQ15: =+'Indice PondENGHO'!BP13/'Indice PondENGHO'!BP12-1 -> 0.015314448 | BR15: =+'Indice PondENGHO'!BQ13/'Indice PondENGHO'!BQ12-1 -> 0.018344152 | BS15: =+'Indice PondENGHO'!BR13/'Indice PondENGHO'!BR12-1 -> 0.0063266901 | BT15: =+'Indice PondENGHO'!BS13/'Indice PondENGHO'!BS12-1 -> 0.015581383 | ... CE15: =+'Indice PondENGHO'!CD13/'Indice PondENGHO'!CD12-1 -> 0.015757137 | CG15: =+'Indice PondENGHO'!CF13/'Indice PondENGHO'!CF12-1 -> 0.016452897 | CI15: =+BM15-BQ15 -> 0.00066554254 | CJ15: =+'[3]Infla Mensual PondENGHO'!CF15 -> -0.00031779203 | CK15: =+CI15-CJ15 -> 0.00098333456
A16: =+DATE(C16,B16,1) -> 43070 | B16: =+IF(B15=12,1,B15+1) -> 12 | C16: 2017 | D16: =+'Indice PondENGHO'!D14/'Indice PondENGHO'!D13-1 -> 0.0090733938 | E16: =+'Indice PondENGHO'!E14/'Indice PondENGHO'!E13-1 -> -0.0013803521 | F16: =+'Indice PondENGHO'!F14/'Indice PondENGHO'!F13-1 -> 0.01917576 | G16: =+'Indice PondENGHO'!G14/'Indice PondENGHO'!G13-1 -> 0.16838597 | H16: =+'Indice PondENGHO'!H14/'Indice PondENGHO'!H13-1 -> 0.033017801 | I16: =+'Indice PondENGHO'!I14/'Indice PondENGHO'!I13-1 -> 0.021955589 | J16: =+'Indice PondENGHO'!J14/'Indice PondENGHO'!J13-1 -> 0.032482857 | K16: =+'Indice PondENGHO'!K14/'Indice PondENGHO'!K13-1 -> 0.0007979058 | ... BK16: =+'Indice PondENGHO'!BK14/'Indice PondENGHO'!BK13-1 -> 0.011514081 | BL16: =+A16 -> 43070 | BM16: =+'Indice PondENGHO'!BL14/'Indice PondENGHO'!BL13-1 -> 0.0291366 | BN16: =+'Indice PondENGHO'!BM14/'Indice PondENGHO'!BM13-1 -> 0.031652081 | BO16: =+'Indice PondENGHO'!BN14/'Indice PondENGHO'!BN13-1 -> 0.0323677 | BP16: =+'Indice PondENGHO'!BO14/'Indice PondENGHO'!BO13-1 -> 0.032889 | BQ16: =+'Indice PondENGHO'!BP14/'Indice PondENGHO'!BP13-1 -> 0.0346682 | BR16: =+'Indice PondENGHO'!BQ14/'Indice PondENGHO'!BQ13-1 -> 0.0084599736 | BS16: =+'Indice PondENGHO'!BR14/'Indice PondENGHO'!BR13-1 -> -0.00074686194 | BT16: =+'Indice PondENGHO'!BS14/'Indice PondENGHO'!BS13-1 -> 0.019799156 | ... CE16: =+'Indice PondENGHO'!CD14/'Indice PondENGHO'!CD13-1 -> 0.032721468 | CG16: =+'Indice PondENGHO'!CF14/'Indice PondENGHO'!CF13-1 -> 0.034948592 | CI16: =+BM16-BQ16 -> -0.0055315998 | CJ16: =+'[3]Infla Mensual PondENGHO'!CF16 -> -0.0051974867 | CK16: =+CI16-CJ16 -> -0.00033411311
... A75: =+DATE(C75,B75,1) -> 44866 | B75: =+IF(B74=12,1,B74+1) -> 11 | C75: 2022 | D75: =+'Indice PondENGHO'!D73/'Indice PondENGHO'!D72-1 -> 0.042598523 | E75: =+'Indice PondENGHO'!E73/'Indice PondENGHO'!E72-1 -> 0.058963729 | F75: =+'Indice PondENGHO'!F73/'Indice PondENGHO'!F72-1 -> 0.049196568 | G75: =+'Indice PondENGHO'!G73/'Indice PondENGHO'!G72-1 -> 0.079798022 | H75: =+'Indice PondENGHO'!H73/'Indice PondENGHO'!H72-1 -> 0.054546717 | I75: =+'Indice PondENGHO'!I73/'Indice PondENGHO'!I72-1 -> 0.043667413 | J75: =+'Indice PondENGHO'!J73/'Indice PondENGHO'!J72-1 -> 0.056754017 | K75: =+'Indice PondENGHO'!K73/'Indice PondENGHO'!K72-1 -> 0.063388731 | ... BK75: =+'Indice PondENGHO'!BK73/'Indice PondENGHO'!BK72-1 -> 0.05565725 | BL75: =+A75 -> 44866 | BM75: =+'Indice PondENGHO'!BL73/'Indice PondENGHO'!BL72-1 -> 0.049753903 | BN75: =+'Indice PondENGHO'!BM73/'Indice PondENGHO'!BM72-1 -> 0.051041963 | BO75: =+'Indice PondENGHO'!BN73/'Indice PondENGHO'!BN72-1 -> 0.051266333 | BP75: =+'Indice PondENGHO'!BO73/'Indice PondENGHO'!BO72-1 -> 0.051895774 | BQ75: =+'Indice PondENGHO'!BP73/'Indice PondENGHO'!BP72-1 -> 0.052705843 | BR75: =+'Indice PondENGHO'!BQ73/'Indice PondENGHO'!BQ72-1 -> 0.041918144 | BS75: =+'Indice PondENGHO'!BR73/'Indice PondENGHO'!BR72-1 -> 0.058865554 | BT75: =+'Indice PondENGHO'!BS73/'Indice PondENGHO'!BS72-1 -> 0.050531851 | ... CE75: =+'Indice PondENGHO'!CD73/'Indice PondENGHO'!CD72-1 -> 0.051643572 | CG75: =+'Indice PondENGHO'!CF73/'Indice PondENGHO'!CF72-1 -> 0.051672202 | CI75: =+BM75-BQ75 -> -0.0029519406 | CJ75: =+'[3]Infla Mensual PondENGHO'!CF75 -> -0.0038386139 | CK75: =+CI75-CJ75 -> 0.00088667325
A76: =+DATE(C76,B76,1) -> 44896 | B76: =+IF(B75=12,1,B75+1) -> 12 | C76: =+'Indice PondENGHO'!C74 -> 2022 | D76: =+'Indice PondENGHO'!D74/'Indice PondENGHO'!D73-1 -> 0.044304991 | E76: =+'Indice PondENGHO'!E74/'Indice PondENGHO'!E73-1 -> 0.064966791 | F76: =+'Indice PondENGHO'!F74/'Indice PondENGHO'!F73-1 -> 0.045534898 | G76: =+'Indice PondENGHO'!G74/'Indice PondENGHO'!G73-1 -> 0.041368847 | H76: =+'Indice PondENGHO'!H74/'Indice PondENGHO'!H73-1 -> 0.061234277 | I76: =+'Indice PondENGHO'!I74/'Indice PondENGHO'!I73-1 -> 0.05651096 | J76: =+'Indice PondENGHO'!J74/'Indice PondENGHO'!J73-1 -> 0.059139843 | K76: =+'Indice PondENGHO'!K74/'Indice PondENGHO'!K73-1 -> 0.02747537 | ... BK76: =+'Indice PondENGHO'!BK74/'Indice PondENGHO'!BK73-1 -> 0.056458437 | BL76: =+A76 -> 44896 | BM76: =+'Indice PondENGHO'!BL74/'Indice PondENGHO'!BL73-1 -> 0.049450148 | BN76: =+'Indice PondENGHO'!BM74/'Indice PondENGHO'!BM73-1 -> 0.051173772 | BO76: =+'Indice PondENGHO'!BN74/'Indice PondENGHO'!BN73-1 -> 0.051979888 | BP76: =+'Indice PondENGHO'!BO74/'Indice PondENGHO'!BO73-1 -> 0.052855242 | BQ76: =+'Indice PondENGHO'!BP74/'Indice PondENGHO'!BP73-1 -> 0.054102805 | BR76: =+'Indice PondENGHO'!BQ74/'Indice PondENGHO'!BQ73-1 -> 0.047128766 | BS76: =+'Indice PondENGHO'!BR74/'Indice PondENGHO'!BR73-1 -> 0.06506624 | BT76: =+'Indice PondENGHO'!BS74/'Indice PondENGHO'!BS73-1 -> 0.046213149 | ... CE76: =+'Indice PondENGHO'!CD74/'Indice PondENGHO'!CD73-1 -> 0.052414508 | CG76: =+'Indice PondENGHO'!CF74/'Indice PondENGHO'!CF73-1 -> 0.048902665 | CI76: =+BM76-BQ76 -> -0.0046526572 | CJ76: =+'[3]Infla Mensual PondENGHO'!CF76 -> -0.0043527748 | CK76: =+CI76-CJ76 -> -0.00029988238
A77: =+DATE(C77,B77,1) -> 44927 | B77: =+IF(B76=12,1,B76+1) -> 1 | C77: =+'Indice PondENGHO'!C75 -> 2023 | D77: =+'Indice PondENGHO'!D75/'Indice PondENGHO'!D74-1 -> 0.063191624 | E77: =+'Indice PondENGHO'!E75/'Indice PondENGHO'!E74-1 -> 0.062586548 | F77: =+'Indice PondENGHO'!F75/'Indice PondENGHO'!F74-1 -> 0.047731713 | G77: =+'Indice PondENGHO'!G75/'Indice PondENGHO'!G74-1 -> 0.076485503 | H77: =+'Indice PondENGHO'!H75/'Indice PondENGHO'!H74-1 -> 0.05811848 | I77: =+'Indice PondENGHO'!I75/'Indice PondENGHO'!I74-1 -> 0.047425609 | J77: =+'Indice PondENGHO'!J75/'Indice PondENGHO'!J74-1 -> 0.05701546 | K77: =+'Indice PondENGHO'!K75/'Indice PondENGHO'!K74-1 -> 0.058010757 | ... BK77: =+'Indice PondENGHO'!BK75/'Indice PondENGHO'!BK74-1 -> 0.063613325 | BL77: =+A77 -> 44927 | BM77: =+'Indice PondENGHO'!BL75/'Indice PondENGHO'!BL74-1 -> 0.061562879 | BN77: =+'Indice PondENGHO'!BM75/'Indice PondENGHO'!BM74-1 -> 0.061312086 | BO77: =+'Indice PondENGHO'!BN75/'Indice PondENGHO'!BN74-1 -> 0.060861321 | BP77: =+'Indice PondENGHO'!BO75/'Indice PondENGHO'!BO74-1 -> 0.060908642 | BQ77: =+'Indice PondENGHO'!BP75/'Indice PondENGHO'!BP74-1 -> 0.061057952 | BR77: =+'Indice PondENGHO'!BQ75/'Indice PondENGHO'!BQ74-1 -> 0.061313477 | BS77: =+'Indice PondENGHO'!BR75/'Indice PondENGHO'!BR74-1 -> 0.062820246 | BT77: =+'Indice PondENGHO'!BS75/'Indice PondENGHO'!BS74-1 -> 0.048839733 | ... CE77: =+'Indice PondENGHO'!CD75/'Indice PondENGHO'!CD74-1 -> 0.061091869 | CG77: =+'Indice PondENGHO'!CF75/'Indice PondENGHO'!CF74-1 -> 0.057138602 | CI77: =+BM77-BQ77 -> 0.00050492682 | CJ77: =+'[3]Infla Mensual PondENGHO'!CF77 -> 0.0018315332 | CK77: =+CI77-CJ77 -> -0.0013266064
A78: =+DATE(C78,B78,1) -> 44958 | B78: =+IF(B77=12,1,B77+1) -> 2 | C78: 2023 | D78: =+'Indice PondENGHO'!D76/'Indice PondENGHO'!D75-1 -> 0.085940742 | E78: =+'Indice PondENGHO'!E76/'Indice PondENGHO'!E75-1 -> 0.052383452 | F78: =+'Indice PondENGHO'!F76/'Indice PondENGHO'!F75-1 -> 0.053626656 | G78: =+'Indice PondENGHO'!G76/'Indice PondENGHO'!G75-1 -> 0.046871427 | H78: =+'Indice PondENGHO'!H76/'Indice PondENGHO'!H75-1 -> 0.054673749 | I78: =+'Indice PondENGHO'!I76/'Indice PondENGHO'!I75-1 -> 0.052697032 | J78: =+'Indice PondENGHO'!J76/'Indice PondENGHO'!J75-1 -> 0.051236644 | K78: =+'Indice PondENGHO'!K76/'Indice PondENGHO'!K75-1 -> 0.061865416 | ... BK78: =+'Indice PondENGHO'!BK76/'Indice PondENGHO'!BK75-1 -> 0.064745803 | BL78: =+A78 -> 44958 | BM78: =+'Indice PondENGHO'!BL76/'Indice PondENGHO'!BL75-1 -> 0.068906257 | BN78: =+'Indice PondENGHO'!BM76/'Indice PondENGHO'!BM75-1 -> 0.066308462 | BO78: =+'Indice PondENGHO'!BN76/'Indice PondENGHO'!BN75-1 -> 0.065136001 | BP78: =+'Indice PondENGHO'!BO76/'Indice PondENGHO'!BO75-1 -> 0.063500537 | BQ78: =+'Indice PondENGHO'!BP76/'Indice PondENGHO'!BP75-1 -> 0.06179321 | BR78: =+'Indice PondENGHO'!BQ76/'Indice PondENGHO'!BQ75-1 -> 0.084448058 | BS78: =+'Indice PondENGHO'!BR76/'Indice PondENGHO'!BR75-1 -> 0.052015246 | BT78: =+'Indice PondENGHO'!BS76/'Indice PondENGHO'!BS75-1 -> 0.054571423 | ... CE78: =+'Indice PondENGHO'!CD76/'Indice PondENGHO'!CD75-1 -> 0.064349801 | CG78: =+'Indice PondENGHO'!CF76/'Indice PondENGHO'!CF75-1 -> 0.063708787 | CI78: =+BM78-BQ78 -> 0.007113047 | CJ78: =+'[3]Infla Mensual PondENGHO'!CF78 -> 0.0096861578 | CK78: =+CI78-CJ78 -> -0.0025731108
A79: =+DATE(C79,B79,1) -> 44986 | B79: =+IF(B78=12,1,B78+1) -> 3 | C79: =+IF(B79=1,C78+1,C78) -> 2023 | D79: =+'Indice PondENGHO'!D77/'Indice PondENGHO'!D76-1 -> 0.074476493 | E79: =+'Indice PondENGHO'!E77/'Indice PondENGHO'!E76-1 -> 0.075097822 | F79: =+'Indice PondENGHO'!F77/'Indice PondENGHO'!F76-1 -> 0.06179771 | G79: =+'Indice PondENGHO'!G77/'Indice PondENGHO'!G76-1 -> 0.063386983 | H79: =+'Indice PondENGHO'!H77/'Indice PondENGHO'!H76-1 -> 0.062387851 | I79: =+'Indice PondENGHO'!I77/'Indice PondENGHO'!I76-1 -> 0.05744921 | J79: =+'Indice PondENGHO'!J77/'Indice PondENGHO'!J76-1 -> 0.052314642 | K79: =+'Indice PondENGHO'!K77/'Indice PondENGHO'!K76-1 -> 0.016745426 | ... BK79: =+'Indice PondENGHO'!BK77/'Indice PondENGHO'!BK76-1 -> 0.061234523 | BL79: =+A79 -> 44986 | BM79: =+'Indice PondENGHO'!BL77/'Indice PondENGHO'!BL76-1 -> 0.066435646 | BN79: =+'Indice PondENGHO'!BM77/'Indice PondENGHO'!BM76-1 -> 0.066233424 | BO79: =+'Indice PondENGHO'!BN77/'Indice PondENGHO'!BN76-1 -> 0.066278472 | BP79: =+'Indice PondENGHO'!BO77/'Indice PondENGHO'!BO76-1 -> 0.065420395 | BQ79: =+'Indice PondENGHO'!BP77/'Indice PondENGHO'!BP76-1 -> 0.064486252 | BR79: =+'Indice PondENGHO'!BQ77/'Indice PondENGHO'!BQ76-1 -> 0.077165873 | BS79: =+'Indice PondENGHO'!BR77/'Indice PondENGHO'!BR76-1 -> 0.07424442 | BT79: =+'Indice PondENGHO'!BS77/'Indice PondENGHO'!BS76-1 -> 0.061891895 | ... CE79: =+'Indice PondENGHO'!CD77/'Indice PondENGHO'!CD76-1 -> 0.065527118 | CG79: =+'Indice PondENGHO'!CF77/'Indice PondENGHO'!CF76-1 -> 0.064750863 | CI79: =+BM79-BQ79 -> 0.0019493948 | CJ79: =+'[3]Infla Mensual PondENGHO'!CF79 -> 0.0025683985 | CK79: =+CI79-CJ79 -> -0.00061900366
A80: =+DATE(C80,B80,1) -> 45017 | B80: =+IF(B79=12,1,B79+1) -> 4 | C80: =+IF(B80=1,C79+1,C79) -> 2023 | D80: =+'Indice PondENGHO'!D78/'Indice PondENGHO'!D77-1 -> 0.09772292 | E80: =+'Indice PondENGHO'!E78/'Indice PondENGHO'!E77-1 -> 0.049390036 | F80: =+'Indice PondENGHO'!F78/'Indice PondENGHO'!F77-1 -> 0.077953769 | G80: =+'Indice PondENGHO'!G78/'Indice PondENGHO'!G77-1 -> 0.052465326 | H80: =+'Indice PondENGHO'!H78/'Indice PondENGHO'!H77-1 -> 0.086056293 | I80: =+'Indice PondENGHO'!I78/'Indice PondENGHO'!I77-1 -> 0.065693126 | J80: =+'Indice PondENGHO'!J78/'Indice PondENGHO'!J77-1 -> 0.062816355 | K80: =+'Indice PondENGHO'!K78/'Indice PondENGHO'!K77-1 -> 0.061983146 | ... BK80: =+'Indice PondENGHO'!BK78/'Indice PondENGHO'!BK77-1 -> 0.072339019 | BL80: =+A80 -> 45017 | BM80: =+'Indice PondENGHO'!BL78/'Indice PondENGHO'!BL77-1 -> 0.082785213 | BN80: =+'Indice PondENGHO'!BM78/'Indice PondENGHO'!BM77-1 -> 0.081477849 | BO80: =+'Indice PondENGHO'!BN78/'Indice PondENGHO'!BN77-1 -> 0.081391394 | BP80: =+'Indice PondENGHO'!BO78/'Indice PondENGHO'!BO77-1 -> 0.080669597 | BQ80: =+'Indice PondENGHO'!BP78/'Indice PondENGHO'!BP77-1 -> 0.079838651 | BR80: =+'Indice PondENGHO'!BQ78/'Indice PondENGHO'!BQ77-1 -> 0.099657054 | BS80: =+'Indice PondENGHO'!BR78/'Indice PondENGHO'!BR77-1 -> 0.048015216 | BT80: =+'Indice PondENGHO'!BS78/'Indice PondENGHO'!BS77-1 -> 0.079436154 | ... CE80: =+'Indice PondENGHO'!CD78/'Indice PondENGHO'!CD77-1 -> 0.080921701 | CG80: =+'Indice PondENGHO'!CF78/'Indice PondENGHO'!CF77-1 -> 0.082482946 | CI80: =+BM80-BQ80 -> 0.0029465613 | CJ80: =+'[3]Infla Mensual PondENGHO'!CF80 -> 0.0036589518 | CK80: =+CI80-CJ80 -> -0.00071239055
A81: =+DATE(C81,B81,1) -> 45047 | B81: =+IF(B80=12,1,B80+1) -> 5 | C81: =+IF(B81=1,C80+1,C80) -> 2023 | D81: =+'Indice PondENGHO'!D79/'Indice PondENGHO'!D78-1 -> 0.073868288 | E81: =+'Indice PondENGHO'!E79/'Indice PondENGHO'!E78-1 -> 0.092473732 | F81: =+'Indice PondENGHO'!F79/'Indice PondENGHO'!F78-1 -> 0.082327095 | G81: =+'Indice PondENGHO'!G79/'Indice PondENGHO'!G78-1 -> 0.11793879 | H81: =+'Indice PondENGHO'!H79/'Indice PondENGHO'!H78-1 -> 0.092015868 | I81: =+'Indice PondENGHO'!I79/'Indice PondENGHO'!I78-1 -> 0.094097729 | J81: =+'Indice PondENGHO'!J79/'Indice PondENGHO'!J78-1 -> 0.07623932 | K81: =+'Indice PondENGHO'!K79/'Indice PondENGHO'!K78-1 -> 0.070042704 | ... BK81: =+'Indice PondENGHO'!BK79/'Indice PondENGHO'!BK78-1 -> 0.077754428 | BL81: =+A81 -> 45047 | BM81: =+'Indice PondENGHO'!BL79/'Indice PondENGHO'!BL78-1 -> 0.081827593 | BN81: =+'Indice PondENGHO'!BM79/'Indice PondENGHO'!BM78-1 -> 0.082642878 | BO81: =+'Indice PondENGHO'!BN79/'Indice PondENGHO'!BN78-1 -> 0.083074244 | BP81: =+'Indice PondENGHO'!BO79/'Indice PondENGHO'!BO78-1 -> 0.083725891 | BQ81: =+'Indice PondENGHO'!BP79/'Indice PondENGHO'!BP78-1 -> 0.085315877 | BR81: =+'Indice PondENGHO'!BQ79/'Indice PondENGHO'!BQ78-1 -> 0.072590941 | BS81: =+'Indice PondENGHO'!BR79/'Indice PondENGHO'!BR78-1 -> 0.092379757 | BT81: =+'Indice PondENGHO'!BS79/'Indice PondENGHO'!BS78-1 -> 0.082816148 | ... CE81: =+'Indice PondENGHO'!CD79/'Indice PondENGHO'!CD78-1 -> 0.083711689 | CG81: =+'Indice PondENGHO'!CF79/'Indice PondENGHO'!CF78-1 -> 0.083346592 | CI81: =+BM81-BQ81 -> -0.0034882835 | CJ81: =+'[3]Infla Mensual PondENGHO'!CF81 -> -0.0056671735 | CK81: =+CI81-CJ81 -> 0.0021788899
A82: =+DATE(C82,B82,1) -> 45078 | B82: =+IF(B81=12,1,B81+1) -> 6 | C82: =+IF(B82=1,C81+1,C81) -> 2023 | D82: =+'Indice PondENGHO'!D80/'Indice PondENGHO'!D79-1 -> 0.057423891 | E82: =+'Indice PondENGHO'!E80/'Indice PondENGHO'!E79-1 -> 0.05201949 | F82: =+'Indice PondENGHO'!F80/'Indice PondENGHO'!F79-1 -> 0.056844866 | G82: =+'Indice PondENGHO'!G80/'Indice PondENGHO'!G79-1 -> 0.094919205 | H82: =+'Indice PondENGHO'!H80/'Indice PondENGHO'!H79-1 -> 0.079061268 | I82: =+'Indice PondENGHO'!I80/'Indice PondENGHO'!I79-1 -> 0.087120609 | J82: =+'Indice PondENGHO'!J80/'Indice PondENGHO'!J79-1 -> 0.065072252 | K82: =+'Indice PondENGHO'!K80/'Indice PondENGHO'!K79-1 -> 0.10484654 | ... BK82: =+'Indice PondENGHO'!BK80/'Indice PondENGHO'!BK79-1 -> 0.076257695 | BL82: =+A82 -> 45078 | BM82: =+'Indice PondENGHO'!BL80/'Indice PondENGHO'!BL79-1 -> 0.064861226 | BN82: =+'Indice PondENGHO'!BM80/'Indice PondENGHO'!BM79-1 -> 0.064974828 | BO82: =+'Indice PondENGHO'!BN80/'Indice PondENGHO'!BN79-1 -> 0.065309358 | BP82: =+'Indice PondENGHO'!BO80/'Indice PondENGHO'!BO79-1 -> 0.066069522 | BQ82: =+'Indice PondENGHO'!BP80/'Indice PondENGHO'!BP79-1 -> 0.067521065 | BR82: =+'Indice PondENGHO'!BQ80/'Indice PondENGHO'!BQ79-1 -> 0.055620179 | BS82: =+'Indice PondENGHO'!BR80/'Indice PondENGHO'!BR79-1 -> 0.051079545 | BT82: =+'Indice PondENGHO'!BS80/'Indice PondENGHO'!BS79-1 -> 0.057091082 | ... CE82: =+'Indice PondENGHO'!CD80/'Indice PondENGHO'!CD79-1 -> 0.066077092 | CG82: =+'Indice PondENGHO'!CF80/'Indice PondENGHO'!CF79-1 -> 0.067566645 | CI82: =+BM82-BQ82 -> -0.0026598391 | CJ82: =+'[3]Infla Mensual PondENGHO'!CF82 -> -0.0051543199 | CK82: =+CI82-CJ82 -> 0.0024944808
A83: =+DATE(C83,B83,1) -> 45108 | B83: =+IF(B82=12,1,B82+1) -> 7 | C83: =+IF(B83=1,C82+1,C82) -> 2023 | D83: =+'Indice PondENGHO'!D81/'Indice PondENGHO'!D80-1 -> 0.064548144 | E83: =+'Indice PondENGHO'!E81/'Indice PondENGHO'!E80-1 -> 0.097261825 | F83: =+'Indice PondENGHO'!F81/'Indice PondENGHO'!F80-1 -> 0.052614033 | G83: =+'Indice PondENGHO'!G81/'Indice PondENGHO'!G80-1 -> 0.042831725 | H83: =+'Indice PondENGHO'!H81/'Indice PondENGHO'!H80-1 -> 0.059358243 | I83: =+'Indice PondENGHO'!I81/'Indice PondENGHO'!I80-1 -> 0.092599049 | J83: =+'Indice PondENGHO'!J81/'Indice PondENGHO'!J80-1 -> 0.05688005 | K83: =+'Indice PondENGHO'!K81/'Indice PondENGHO'!K80-1 -> 0.12941816 | ... BK83: =+'Indice PondENGHO'!BK81/'Indice PondENGHO'!BK80-1 -> 0.066704758 | BL83: =+A83 -> 45108 | BM83: =+'Indice PondENGHO'!BL81/'Indice PondENGHO'!BL80-1 -> 0.067579479 | BN83: =+'Indice PondENGHO'!BM81/'Indice PondENGHO'!BM80-1 -> 0.068308036 | BO83: =+'Indice PondENGHO'!BN81/'Indice PondENGHO'!BN80-1 -> 0.069126749 | BP83: =+'Indice PondENGHO'!BO81/'Indice PondENGHO'!BO80-1 -> 0.069272137 | BQ83: =+'Indice PondENGHO'!BP81/'Indice PondENGHO'!BP80-1 -> 0.070257859 | BR83: =+'Indice PondENGHO'!BQ81/'Indice PondENGHO'!BQ80-1 -> 0.065692531 | BS83: =+'Indice PondENGHO'!BR81/'Indice PondENGHO'!BR80-1 -> 0.097370173 | BT83: =+'Indice PondENGHO'!BS81/'Indice PondENGHO'!BS80-1 -> 0.053504497 | ... CE83: =+'Indice PondENGHO'!CD81/'Indice PondENGHO'!CD80-1 -> 0.069201071 | CG83: =+'Indice PondENGHO'!CF81/'Indice PondENGHO'!CF80-1 -> 0.072511495 | CI83: =+BM83-BQ83 -> -0.0026783804 | CJ83: =+'[3]Infla Mensual PondENGHO'!CF83 -> -0.0045307474 | CK83: =+CI83-CJ83 -> 0.001852367
A84: =+DATE(C84,B84,1) -> 45139 | B84: =+IF(B83=12,1,B83+1) -> 8 | C84: =+IF(B84=1,C83+1,C83) -> 2023 | D84: =+'Indice PondENGHO'!D82/'Indice PondENGHO'!D81-1 -> 0.15988408 | E84: =+'Indice PondENGHO'!E82/'Indice PondENGHO'!E81-1 -> 0.093989585 | F84: =+'Indice PondENGHO'!F82/'Indice PondENGHO'!F81-1 -> 0.10119574 | G84: =+'Indice PondENGHO'!G82/'Indice PondENGHO'!G81-1 -> 0.083323782 | H84: =+'Indice PondENGHO'!H82/'Indice PondENGHO'!H81-1 -> 0.14041437 | I84: =+'Indice PondENGHO'!I82/'Indice PondENGHO'!I81-1 -> 0.1516956 | J84: =+'Indice PondENGHO'!J82/'Indice PondENGHO'!J81-1 -> 0.10612631 | K84: =+'Indice PondENGHO'!K82/'Indice PondENGHO'!K81-1 -> 0.062547906 | ... BK84: =+'Indice PondENGHO'!BK82/'Indice PondENGHO'!BK81-1 -> 0.087504231 | BL84: =+A84 -> 45139 | BM84: =+'Indice PondENGHO'!BL82/'Indice PondENGHO'!BL81-1 -> 0.13102465 | BN84: =+'Indice PondENGHO'!BM82/'Indice PondENGHO'!BM81-1 -> 0.12678788 | BO84: =+'Indice PondENGHO'!BN82/'Indice PondENGHO'!BN81-1 -> 0.12570794 | BP84: =+'Indice PondENGHO'!BO82/'Indice PondENGHO'!BO81-1 -> 0.12401532 | BQ84: =+'Indice PondENGHO'!BP82/'Indice PondENGHO'!BP81-1 -> 0.12266616 | BR84: =+'Indice PondENGHO'!BQ82/'Indice PondENGHO'!BQ81-1 -> 0.15624836 | BS84: =+'Indice PondENGHO'!BR82/'Indice PondENGHO'!BR81-1 -> 0.090698475 | BT84: =+'Indice PondENGHO'!BS82/'Indice PondENGHO'!BS81-1 -> 0.099992158 | ... CE84: =+'Indice PondENGHO'!CD82/'Indice PondENGHO'!CD81-1 -> 0.12518498 | CG84: =+'Indice PondENGHO'!CF82/'Indice PondENGHO'!CF81-1 -> 0.12546468 | CI84: =+BM84-BQ84 -> 0.0083584855 | CJ84: =+'[3]Infla Mensual PondENGHO'!CF84 -> 0.0086332003 | CK84: =+CI84-CJ84 -> -0.00027471476
A85: =+DATE(C85,B85,1) -> 45170 | B85: =+IF(B84=12,1,B84+1) -> 9 | C85: =+IF(B85=1,C84+1,C84) -> 2023 | D85: =+'Indice PondENGHO'!D83/'Indice PondENGHO'!D82-1 -> 0.13989187 | E85: =+'Indice PondENGHO'!E83/'Indice PondENGHO'!E82-1 -> 0.10940414 | F85: =+'Indice PondENGHO'!F83/'Indice PondENGHO'!F82-1 -> 0.11816263 | G85: =+'Indice PondENGHO'!G83/'Indice PondENGHO'!G82-1 -> 0.089623884 | H85: =+'Indice PondENGHO'!H83/'Indice PondENGHO'!H82-1 -> 0.1231032 | I85: =+'Indice PondENGHO'!I83/'Indice PondENGHO'!I82-1 -> 0.099285934 | J85: =+'Indice PondENGHO'!J83/'Indice PondENGHO'!J82-1 -> 0.11183237 | K85: =+'Indice PondENGHO'!K83/'Indice PondENGHO'!K82-1 -> 0.10597047 | ... BK85: =+'Indice PondENGHO'!BK83/'Indice PondENGHO'!BK82-1 -> 0.11626027 | BL85: =+A85 -> 45170 | BM85: =+'Indice PondENGHO'!BL83/'Indice PondENGHO'!BL82-1 -> 0.1262439 | BN85: =+'Indice PondENGHO'!BM83/'Indice PondENGHO'!BM82-1 -> 0.12403172 | BO85: =+'Indice PondENGHO'!BN83/'Indice PondENGHO'!BN82-1 -> 0.12332462 | BP85: =+'Indice PondENGHO'!BO83/'Indice PondENGHO'!BO82-1 -> 0.12179792 | BQ85: =+'Indice PondENGHO'!BP83/'Indice PondENGHO'!BP82-1 -> 0.11977724 | BR85: =+'Indice PondENGHO'!BQ83/'Indice PondENGHO'!BQ82-1 -> 0.13958089 | BS85: =+'Indice PondENGHO'!BR83/'Indice PondENGHO'!BR82-1 -> 0.10889917 | BT85: =+'Indice PondENGHO'!BS83/'Indice PondENGHO'!BS82-1 -> 0.11852765 | ... CE85: =+'Indice PondENGHO'!CD83/'Indice PondENGHO'!CD82-1 -> 0.12232617 | CG85: =+'Indice PondENGHO'!CF83/'Indice PondENGHO'!CF82-1 -> 0.12308681 | CI85: =+BM85-BQ85 -> 0.0064666518 | CJ85: =+'[3]Infla Mensual PondENGHO'!CF85 -> 0.0077424829 | CK85: =+CI85-CJ85 -> -0.0012758311
A86: =+DATE(C86,B86,1) -> 45200 | B86: =+IF(B85=12,1,B85+1) -> 10 | C86: =+IF(B86=1,C85+1,C85) -> 2023 | D86: =+'Indice PondENGHO'!D84/'Indice PondENGHO'!D83-1 -> 0.070940824 | E86: =+'Indice PondENGHO'!E84/'Indice PondENGHO'!E83-1 -> 0.097771887 | F86: =+'Indice PondENGHO'!F84/'Indice PondENGHO'!F83-1 -> 0.098493093 | G86: =+'Indice PondENGHO'!G84/'Indice PondENGHO'!G83-1 -> 0.072303598 | H86: =+'Indice PondENGHO'!H84/'Indice PondENGHO'!H83-1 -> 0.10287852 | I86: =+'Indice PondENGHO'!I84/'Indice PondENGHO'!I83-1 -> 0.04858806 | J86: =+'Indice PondENGHO'!J84/'Indice PondENGHO'!J83-1 -> 0.07017971 | K86: =+'Indice PondENGHO'!K84/'Indice PondENGHO'!K83-1 -> 0.13322998 | ... BK86: =+'Indice PondENGHO'!BK84/'Indice PondENGHO'!BK83-1 -> 0.067568077 | BL86: =+A86 -> 45200 | BM86: =+'Indice PondENGHO'!BL84/'Indice PondENGHO'!BL83-1 -> 0.079175418 | BN86: =+'Indice PondENGHO'!BM84/'Indice PondENGHO'!BM83-1 -> 0.080654974 | BO86: =+'Indice PondENGHO'!BN84/'Indice PondENGHO'!BN83-1 -> 0.08101993 | BP86: =+'Indice PondENGHO'!BO84/'Indice PondENGHO'!BO83-1 -> 0.081171927 | BQ86: =+'Indice PondENGHO'!BP84/'Indice PondENGHO'!BP83-1 -> 0.082219352 | BR86: =+'Indice PondENGHO'!BQ84/'Indice PondENGHO'!BQ83-1 -> 0.073196951 | BS86: =+'Indice PondENGHO'!BR84/'Indice PondENGHO'!BR83-1 -> 0.098803486 | BT86: =+'Indice PondENGHO'!BS84/'Indice PondENGHO'!BS83-1 -> 0.10028989 | ... CE86: =+'Indice PondENGHO'!CD84/'Indice PondENGHO'!CD83-1 -> 0.081148246
A87: =+DATE(C87,B87,1) -> 45231 | B87: =+IF(B86=12,1,B86+1) -> 11 | C87: =+IF(B87=1,C86+1,C86) -> 2023 | D87: =+'Indice PondENGHO'!D85/'Indice PondENGHO'!D84-1 -> 0.15924591 | E87: =+'Indice PondENGHO'!E85/'Indice PondENGHO'!E84-1 -> 0.11191708 | F87: =+'Indice PondENGHO'!F85/'Indice PondENGHO'!F84-1 -> 0.10704355 | G87: =+'Indice PondENGHO'!G85/'Indice PondENGHO'!G84-1 -> 0.073952326 | H87: =+'Indice PondENGHO'!H85/'Indice PondENGHO'!H84-1 -> 0.1269198 | I87: =+'Indice PondENGHO'!I85/'Indice PondENGHO'!I84-1 -> 0.15587344 | J87: =+'Indice PondENGHO'!J85/'Indice PondENGHO'!J84-1 -> 0.10284753 | K87: =+'Indice PondENGHO'!K85/'Indice PondENGHO'!K84-1 -> 0.15417657 | ... BK87: =+'Indice PondENGHO'!BK85/'Indice PondENGHO'!BK84-1 -> 0.1121319 | BL87: =+A87 -> 45231 | BM87: =+'Indice PondENGHO'!BL85/'Indice PondENGHO'!BL84-1 -> 0.13411943 | BN87: =+'Indice PondENGHO'!BM85/'Indice PondENGHO'!BM84-1 -> 0.13199829 | BO87: =+'Indice PondENGHO'!BN85/'Indice PondENGHO'!BN84-1 -> 0.13211334 | BP87: =+'Indice PondENGHO'!BO85/'Indice PondENGHO'!BO84-1 -> 0.13054768 | BQ87: =+'Indice PondENGHO'!BP85/'Indice PondENGHO'!BP84-1 -> 0.12902321 | BR87: =+'Indice PondENGHO'!BQ85/'Indice PondENGHO'!BQ84-1 -> 0.16256925 | BS87: =+'Indice PondENGHO'!BR85/'Indice PondENGHO'!BR84-1 -> 0.11217353 | BT87: =+'Indice PondENGHO'!BS85/'Indice PondENGHO'!BS84-1 -> 0.10601936 | ... CE87: =+'Indice PondENGHO'!CD85/'Indice PondENGHO'!CD84-1 -> 0.13101193
A88: =+DATE(C88,B88,1) -> 45261 | B88: =+IF(B87=12,1,B87+1) -> 12 | C88: =+IF(B88=1,C87+1,C87) -> 2023 | D88: =+'Indice PondENGHO'!D86/'Indice PondENGHO'!D85-1 -> 0.29957664 | E88: =+'Indice PondENGHO'!E86/'Indice PondENGHO'!E85-1 -> 0.19325847 | F88: =+'Indice PondENGHO'!F86/'Indice PondENGHO'!F85-1 -> 0.17222868 | G88: =+'Indice PondENGHO'!G86/'Indice PondENGHO'!G85-1 -> 0.13844678 | H88: =+'Indice PondENGHO'!H86/'Indice PondENGHO'!H85-1 -> 0.30529334 | I88: =+'Indice PondENGHO'!I86/'Indice PondENGHO'!I85-1 -> 0.331238 | J88: =+'Indice PondENGHO'!J86/'Indice PondENGHO'!J85-1 -> 0.32272851 | K88: =+'Indice PondENGHO'!K86/'Indice PondENGHO'!K85-1 -> 0.14885742 | ... BK88: =+'Indice PondENGHO'!BK86/'Indice PondENGHO'!BK85-1 -> 0.31640693 | BL88: =+A88 -> 45261 | BM88: =+'Indice PondENGHO'!BL86/'Indice PondENGHO'!BL85-1 -> 0.26011354 | BN88: =+'Indice PondENGHO'!BM86/'Indice PondENGHO'!BM85-1 -> 0.25662257 | BO88: =+'Indice PondENGHO'!BN86/'Indice PondENGHO'!BN85-1 -> 0.25601713 | BP88: =+'Indice PondENGHO'!BO86/'Indice PondENGHO'!BO85-1 -> 0.2554964 | BQ88: =+'Indice PondENGHO'!BP86/'Indice PondENGHO'!BP85-1 -> 0.25268343 | BR88: =+'Indice PondENGHO'!BQ86/'Indice PondENGHO'!BQ85-1 -> 0.29878197 | BS88: =+'Indice PondENGHO'!BR86/'Indice PondENGHO'!BR85-1 -> 0.19444091 | BT88: =+'Indice PondENGHO'!BS86/'Indice PondENGHO'!BS85-1 -> 0.17473353 | ... CE88: =+'Indice PondENGHO'!CD86/'Indice PondENGHO'!CD85-1 -> 0.2554472
A89: =+DATE(C89,B89,1) -> 45292 | B89: =+IF(B88=12,1,B88+1) -> 1 | C89: =+IF(B89=1,C88+1,C88) -> 2024 | D89: =+'Indice PondENGHO'!D87/'Indice PondENGHO'!D86-1 -> 0.19685818 | E89: =+'Indice PondENGHO'!E87/'Indice PondENGHO'!E86-1 -> 0.19852694 | F89: =+'Indice PondENGHO'!F87/'Indice PondENGHO'!F86-1 -> 0.14377329 | G89: =+'Indice PondENGHO'!G87/'Indice PondENGHO'!G86-1 -> 0.15611659 | H89: =+'Indice PondENGHO'!H87/'Indice PondENGHO'!H86-1 -> 0.22614027 | I89: =+'Indice PondENGHO'!I87/'Indice PondENGHO'!I86-1 -> 0.20409534 | J89: =+'Indice PondENGHO'!J87/'Indice PondENGHO'!J86-1 -> 0.2666921 | K89: =+'Indice PondENGHO'!K87/'Indice PondENGHO'!K86-1 -> 0.22630622 | ... BK89: =+'Indice PondENGHO'!BK87/'Indice PondENGHO'!BK86-1 -> 0.43894517 | BL89: =+A89 -> 45292 | BM89: =+'Indice PondENGHO'!BL87/'Indice PondENGHO'!BL86-1 -> 0.20324766 | BN89: =+'Indice PondENGHO'!BM87/'Indice PondENGHO'!BM86-1 -> 0.20502921 | BO89: =+'Indice PondENGHO'!BN87/'Indice PondENGHO'!BN86-1 -> 0.20520063 | BP89: =+'Indice PondENGHO'!BO87/'Indice PondENGHO'!BO86-1 -> 0.20785203 | BQ89: =+'Indice PondENGHO'!BP87/'Indice PondENGHO'!BP86-1 -> 0.20868213 | BR89: =+'Indice PondENGHO'!BQ87/'Indice PondENGHO'!BQ86-1 -> 0.19724939 | BS89: =+'Indice PondENGHO'!BR87/'Indice PondENGHO'!BR86-1 -> 0.20029938 | BT89: =+'Indice PondENGHO'!BS87/'Indice PondENGHO'!BS86-1 -> 0.14567477 | ... CE89: =+'Indice PondENGHO'!CD87/'Indice PondENGHO'!CD86-1 -> 0.20662379
A90: =+DATE(C90,B90,1) -> 45323 | B90: =+IF(B89=12,1,B89+1) -> 2 | C90: =+IF(B90=1,C89+1,C89) -> 2024 | D90: =+'Indice PondENGHO'!D88/'Indice PondENGHO'!D87-1 -> 0.099165048 | E90: =+'Indice PondENGHO'!E88/'Indice PondENGHO'!E87-1 -> 0.17306443 | F90: =+'Indice PondENGHO'!F88/'Indice PondENGHO'!F87-1 -> 0.090321627 | G90: =+'Indice PondENGHO'!G88/'Indice PondENGHO'!G87-1 -> 0.20008932 | H90: =+'Indice PondENGHO'!H88/'Indice PondENGHO'!H87-1 -> 0.10384536 | I90: =+'Indice PondENGHO'!I88/'Indice PondENGHO'!I87-1 -> 0.13197332 | J90: =+'Indice PondENGHO'!J88/'Indice PondENGHO'!J87-1 -> 0.1953684 | K90: =+'Indice PondENGHO'!K88/'Indice PondENGHO'!K87-1 -> 0.22184103 | ... BK90: =+'Indice PondENGHO'!BK88/'Indice PondENGHO'!BK87-1 -> 0.16241494 | BL90: =+A90 -> 45323 | BM90: =+'Indice PondENGHO'!BL88/'Indice PondENGHO'!BL87-1 -> 0.11970581 | BN90: =+'Indice PondENGHO'!BM88/'Indice PondENGHO'!BM87-1 -> 0.12597741 | BO90: =+'Indice PondENGHO'!BN88/'Indice PondENGHO'!BN87-1 -> 0.12646971 | BP90: =+'Indice PondENGHO'!BO88/'Indice PondENGHO'!BO87-1 -> 0.13059046 | BQ90: =+'Indice PondENGHO'!BP88/'Indice PondENGHO'!BP87-1 -> 0.13289624 | BR90: =+'Indice PondENGHO'!BQ88/'Indice PondENGHO'!BQ87-1 -> 0.10350724 | BS90: =+'Indice PondENGHO'!BR88/'Indice PondENGHO'!BR87-1 -> 0.17682238 | BT90: =+'Indice PondENGHO'!BS88/'Indice PondENGHO'!BS87-1 -> 0.088388737 | ... CE90: =+'Indice PondENGHO'!CD88/'Indice PondENGHO'!CD87-1 -> 0.12850724
